Workbook

Sheet Anleitung
A1: SparteNet – Gateway-Standorte, Investition und Buchungsquote der Kleingartenanlagen
A2: Grundlage: Kleingartenentwicklungskonzept 2040, Anlage 1 (Steckbriefe), Anlage 2 (Karte) – Stadt Brandenburg an der Havel, März/April 2026
A4: So ist das Netz aufgebaut
A5: • Ein Gateway versorgt 55 Parzellen (Annahme „Parzellen je Gateway“). An einem Standort stehen so viele Gateways, wie die zugeordneten Sparten brauchen.
A6: • Die Gateways werden der Reihe nach gefüllt: hat die erste Sparte 86 Parzellen, belegt sie Gateway 1 ganz und 31 Plätze von Gateway 2 – die nächste Sparte nutzt die restlichen 24 Plätze, dann folgt Gateway 3.
A7: • Alle Gateways eines Standorts teilen sich einen Internet-Anschluss. Erst wenn der Bedarf größer ist als der Anschluss, wird ein zweiter gerechnet.
A8: • Sparten ohne eigene Gateways werden per Glasfaser von Sparte zu Sparte angebunden (Spalte „Zuleitung von“). Kein Richtfunk, keine Tiefbaukosten (Annahme „Tiefbau €/m“ = 0).
A10: Was Sie frei festlegen (Blatt „Anlagen“, gelbe Spalten)
A11: • „Gateway-Standort“: Nr. der Sparte, in der die Gateways stehen. Eigene Nr. = Sparte ist selbst Standort. Leer = Vorschlag (wenn in „Annahmen“ eingeschaltet), sonst eigener Standort.
A12: • „Zuleitung von“: Nr. der Sparte, von der die Glasfaser kommt (muss am selben Standort hängen). Leer = direkt vom Standort.
A13: • „Reihenfolge“: in welcher Reihenfolge die Sparten die Gateways eines Standorts füllen (1, 2, 3 …). Leer = zuerst die Standort-Sparte selbst, dann die übrigen in Zeilenfolge. Eingetragene Nummern kommen vor allen leeren.
A14: • „Quote manuell“: feste Buchungsquote nur für diese Sparte (z. B. 70 %).
... A30: • Preise netto; bei Kleinunternehmer rechnet die Mappe brutto (keine Vorsteuer).

Sheet Übersicht
A1: Übersicht – Planung gegenüber „jede Sparte eigenständig“
A2: Alle Werte berechnet · Planung in „Anlagen“ (gelbe Spalten) · Regeln und Quote in „Annahmen“
A4: Kennzahl | B4: jede Sparte eigenständig | C4: Ihre Planung | D4: Unterschied
A5: NETZ
A6: Gateway-Standorte (Schränke) | B6: =COUNT(Anlagen!A5:A92) -> 88 | C6: =Standorte!C93 -> 16 | D6: =C6-B6 -> -72
A7: Gateways | B7: =Investition!P93 -> 133 | C7: =Standorte!E93 -> 96 | D7: =C7-B7 -> -37
A8: Internet-Anschlüsse | B8: =SUMPRODUCT(--(Anlagen!A5:A92>0)) -> 88 | C8: =Standorte!K93 -> 23 | D8: =C8-B8 -> -65
A9: Glasfaser-Zuleitungen zwischen Sparten (m) | B9: 0 | C9: =Netz!G93 -> 56896.649 | D9: =C9-B9 -> 56896.649
A10: Prüfungen mit Fehler | C10: =COUNTIF(Netz!P5:P92,"Fehler*")+COUNTIF(Netz!Y5:Y92,"Fehler*") -> 0
A11: KOSTEN
A12: Investition | B12: =Investition!Q93 -> 1812369.8 | C12: =Investition!N93+Standorte!N93 -> 1768027.3 | D12: =C12-B12 -> -44342.525
A13: Laufende Kosten / Jahr | B13: =Investition!R93 -> 183146.94 | C13: =Investition!O93+Standorte!O93 -> 104246.52 | D13: =C13-B13 -> -78900.426
A14: Kosten im Betrachtungszeitraum (Investition + laufend × Jahre) | B14: =B12+B13*Jahre -> 2728104.5 | C14: =C12+C13*Jahre -> 2289259.9 | D14: =C14-B14 -> -438844.65
A15: BUCHUNG UND ERGEBNIS (Ihre Planung)
A16: Parzellen | C16: =SUM(Anlagen!F5:F92) -> 5017
A17: Leerstandsquote heute | C17: =Buchungsquote!E93 -> 0.034084114
A18: Leerstandsquote in 5 Jahren (Prognose) | C18: =Buchungsquote!Q93 -> 0.079125515
A19: Buchungsquote (gewählt) | C19: =Buchungsquote!T93 -> 0.56105513
A20: Kunden | C20: =Buchungsquote!V93 -> 2814.8136
A21: Umsatz / Jahr | C21: =Ergebnis!H93 -> 337777.63
A22: Deckungsbeitrag / Jahr (vor zentralen Firmenkosten) | C22: =Ergebnis!L93 -> 223397.79
A23: Amortisation (Jahre) | C23: =Ergebnis!M93 -> 7.9142561
A24: Investition je Kunde | C24: =Ergebnis!N93 -> 628.11522
A26: Buchungsquote-Modus laut Annahmen: | C26: =IF(Quote_Modus=2,"feste Quote "&TEXT(Quote_fest,"0%"),IF(Szenario=2,"aus Alter und Leerstand, in 5 Jahren","aus Alter und Leerstand, heute")) -> aus Alter und Leerstand, heute

Sheet Annahmen
A1: Annahmen
A2: Gelbe Felder ändern – alle Blätter rechnen neu.
A4: Annahme | C4: Wert | D4: Einheit / Quelle
A6: NETZ-REGELN
A7: Parzellen je Gateway | C7: 55 | D7: Ihre Vorgabe
A8: Gateways je Standort (Richtwert für die Prüfung) | C8: 10 | D8: darüber Warnung
A9: Standort-Vorschlag verwenden, wo keine eigene Wahl (1 = ja, 0 = jede Sparte eigenständig) | C9: 1 | D9: Vorschlag: Glasfaser zur nächsten Sparte bis 1,5 km, max. 10 Gateways
A10: Umwegfaktor Glasfaser (Trasse statt Luftlinie) | C10: 1.3
A11: Kapazität eines Internet-Anschlusses | C11: 1000 | D11: Mbit/s
A12: Überbuchungsfaktor | C12: 8 | D12: 1:x, wie Kalkulation
A13: Ø gebuchte Bandbreite je Kunde | C13: 30 | D13: Mbit/s
A14: Betrachtungszeitraum für Vergleiche | C14: 5 | D14: Jahre
A16: PREISE (netto) – aus Kalkulation_Sparten_WLAN.xlsx, Blatt „Preise“
A17: Gateway (UniFi Cloud Gateway Fiber) | C17: 250 | D17: Stück · UI Store
A18: UniFi Switch Aggregation (8× SFP+) | C18: 240 | D18: Stück · je 8 Anschlüsse
A19: DAC-Kabel 10G (je Gateway) | C19: 20 | D19: Stück
A20: Außenschrank Glasfaser (Standort) | C20: 1500 | D20: Stück · Schätzung
A21: USV + Überspannungsschutz Standort | C21: 250 | D21: Stück · Schätzung
A22: SFP 1G Singlemode | C22: 21.9 | D22: Stück · fiber24
A23: UniFi Switch Flex 2.5G PoE | C23: 179 | D23: Stück · UI Store
A24: Netzteil Flex | C24: 70 | D24: Stück
A25: Hutschienen-Halter | C25: 8.5 | D25: Stück
A26: Lüfter mit Thermostat | C26: 45 | D26: Stück · Schätzung
A27: Mini-Spleißbox LC | C27: 32.9 | D27: Stück · fiber24
A28: Strom-Säule (Leergehäuse) | C28: 300 | D28: Stück · Schätzung
... A39: Montage je Glasfaser-Zuleitung (Spleißen, Einmessen) | C39: 150 | D39: je Zuleitung · Schätzung
A41: STEUER
A42: Kleinunternehmer (1 = ja, 0 = Regelbesteuerung) | C42: 1 | D42: wie Kalkulation
A43: Umsatzsteuersatz | C43: 0.19
A44: Faktor Einkauf (ohne Vorsteuerabzug = brutto) | C44: =IF(KU=1,1+USt,1) -> 1.19 | D44: berechnet
A46: MENGEN IN DER SPARTE (kalibriert an KGV Buchenweg: 86 Parzellen, 49.614 m² → 24 APs, 11 Masten, 6 mit Technik)
A47: Parzellen je Access Point | C47: 3.6 | D47: Buchenweg: 86 ÷ 24
A48: Access Points je Mast | C48: 2.2 | D48: Buchenweg: 24 ÷ 11
A49: Anteil Masten mit Technik (Switch in der Säule) | C49: 0.5 | D49: Buchenweg: 6 von 11
A50: Leitungsweg in der Sparte (m = Faktor × √Fläche m²) | C50: 2.806 | D50: Buchenweg: 625 m ÷ √49.614
A51: Glasfaser m je m Leitungsweg | C51: 1.66 | D51: Buchenweg: 1.039 ÷ 625
A52: Kupferkabel m je m Leitungsweg | C52: 1.06 | D52: Buchenweg: 663 ÷ 625
A53: Kupferkabel (2 Überspannungsschutz) je AP | C53: 0.42 | D53: Buchenweg: 10 ÷ 24
A54: Anschlüsse je Aggregation-Switch | C54: 8 | D54: Gateways + Glasfaserstrecken
A56: LAUFENDE KOSTEN UND ERLÖS
...

Sheet Anlagen
A1: Anlagen – Daten aus Steckbriefen und Karte, Ihre Planung in den gelben Spalten
A2: Blau = Daten aus den Unterlagen (änderbar) · Gelb = Gateway-Standort, Zuleitung, Reihenfolge, Quote und genauere Mengen
A4: Nr. | B4: Kleingartenanlage | C4: Adresse | D4: Entwicklungsstufe | E4: Eigentum | F4: Parzellen | G4: Leerstand (Parzellen) | H4: Fläche m² | I4: Pächter bis 30 | J4: 30–50 | K4: 50–70 | L4: 70–90 | M4: ab 90 | N4: Lage x (km) | O4: Lage y (km) | P4: Parzellen lt. Konzept-Tabelle | Q4: Standort (Vorschlag) | R4: Zuleitung (Vorschlag) | S4: Gateway-Standort (eigene Wahl) | T4: Zuleitung von (eigene Wahl) | U4: Reihenfolge | V4: Entfernung manuell (m) | W4: Quote manuell | X4: APs manuell | Y4: Masten manuell | Z4: Leitungsweg m manuell | AA4: Kürzel | AB4: VLAN-Block (eigene Wahl)
A5: 1 | B5: 1. März | C5: Willibald-Alexis-Straße 38 | D5: B – Beobachtung | E5: Stadt BRB | F5: 30 | G5: 2 | H5: 8547 | I5: 0.4 | J5: 24.3 | K5: 10.8 | L5: 4.1 | M5: 0 | N5: 9.22 | O5: 7.78 | P5: 30 | Q5: 33 | R5: 6 | AA5: MAERZ
A6: 2 | B6: Abendfrieden | C6: Ziesarer Landstraße 24 | D6: C – Qualifizierung | E6: Stadt / Kirche | F6: 75 | G6: 4 | H6: 34727 | I6: 0 | J6: 36.8 | K6: 33.3 | L6: 12.7 | M6: 0 | N6: 9.12 | O6: 2.09 | P6: 75 | Q6: 41 | R6: 20 | AA6: ABFRI
A7: 3 | B7: Abendrot | C7: Am Gallberg 3 | D7: A – Stabil | E7: Stadt / privat | F7: 137 | G7: 0 | H7: 64614 | I7: 1.6 | J7: 42.5 | K7: 105.7 | L7: 51.9 | M7: 0 | N7: 9.64 | O7: 6.32 | P7: 137 | Q7: 30 | R7: 30 | AA7: ABROT
A8: 4 | B8: Abendruh | C8: Mahlerstraße 21 | D8: A – Stabil | E8: Stadt BRB | F8: 142 | G8: 0 | H8: 75974 | I8: 2.8 | J8: 46.9 | K8: 71.4 | L8: 52.9 | M8: 2.8 | N8: 8.01 | O8: 7.51 | P8: 142 | Q8: 30 | R8: 30 | AA8: ABRUH
A9: 5 | B9: Abendsonne | C9: Bayernstraße 9a | D9: A – Stabil | E9: Privat | F9: 67 | G9: 13 | H9: 17033 | I9: 1.7 | J9: 21.5 | K9: 30.3 | L9: 8.1 | M9: 0 | N9: 8.03 | O9: 5.22 | P9: 67 | Q9: 23 | R9: 24 | AA9: ABSON
A10: 6 | B10: Altstadt Forst | C10: Rathenower Landstraße 3 | D10: A – Stabil | E10: Stadt / privat | F10: 88 | G10: 0 | H10: 46549 | I10: 2.8 | J10: 46.9 | K10: 71.4 | L10: 52.9 | M10: 2.8 | N10: 8.52 | O10: 8.34 | P10: 88 | Q10: 33 | R10: 33 | AA10: ALTFO
A11: 7 | B11: Am Beetzseeufer | C11: Beetzseeufer 8 | D11: A – Stabil | E11: Stadt BRB | F11: 77 | G11: 0 | H11: 38607 | I11: 0.1 | J11: 44.9 | K11: 59.7 | L11: 11.7 | M11: 0 | N11: 11.55 | O11: 6.05 | P11: 76 | Q11: 49 | R11: 88 | AA11: BEETZ
A12: 8 | B12: Am Büttelhandfassgraben | C12: Am Bittelhandfassgraben 14 | D12: B – Beobachtung | E12: Privat | F12: 5 | G12: 0 | H12: 2345 | I12: 1.1 | J12: 0 | K12: 1.7 | L12: 0 | M12: 0 | N12: 10.02 | O12: 3.54 | P12: 5 | Q12: 49 | R12: 50 | AA12: BUETT
A13: 9 | B13: Am Eichenweg | C13: Ziesarer Landstraße 1 | D13: C – Qualifizierung | E13: Stadt / Kirche | F13: 54 | G13: 2 | H13: 33743 | I13: 0.9 | J13: 33 | K13: 22.2 | L13: 8.9 | M13: 0 | N13: 9.1 | O13: 2.38 | P13: 54 | Q13: 17 | R13: 17 | AA13: EICHW
A14: 10 | B14: Am Jakobsgraben | C14: Otto-Gartz-Straße 10a | D14: D – Planungskonflikt | E14: Stadt BRB | F14: 41 | G14: 0 | H14: 21966 | I14: 0.4 | J14: 17.5 | K14: 22.6 | L14: 9.6 | M14: 0 | N14: 10.92 | O14: 3.53 | P14: 41 | Q14: 17 | R14: 27 | AA14: JAKGR
A15: 11 | B15: Am Schafdamm | C15: Schafdamm 3 | D15: C – Qualifizierung | E15: Stadt / privat | F15: 10 | G15: 0 | H15: 6123 | I15: 0 | J15: 1.6 | K15: 5.1 | L15: 5 | M15: 0 | N15: 8.11 | O15: 9.91 | P15: 10 | Q15: 33 | R15: 12 | AA15: SCHAF
A16: 12 | B16: Am Schlangenpfad | C16: Schlangenpfad 21 | D16: C – Qualifizierung | E16: Stadt BRB | F16: 19 | G16: 0 | H16: 11021 | I16: 0 | J16: 2.9 | K16: 8.6 | L16: 14.6 | M16: 0 | N16: 8.03 | O16: 9.59 | P16: 19 | Q16: 33 | R16: 13 | AA16: SCHLA
... A19: 15 | B19: Bergeshöh | C19: Triglafweg 20 | D19: A – Stabil | E19: Stadt BRB | F19: 14 | G19: 1 | H19: 7551 | I19: 0 | J19: 12.6 | K19: 3.3 | L19: 3.2 | M19: 0 | N19: 10.6 | O19: 5.33 | P19: 14 | Q19: 28 | R19: 83 | AA19: BERGH
A20: 16 | B20: Bergfrieden | C20: Wusterwitzer Str. 71 | D20: C – Qualifizierung | E20: Stadt BRB | F20: 130 | G20: 17 | H20: 55513 | I20: 5 | J20: 38.9 | K20: 45.7 | L20: 47 | M20: 0.1 | N20: 0.27 | O20: 3.02 | P20: 139 | Q20: 16 | AA20: BERGF
A21: 17 | B21: Birkenwäldchen | C21: Wittstocker Gäßchen 36 | D21: B – Beobachtung | E21: Stadt / privat | F21: 56 | G21: 3 | H21: 30065 | I21: 0 | J21: 16.8 | K21: 54.2 | L21: 3.3 | M21: 0 | N21: 9.78 | O21: 1.18 | P21: 56 | Q21: 17 | AA21: BIRKE
A22: 18 | B22: BKV Pfefferland | C22: Pfefferlander Weg 11 | D22: B – Beobachtung | E22: Privat | F22: 64 | G22: 0 | H22: 32712 | I22: 0.3 | J22: 28.5 | K22: 44.4 | L22: 14.5 | M22: 0 | N22: 7.78 | O22: 1.54 | P22: 64 | Q22: 73 | R22: 73 | AA22: PFEFF
A23: 19 | B23: Brielower Dreieck | C23: Am Industriegelande 1 | D23: A – Stabil | E23: Stadt BRB | F23: 35 | G23: 0 | H23: 15539 | I23: 1.3 | J23: 4.4 | K23: 30.4 | L23: 6.9 | M23: 0 | N23: 10.78 | O23: 6.72 | P23: 35 | Q23: 81 | R23: 81 | AA23: BRIDR
A24: 20 | B24: Buchenweg | C24: Buchenweg 77 | D24: B – Beobachtung | E24: Stadt BRB | F24: 86 | G24: 1 | H24: 49614 | I24: 5.4 | J24: 44.2 | K24: 38.1 | L24: 20.6 | M24: 0 | N24: 9.3 | O24: 1.65 | P24: 86 | Q24: 41 | R24: 41 | AA24: BW
A25: 21 | B25: Butterlake | C25: Brielower Aue 30 | D25: B – Beobachtung | E25: Stadt / privat | F25: 75 | G25: 1 | H25: 34343 | I25: 0 | J25: 37.3 | K25: 42.3 | L25: 32.1 | M25: 0.3 | N25: 8.22 | O25: 9.04 | P25: 75 | Q25: 33 | R25: 33 | AA25: BUTTL
A26: 22 | B26: Eichhorstweg | C26: Eichhorstweg 15 | D26: B – Beobachtung | E26: Privat | F26: 38 | G26: 1 | H26: 20436 | I26: 1.2 | J26: 13.9 | K26: 21.9 | L26: 11.6 | M26: 0 | N26: 9.53 | O26: 0.95 | P26: 38 | Q26: 22 | AA26: EICHH
A27: 23 | B27: Eigener Fleiß | C27: Hannoversche Str. 38 | D27: A – Stabil | E27: Stadt BRB | F27: 123 | G27: 0 | H27: 63177 | I27: 6.1 | J27: 44.7 | K27: 81.9 | L27: 49.7 | M27: 0 | N27: 7.81 | O27: 4.85 | P27: 123 | Q27: 23 | AA27: FLEIS
A28: 24 | B28: Einheit | C28: Thuringer Str. 18 | D28: A – Stabil | E28: Stadt BRB | F28: 99 | G28: 1 | H28: 49589 | I28: 4.8 | J28: 45.8 | K28: 49.2 | L28: 21.1 | M28: 0 | N28: 8.32 | O28: 4.92 | P28: 99 | Q28: 23 | R28: 23 | AA28: EINH
A29: 25 | B29: Einigkeit | C29: Klingenbergstr. 2b | D29: A – Stabil | E29: Stadt BRB | F29: 14 | G29: 0 | H29: 4670 | I29: 0.5 | J29: 3.2 | K29: 8.8 | L29: 1.2 | M29: 0 | N29: 9.44 | O29: 4.39 | P29: 14 | Q29: 56 | R29: 56 | AA29: EINIG
A30: 26 | B30: Eintracht I | C30: Franz-Ziegler-Str. 29b | D30: A – Stabil | E30: Stadt / privat | F30: 32 | G30: 1 | H30: 9606 | I30: 0.2 | J30: 7.9 | K30: 18.3 | L30: 4.2 | M30: 0 | N30: 10.46 | O30: 3.81 | P30: 32 | Q30: 23 | R30: 55 | AA30: EINT1
A31: 27 | B31: Eintracht II | C31: Gottiner Landstr. 17 | D31: A – Stabil | E31: k. A. | F31: 42 | G31: 2 | H31: 15820 | I31: 0 | J31: 24 | K31: 26.7 | L31: 8.7 | M31: 0 | N31: 10.2 | O31: 2.67 | P31: 42 | Q31: 17 | R31: 9 | AA31: EINT2
A32: 28 | B32: Erdenglück | C32: Johannisburger Anger 26 | D32: B – Beobachtung | E32: Stadt / privat | F32: 99 | G32: 2 | H32: 40185 | I32: 0.8 | J32: 39.9 | K32: 46.1 | L32: 42.3 | M32: 0 | N32: 6.72 | O32: 7.19 | P32: 96 | Q32: 28 | AA32: ERDGL
A33: 29 | B33: Erntesegen | C33: Brahmsstr. 12b | D33: A – Stabil | E33: Stadt / privat | F33: 92 | G33: 1 | H33: 43349 | I33: 4.4 | J33: 43.6 | K33: 42.2 | L33: 19.8 | M33: 0.4 | N33: 7.97 | O33: 6.74 | P33: 91 | Q33: 28 | R33: 28 | AA33: ERNTE
A34: 30 | B34: Feierabend | C34: Beethovenstr. 31 | D34: A – Stabil | E34: Stadt BRB | F34: 190 | G34: 5 | H34: 99039 | I34: 7.9 | J34: 61.8 | K34: 79.2 | L34: 81.3 | M34: 1.1 | N34: 8.64 | O34: 6.96 | P34: 190 | Q34: 30 | AA34: FEIER
A35: 31 | B35: Feldstraße | C35: Feldstraße 1c | D35: C – Qualifizierung | E35: Stadt BRB | F35: 68 | G35: 4 | H35: 35041 | I35: 1.1 | J35: 24.4 | K35: 32.2 | L35: 21.3 | M35: 0 | N35: 9.65 | O35: 2.54 | P35: 68 | Q35: 41 | R35: 60 | AA35: FELD
A36: 32 | B36: Finkenhain | C36: Mendelssohnstr. 13 | D36: C – Qualifizierung | E36: Stadt BRB | F36: 8 | G36: 0 | H36: 5992 | I36: 0 | J36: 0 | K36: 5.7 | L36: 1.5 | M36: 0 | N36: 7.35 | O36: 7.18 | P36: 8 | Q36: 28 | R36: 82 | AA36: FINK
A37: 33 | B37: Fohrder Landstraße | C37: Brielower Aue 33 | D37: A – Stabil | E37: Stadt / privat | F37: 127 | G37: 1 | H37: 71463 | I37: 1.5 | J37: 54 | K37: 51.7 | L37: 49.4 | M37: 1.6 | N37: 8.35 | O37: 8.76 | P37: 127 | Q37: 33 | AA37: FOHRD
A38: 34 | B38: Freiheit | C38: Feldstr. 1b | D38: C – Qualifizierung | E38: Stadt BRB | F38: 55 | G38: 6 | H38: 28864 | I38: 0 | J38: 30.6 | K38: 18.3 | L38: 6.9 | M38: 0 | N38: 9.86 | O38: 2.55 | P38: 55 | Q38: 49 | R38: 64 | AA38: FREIH
A39: 35 | B39: Freizeit | C39: Ziesarer Landstr. 64 | D39: B – Beobachtung | E39: Stadt / privat | F39: 63 | G39: 1 | H39: 32286 | I39: 1.7 | J39: 20.7 | K39: 28.8 | L39: 20.9 | M39: 0 | N39: 8.93 | O39: 1.91 | P39: 63 | Q39: 41 | R39: 2 | AA39: FREIZ
A40: 36 | B40: Friedland | C40: Klingenbergstr. 19 | D40: A – Stabil | E40: k. A. | F40: 64 | G40: 1 | H40: 29654 | I40: 0 | J40: 30.9 | K40: 24.3 | L40: 23.3 | M40: 0 | N40: 8.93 | O40: 4.49 | P40: 64 | Q40: 23 | R40: 24 | AA40: FRIED
A41: 37 | B41: Frisch Auf | C41: Klingenbergstr. 4 | D41: B – Beobachtung | E41: Stadt BRB | F41: 19 | G41: 1 | H41: 9927 | I41: 0 | J41: 3.7 | K41: 12.4 | L41: 4.9 | M41: 0 | N41: 9.24 | O41: 4.36 | P41: 19 | Q41: 56 | R41: 56 | AA41: FRISA
A42: 38 | B42: Frohsinn | C42: Ziesarer Landstr. 3 | D42: C – Qualifizierung | E42: Stadt / Kirche | F42: 54 | G42: 3 | H42: 29762 | I42: 0.4 | J42: 23.7 | K42: 33.5 | L42: 12.4 | M42: 0 | N42: 8.62 | O42: 1.78 | P42: 54 | Q42: 17 | R42: 9 | AA42: FROH
A43: 39 | B43: Gartenfreunde Brielower Aue | C43: Brielower Aue 47 | D43: B – Beobachtung | E43: Stadt / privat | F43: 69 | G43: 1 | H43: 39053 | I43: 2.4 | J43: 27.5 | K43: 27.7 | L43: 14.1 | M43: 0 | N43: 9.37 | O43: 9.04 | P43: 69 | Q43: 33 | R43: 33 | AA43: BRAUE
...

Sheet Buchungsquote
A1: Buchungsquote – berechnet aus Alter und Leerstand, fest oder je Sparte manuell
A2: Modus 1: Ø Buchungsneigung nach Alter × (1 − Leerstandsquote) × Faktor Entwicklungsstufe · Modus 2: feste Quote · „Quote manuell“ (Anlagen) hat Vorrang
A4: Nr. | B4: Kleingartenanlage | C4: Parzellen | D4: Leerstand | E4: Leerstands-quote | F4: Anteil bis 30 | G4: 30–50 | H4: 50–70 | I4: 70–90 | J4: ab 90 | K4: Ø Buchungs-neigung | L4: Faktor Stufe | M4: Quote heute (Alter) | N4: Pachtaufgabe 5 J. | O4: Nachbe-setzung | P4: Leerstand in 5 J. | Q4: Leerstands-quote 5 J. | R4: Neigung Bestand 5 J. | S4: Quote in 5 J. (Alter) | T4: Quote gewählt | U4: Herkunft | V4: Kunden
A5: =Anlagen!A5 -> 1 | B5: =Anlagen!B5 -> 1. März | C5: =Anlagen!F5 -> 30 | D5: =Anlagen!G5 -> 2 | E5: =D5/C5 -> 0.066666667 | F5: =Anlagen!I5/MAX(0.0001,SUM(Anlagen!I5:M5)) -> 0.01010101 | G5: =Anlagen!J5/MAX(0.0001,SUM(Anlagen!I5:M5)) -> 0.61363636 | H5: =Anlagen!K5/MAX(0.0001,SUM(Anlagen!I5:M5)) -> 0.27272727 | I5: =Anlagen!L5/MAX(0.0001,SUM(Anlagen!I5:M5)) -> 0.10353535 | J5: =Anlagen!M5/MAX(0.0001,SUM(Anlagen!I5:M5)) -> 0 | K5: =F5*Neig_1+G5*Neig_2+H5*Neig_3+I5*Neig_4+J5*Neig_5 -> 0.66818182 | L5: =IF(LEFT(Anlagen!D5,1)="A",Stufe_A,IF(LEFT(Anlagen!D5,1)="B",Stufe_B,IF(LEFT(Anlagen!D5,1)="C",Stufe_C,Stufe_D))) -> 1 | M5: =K5*(1-E5)*L5 -> 0.62363636 | N5: =F5*Abg_1+G5*Abg_2+H5*Abg_3+I5*Abg_4+J5*Abg_5 -> 0.089520202 | O5: =MAX(0,MIN(1,Nachbes-E5*Nachbes_Leer)) -> 0.56666667 | P5: =D5+(C5-D5)*N5*(1-O5) -> 3.0861785 | Q5: =P5/C5 -> 0.10287262 | R5: =(F5*(1-Abg_1)*Neig_1+G5*(1-Abg_2)*Neig_2+H5*(1-Abg_3)*Neig_3+I5*(1-Abg_4)*Neig_4+J5*(1-Abg_5)*Neig_5)/MAX(0.0001,1-N5) -> 0.67824851 | S5: =(C5-D5)*((1-N5)*R5+N5*O5*Neig_Neu)*L5/C5 -> 0.61187247 | T5: =IF(Anlagen!W5<>"",Anlagen!W5,IF(Quote_Modus=2,Quote_fest,IF(Szenario=2,S5,M5))) -> 0.62363636 | U5: =IF(Anlagen!W5<>"","manuell",IF(Quote_Modus=2,"fest",IF(Szenario=2,"Alter, in 5 J.","Alter, heute"))) -> Alter, heute | V5: =C5*T5 -> 18.709091
A6: =Anlagen!A6 -> 2 | B6: =Anlagen!B6 -> Abendfrieden | C6: =Anlagen!F6 -> 75 | D6: =Anlagen!G6 -> 4 | E6: =D6/C6 -> 0.053333333 | F6: =Anlagen!I6/MAX(0.0001,SUM(Anlagen!I6:M6)) -> 0 | G6: =Anlagen!J6/MAX(0.0001,SUM(Anlagen!I6:M6)) -> 0.44444444 | H6: =Anlagen!K6/MAX(0.0001,SUM(Anlagen!I6:M6)) -> 0.40217391 | I6: =Anlagen!L6/MAX(0.0001,SUM(Anlagen!I6:M6)) -> 0.15338164 | J6: =Anlagen!M6/MAX(0.0001,SUM(Anlagen!I6:M6)) -> 0 | K6: =F6*Neig_1+G6*Neig_2+H6*Neig_3+I6*Neig_4+J6*Neig_5 -> 0.62832126 | L6: =IF(LEFT(Anlagen!D6,1)="A",Stufe_A,IF(LEFT(Anlagen!D6,1)="B",Stufe_B,IF(LEFT(Anlagen!D6,1)="C",Stufe_C,Stufe_D))) -> 0.9 | M6: =K6*(1-E6)*L6 -> 0.53532971 | N6: =F6*Abg_1+G6*Abg_2+H6*Abg_3+I6*Abg_4+J6*Abg_5 -> 0.10845411 | O6: =MAX(0,MIN(1,Nachbes-E6*Nachbes_Leer)) -> 0.59333333 | P6: =D6+(C6-D6)*N6*(1-O6) -> 7.1314316 | Q6: =P6/C6 -> 0.095085754 | R6: =(F6*(1-Abg_1)*Neig_1+G6*(1-Abg_2)*Neig_2+H6*(1-Abg_3)*Neig_3+I6*(1-Abg_4)*Neig_4+J6*(1-Abg_5)*Neig_5)/MAX(0.0001,1-N6) -> 0.64093064 | S6: =(C6-D6)*((1-N6)*R6+N6*O6*Neig_Neu)*L6/C6 -> 0.52796835 | T6: =IF(Anlagen!W6<>"",Anlagen!W6,IF(Quote_Modus=2,Quote_fest,IF(Szenario=2,S6,M6))) -> 0.53532971 | U6: =IF(Anlagen!W6<>"","manuell",IF(Quote_Modus=2,"fest",IF(Szenario=2,"Alter, in 5 J.","Alter, heute"))) -> Alter, heute | V6: =C6*T6 -> 40.149728
A7: =Anlagen!A7 -> 3 | B7: =Anlagen!B7 -> Abendrot | C7: =Anlagen!F7 -> 137 | D7: =Anlagen!G7 -> 0 | E7: =D7/C7 -> 0 | F7: =Anlagen!I7/MAX(0.0001,SUM(Anlagen!I7:M7)) -> 0.0079325731 | G7: =Anlagen!J7/MAX(0.0001,SUM(Anlagen!I7:M7)) -> 0.21070897 | H7: =Anlagen!K7/MAX(0.0001,SUM(Anlagen!I7:M7)) -> 0.52404561 | I7: =Anlagen!L7/MAX(0.0001,SUM(Anlagen!I7:M7)) -> 0.25731284 | J7: =Anlagen!M7/MAX(0.0001,SUM(Anlagen!I7:M7)) -> 0 | K7: =F7*Neig_1+G7*Neig_2+H7*Neig_3+I7*Neig_4+J7*Neig_5 -> 0.56886465 | L7: =IF(LEFT(Anlagen!D7,1)="A",Stufe_A,IF(LEFT(Anlagen!D7,1)="B",Stufe_B,IF(LEFT(Anlagen!D7,1)="C",Stufe_C,Stufe_D))) -> 1 | M7: =K7*(1-E7)*L7 -> 0.56886465 | N7: =F7*Abg_1+G7*Abg_2+H7*Abg_3+I7*Abg_4+J7*Abg_5 -> 0.14053049 | O7: =MAX(0,MIN(1,Nachbes-E7*Nachbes_Leer)) -> 0.7 | P7: =D7+(C7-D7)*N7*(1-O7) -> 5.7758032 | Q7: =P7/C7 -> 0.042159147 | R7: =(F7*(1-Abg_1)*Neig_1+G7*(1-Abg_2)*Neig_2+H7*(1-Abg_3)*Neig_3+I7*(1-Abg_4)*Neig_4+J7*(1-Abg_5)*Neig_5)/MAX(0.0001,1-N7) -> 0.58429667 | S7: =(C7-D7)*((1-N7)*R7+N7*O7*Neig_Neu)*L7/C7 -> 0.57596368 | T7: =IF(Anlagen!W7<>"",Anlagen!W7,IF(Quote_Modus=2,Quote_fest,IF(Szenario=2,S7,M7))) -> 0.56886465 | U7: =IF(Anlagen!W7<>"","manuell",IF(Quote_Modus=2,"fest",IF(Szenario=2,"Alter, in 5 J.","Alter, heute"))) -> Alter, heute | V7: =C7*T7 -> 77.934457
A8: =Anlagen!A8 -> 4 | B8: =Anlagen!B8 -> Abendruh | C8: =Anlagen!F8 -> 142 | D8: =Anlagen!G8 -> 0 | E8: =D8/C8 -> 0 | F8: =Anlagen!I8/MAX(0.0001,SUM(Anlagen!I8:M8)) -> 0.015837104 | G8: =Anlagen!J8/MAX(0.0001,SUM(Anlagen!I8:M8)) -> 0.26527149 | H8: =Anlagen!K8/MAX(0.0001,SUM(Anlagen!I8:M8)) -> 0.40384615 | I8: =Anlagen!L8/MAX(0.0001,SUM(Anlagen!I8:M8)) -> 0.29920814 | J8: =Anlagen!M8/MAX(0.0001,SUM(Anlagen!I8:M8)) -> 0.015837104 | K8: =F8*Neig_1+G8*Neig_2+H8*Neig_3+I8*Neig_4+J8*Neig_5 -> 0.56023756 | L8: =IF(LEFT(Anlagen!D8,1)="A",Stufe_A,IF(LEFT(Anlagen!D8,1)="B",Stufe_B,IF(LEFT(Anlagen!D8,1)="C",Stufe_C,Stufe_D))) -> 1 | M8: =K8*(1-E8)*L8 -> 0.56023756 | N8: =F8*Abg_1+G8*Abg_2+H8*Abg_3+I8*Abg_4+J8*Abg_5 -> 0.15370475 | O8: =MAX(0,MIN(1,Nachbes-E8*Nachbes_Leer)) -> 0.7 | P8: =D8+(C8-D8)*N8*(1-O8) -> 6.5478224 | Q8: =P8/C8 -> 0.046111425 | R8: =(F8*(1-Abg_1)*Neig_1+G8*(1-Abg_2)*Neig_2+H8*(1-Abg_3)*Neig_3+I8*(1-Abg_4)*Neig_4+J8*(1-Abg_5)*Neig_5)/MAX(0.0001,1-N8) -> 0.58260819 | S8: =(C8-D8)*((1-N8)*R8+N8*O8*Neig_Neu)*L8/C8 -> 0.57375354 | T8: =IF(Anlagen!W8<>"",Anlagen!W8,IF(Quote_Modus=2,Quote_fest,IF(Szenario=2,S8,M8))) -> 0.56023756 | U8: =IF(Anlagen!W8<>"","manuell",IF(Quote_Modus=2,"fest",IF(Szenario=2,"Alter, in 5 J.","Alter, heute"))) -> Alter, heute | V8: =C8*T8 -> 79.553733
A9: =Anlagen!A9 -> 5 | B9: =Anlagen!B9 -> Abendsonne | C9: =Anlagen!F9 -> 67 | D9: =Anlagen!G9 -> 13 | E9: =D9/C9 -> 0.19402985 | F9: =Anlagen!I9/MAX(0.0001,SUM(Anlagen!I9:M9)) -> 0.027597403 | G9: =Anlagen!J9/MAX(0.0001,SUM(Anlagen!I9:M9)) -> 0.34902597 | H9: =Anlagen!K9/MAX(0.0001,SUM(Anlagen!I9:M9)) -> 0.49188312 | I9: =Anlagen!L9/MAX(0.0001,SUM(Anlagen!I9:M9)) -> 0.13149351 | J9: =Anlagen!M9/MAX(0.0001,SUM(Anlagen!I9:M9)) -> 0 | K9: =F9*Neig_1+G9*Neig_2+H9*Neig_3+I9*Neig_4+J9*Neig_5 -> 0.625 | L9: =IF(LEFT(Anlagen!D9,1)="A",Stufe_A,IF(LEFT(Anlagen!D9,1)="B",Stufe_B,IF(LEFT(Anlagen!D9,1)="C",Stufe_C,Stufe_D))) -> 1 | M9: =K9*(1-E9)*L9 -> 0.50373134 | N9: =F9*Abg_1+G9*Abg_2+H9*Abg_3+I9*Abg_4+J9*Abg_5 -> 0.10746753 | O9: =MAX(0,MIN(1,Nachbes-E9*Nachbes_Leer)) -> 0.3119403 | P9: =D9+(C9-D9)*N9*(1-O9) -> 16.99298 | Q9: =P9/C9 -> 0.25362657 | R9: =(F9*(1-Abg_1)*Neig_1+G9*(1-Abg_2)*Neig_2+H9*(1-Abg_3)*Neig_3+I9*(1-Abg_4)*Neig_4+J9*(1-Abg_5)*Neig_5)/MAX(0.0001,1-N9) -> 0.63581757 | S9: =(C9-D9)*((1-N9)*R9+N9*O9*Neig_Neu)*L9/C9 -> 0.47764242 | T9: =IF(Anlagen!W9<>"",Anlagen!W9,IF(Quote_Modus=2,Quote_fest,IF(Szenario=2,S9,M9))) -> 0.50373134 | U9: =IF(Anlagen!W9<>"","manuell",IF(Quote_Modus=2,"fest",IF(Szenario=2,"Alter, in 5 J.","Alter, heute"))) -> Alter, heute | V9: =C9*T9 -> 33.75
A10: =Anlagen!A10 -> 6 | B10: =Anlagen!B10 -> Altstadt Forst | C10: =Anlagen!F10 -> 88 | D10: =Anlagen!G10 -> 0 | E10: =D10/C10 -> 0 | F10: =Anlagen!I10/MAX(0.0001,SUM(Anlagen!I10:M10)) -> 0.015837104 | G10: =Anlagen!J10/MAX(0.0001,SUM(Anlagen!I10:M10)) -> 0.26527149 | H10: =Anlagen!K10/MAX(0.0001,SUM(Anlagen!I10:M10)) -> 0.40384615 | I10: =Anlagen!L10/MAX(0.0001,SUM(Anlagen!I10:M10)) -> 0.29920814 | J10: =Anlagen!M10/MAX(0.0001,SUM(Anlagen!I10:M10)) -> 0.015837104 | K10: =F10*Neig_1+G10*Neig_2+H10*Neig_3+I10*Neig_4+J10*Neig_5 -> 0.56023756 | L10: =IF(LEFT(Anlagen!D10,1)="A",Stufe_A,IF(LEFT(Anlagen!D10,1)="B",Stufe_B,IF(LEFT(Anlagen!D10,1)="C",Stufe_C,Stufe_D))) -> 1 | M10: =K10*(1-E10)*L10 -> 0.56023756 | N10: =F10*Abg_1+G10*Abg_2+H10*Abg_3+I10*Abg_4+J10*Abg_5 -> 0.15370475 | O10: =MAX(0,MIN(1,Nachbes-E10*Nachbes_Leer)) -> 0.7 | P10: =D10+(C10-D10)*N10*(1-O10) -> 4.0578054 | Q10: =P10/C10 -> 0.046111425 | R10: =(F10*(1-Abg_1)*Neig_1+G10*(1-Abg_2)*Neig_2+H10*(1-Abg_3)*Neig_3+I10*(1-Abg_4)*Neig_4+J10*(1-Abg_5)*Neig_5)/MAX(0.0001,1-N10) -> 0.58260819 | S10: =(C10-D10)*((1-N10)*R10+N10*O10*Neig_Neu)*L10/C10 -> 0.57375354 | T10: =IF(Anlagen!W10<>"",Anlagen!W10,IF(Quote_Modus=2,Quote_fest,IF(Szenario=2,S10,M10))) -> 0.56023756 | U10: =IF(Anlagen!W10<>"","manuell",IF(Quote_Modus=2,"fest",IF(Szenario=2,"Alter, in 5 J.","Alter, heute"))) -> Alter, heute | V10: =C10*T10 -> 49.300905
A11: =Anlagen!A11 -> 7 | B11: =Anlagen!B11 -> Am Beetzseeufer | C11: =Anlagen!F11 -> 77 | D11: =Anlagen!G11 -> 0 | E11: =D11/C11 -> 0 | F11: =Anlagen!I11/MAX(0.0001,SUM(Anlagen!I11:M11)) -> 0.00085910653 | G11: =Anlagen!J11/MAX(0.0001,SUM(Anlagen!I11:M11)) -> 0.38573883 | H11: =Anlagen!K11/MAX(0.0001,SUM(Anlagen!I11:M11)) -> 0.5128866 | I11: =Anlagen!L11/MAX(0.0001,SUM(Anlagen!I11:M11)) -> 0.10051546 | J11: =Anlagen!M11/MAX(0.0001,SUM(Anlagen!I11:M11)) -> 0 | K11: =F11*Neig_1+G11*Neig_2+H11*Neig_3+I11*Neig_4+J11*Neig_5 -> 0.63290378 | L11: =IF(LEFT(Anlagen!D11,1)="A",Stufe_A,IF(LEFT(Anlagen!D11,1)="B",Stufe_B,IF(LEFT(Anlagen!D11,1)="C",Stufe_C,Stufe_D))) -> 1 | M11: =K11*(1-E11)*L11 -> 0.63290378 | N11: =F11*Abg_1+G11*Abg_2+H11*Abg_3+I11*Abg_4+J11*Abg_5 -> 0.1007732 | O11: =MAX(0,MIN(1,Nachbes-E11*Nachbes_Leer)) -> 0.7 | P11: =D11+(C11-D11)*N11*(1-O11) -> 2.3278608 | Q11: =P11/C11 -> 0.030231959 | R11: =(F11*(1-Abg_1)*Neig_1+G11*(1-Abg_2)*Neig_2+H11*(1-Abg_3)*Neig_3+I11*(1-Abg_4)*Neig_4+J11*(1-Abg_5)*Neig_5)/MAX(0.0001,1-N11) -> 0.64174787 | S11: =(C11-D11)*((1-N11)*R11+N11*O11*Neig_Neu)*L11/C11 -> 0.62998282 | T11: =IF(Anlagen!W11<>"",Anlagen!W11,IF(Quote_Modus=2,Quote_fest,IF(Szenario=2,S11,M11))) -> 0.63290378 | U11: =IF(Anlagen!W11<>"","manuell",IF(Quote_Modus=2,"fest",IF(Szenario=2,"Alter, in 5 J.","Alter, heute"))) -> Alter, heute | V11: =C11*T11 -> 48.733591
A12: =Anlagen!A12 -> 8 | B12: =Anlagen!B12 -> Am Büttelhandfassgraben | C12: =Anlagen!F12 -> 5 | D12: =Anlagen!G12 -> 0 | E12: =D12/C12 -> 0 | F12: =Anlagen!I12/MAX(0.0001,SUM(Anlagen!I12:M12)) -> 0.39285714 | G12: =Anlagen!J12/MAX(0.0001,SUM(Anlagen!I12:M12)) -> 0 | H12: =Anlagen!K12/MAX(0.0001,SUM(Anlagen!I12:M12)) -> 0.60714286 | I12: =Anlagen!L12/MAX(0.0001,SUM(Anlagen!I12:M12)) -> 0 | J12: =Anlagen!M12/MAX(0.0001,SUM(Anlagen!I12:M12)) -> 0 | K12: =F12*Neig_1+G12*Neig_2+H12*Neig_3+I12*Neig_4+J12*Neig_5 -> 0.67857143 | L12: =IF(LEFT(Anlagen!D12,1)="A",Stufe_A,IF(LEFT(Anlagen!D12,1)="B",Stufe_B,IF(LEFT(Anlagen!D12,1)="C",Stufe_C,Stufe_D))) -> 1 | M12: =K12*(1-E12)*L12 -> 0.67857143 | N12: =F12*Abg_1+G12*Abg_2+H12*Abg_3+I12*Abg_4+J12*Abg_5 -> 0.080357143 | O12: =MAX(0,MIN(1,Nachbes-E12*Nachbes_Leer)) -> 0.7 | P12: =D12+(C12-D12)*N12*(1-O12) -> 0.12053571 | Q12: =P12/C12 -> 0.024107143 | R12: =(F12*(1-Abg_1)*Neig_1+G12*(1-Abg_2)*Neig_2+H12*(1-Abg_3)*Neig_3+I12*(1-Abg_4)*Neig_4+J12*(1-Abg_5)*Neig_5)/MAX(0.0001,1-N12) -> 0.68116505 | S12: =(C12-D12)*((1-N12)*R12+N12*O12*Neig_Neu)*L12/C12 -> 0.66861607 | T12: =IF(Anlagen!W12<>"",Anlagen!W12,IF(Quote_Modus=2,Quote_fest,IF(Szenario=2,S12,M12))) -> 0.67857143 | U12: =IF(Anlagen!W12<>"","manuell",IF(Quote_Modus=2,"fest",IF(Szenario=2,"Alter, in 5 J.","Alter, heute"))) -> Alter, heute | V12: =C12*T12 -> 3.3928571
A13: =Anlagen!A13 -> 9 | B13: =Anlagen!B13 -> Am Eichenweg | C13: =Anlagen!F13 -> 54 | D13: =Anlagen!G13 -> 2 | E13: =D13/C13 -> 0.037037037 | F13: =Anlagen!I13/MAX(0.0001,SUM(Anlagen!I13:M13)) -> 0.013846154 | G13: =Anlagen!J13/MAX(0.0001,SUM(Anlagen!I13:M13)) -> 0.50769231 | H13: =Anlagen!K13/MAX(0.0001,SUM(Anlagen!I13:M13)) -> 0.34153846 | I13: =Anlagen!L13/MAX(0.0001,SUM(Anlagen!I13:M13)) -> 0.13692308 | J13: =Anlagen!M13/MAX(0.0001,SUM(Anlagen!I13:M13)) -> 0 | K13: =F13*Neig_1+G13*Neig_2+H13*Neig_3+I13*Neig_4+J13*Neig_5 -> 0.64469231 | L13: =IF(LEFT(Anlagen!D13,1)="A",Stufe_A,IF(LEFT(Anlagen!D13,1)="B",Stufe_B,IF(LEFT(Anlagen!D13,1)="C",Stufe_C,Stufe_D))) -> 0.9 | M13: =K13*(1-E13)*L13 -> 0.55873333 | N13: =F13*Abg_1+G13*Abg_2+H13*Abg_3+I13*Abg_4+J13*Abg_5 -> 0.10130769 | O13: =MAX(0,MIN(1,Nachbes-E13*Nachbes_Leer)) -> 0.62592593 | P13: =D13+(C13-D13)*N13*(1-O13) -> 3.9706222 | Q13: =P13/C13 -> 0.073530041 | R13: =(F13*(1-Abg_1)*Neig_1+G13*(1-Abg_2)*Neig_2+H13*(1-Abg_3)*Neig_3+I13*(1-Abg_4)*Neig_4+J13*(1-Abg_5)*Neig_5)/MAX(0.0001,1-N13) -> 0.65676624 | S13: =(C13-D13)*((1-N13)*R13+N13*O13*Neig_Neu)*L13/C13 -> 0.55275056 | T13: =IF(Anlagen!W13<>"",Anlagen!W13,IF(Quote_Modus=2,Quote_fest,IF(Szenario=2,S13,M13))) -> 0.55873333 | U13: =IF(Anlagen!W13<>"","manuell",IF(Quote_Modus=2,"fest",IF(Szenario=2,"Alter, in 5 J.","Alter, heute"))) -> Alter, heute | V13: =C13*T13 -> 30.1716
A14: =Anlagen!A14 -> 10 | B14: =Anlagen!B14 -> Am Jakobsgraben | C14: =Anlagen!F14 -> 41 | D14: =Anlagen!G14 -> 0 | E14: =D14/C14 -> 0 | F14: =Anlagen!I14/MAX(0.0001,SUM(Anlagen!I14:M14)) -> 0.0079840319 | G14: =Anlagen!J14/MAX(0.0001,SUM(Anlagen!I14:M14)) -> 0.3493014 | H14: =Anlagen!K14/MAX(0.0001,SUM(Anlagen!I14:M14)) -> 0.4510978 | I14: =Anlagen!L14/MAX(0.0001,SUM(Anlagen!I14:M14)) -> 0.19161677 | J14: =Anlagen!M14/MAX(0.0001,SUM(Anlagen!I14:M14)) -> 0 | K14: =F14*Neig_1+G14*Neig_2+H14*Neig_3+I14*Neig_4+J14*Neig_5 -> 0.60608782 | L14: =IF(LEFT(Anlagen!D14,1)="A",Stufe_A,IF(LEFT(Anlagen!D14,1)="B",Stufe_B,IF(LEFT(Anlagen!D14,1)="C",Stufe_C,Stufe_D))) -> 0.75 | M14: =K14*(1-E14)*L14 -> 0.45456587 | N14: =F14*Abg_1+G14*Abg_2+H14*Abg_3+I14*Abg_4+J14*Abg_5 -> 0.12045908 | O14: =MAX(0,MIN(1,Nachbes-E14*Nachbes_Leer)) -> 0.7 | P14: =D14+(C14-D14)*N14*(1-O14) -> 1.4816467 | Q14: =P14/C14 -> 0.036137725 | R14: =(F14*(1-Abg_1)*Neig_1+G14*(1-Abg_2)*Neig_2+H14*(1-Abg_3)*Neig_3+I14*(1-Abg_4)*Neig_4+J14*(1-Abg_5)*Neig_5)/MAX(0.0001,1-N14) -> 0.62019176 | S14: =(C14-D14)*((1-N14)*R14+N14*O14*Neig_Neu)*L14/C14 -> 0.45654379 | T14: =IF(Anlagen!W14<>"",Anlagen!W14,IF(Quote_Modus=2,Quote_fest,IF(Szenario=2,S14,M14))) -> 0.45456587 | U14: =IF(Anlagen!W14<>"","manuell",IF(Quote_Modus=2,"fest",IF(Szenario=2,"Alter, in 5 J.","Alter, heute"))) -> Alter, heute | V14: =C14*T14 -> 18.637201
A15: =Anlagen!A15 -> 11 | B15: =Anlagen!B15 -> Am Schafdamm | C15: =Anlagen!F15 -> 10 | D15: =Anlagen!G15 -> 0 | E15: =D15/C15 -> 0 | F15: =Anlagen!I15/MAX(0.0001,SUM(Anlagen!I15:M15)) -> 0 | G15: =Anlagen!J15/MAX(0.0001,SUM(Anlagen!I15:M15)) -> 0.13675214 | H15: =Anlagen!K15/MAX(0.0001,SUM(Anlagen!I15:M15)) -> 0.43589744 | I15: =Anlagen!L15/MAX(0.0001,SUM(Anlagen!I15:M15)) -> 0.42735043 | J15: =Anlagen!M15/MAX(0.0001,SUM(Anlagen!I15:M15)) -> 0 | K15: =F15*Neig_1+G15*Neig_2+H15*Neig_3+I15*Neig_4+J15*Neig_5 -> 0.51367521 | L15: =IF(LEFT(Anlagen!D15,1)="A",Stufe_A,IF(LEFT(Anlagen!D15,1)="B",Stufe_B,IF(LEFT(Anlagen!D15,1)="C",Stufe_C,Stufe_D))) -> 0.9 | M15: =K15*(1-E15)*L15 -> 0.46230769 | N15: =F15*Abg_1+G15*Abg_2+H15*Abg_3+I15*Abg_4+J15*Abg_5 -> 0.17863248 | O15: =MAX(0,MIN(1,Nachbes-E15*Nachbes_Leer)) -> 0.7 | P15: =D15+(C15-D15)*N15*(1-O15) -> 0.53589744 | Q15: =P15/C15 -> 0.053589744 | R15: =(F15*(1-Abg_1)*Neig_1+G15*(1-Abg_2)*Neig_2+H15*(1-Abg_3)*Neig_3+I15*(1-Abg_4)*Neig_4+J15*(1-Abg_5)*Neig_5)/MAX(0.0001,1-N15) -> 0.5326743 | S15: =(C15-D15)*((1-N15)*R15+N15*O15*Neig_Neu)*L15/C15 -> 0.47817308 | T15: =IF(Anlagen!W15<>"",Anlagen!W15,IF(Quote_Modus=2,Quote_fest,IF(Szenario=2,S15,M15))) -> 0.46230769 | U15: =IF(Anlagen!W15<>"","manuell",IF(Quote_Modus=2,"fest",IF(Szenario=2,"Alter, in 5 J.","Alter, heute"))) -> Alter, heute | V15: =C15*T15 -> 4.6230769
A16: =Anlagen!A16 -> 12 | B16: =Anlagen!B16 -> Am Schlangenpfad | C16: =Anlagen!F16 -> 19 | D16: =Anlagen!G16 -> 0 | E16: =D16/C16 -> 0 | F16: =Anlagen!I16/MAX(0.0001,SUM(Anlagen!I16:M16)) -> 0 | G16: =Anlagen!J16/MAX(0.0001,SUM(Anlagen!I16:M16)) -> 0.11111111 | H16: =Anlagen!K16/MAX(0.0001,SUM(Anlagen!I16:M16)) -> 0.32950192 | I16: =Anlagen!L16/MAX(0.0001,SUM(Anlagen!I16:M16)) -> 0.55938697 | J16: =Anlagen!M16/MAX(0.0001,SUM(Anlagen!I16:M16)) -> 0 | K16: =F16*Neig_1+G16*Neig_2+H16*Neig_3+I16*Neig_4+J16*Neig_5 -> 0.47681992 | L16: =IF(LEFT(Anlagen!D16,1)="A",Stufe_A,IF(LEFT(Anlagen!D16,1)="B",Stufe_B,IF(LEFT(Anlagen!D16,1)="C",Stufe_C,Stufe_D))) -> 0.9 | M16: =K16*(1-E16)*L16 -> 0.42913793 | N16: =F16*Abg_1+G16*Abg_2+H16*Abg_3+I16*Abg_4+J16*Abg_5 -> 0.20632184 | O16: =MAX(0,MIN(1,Nachbes-E16*Nachbes_Leer)) -> 0.7 | P16: =D16+(C16-D16)*N16*(1-O16) -> 1.1760345 | Q16: =P16/C16 -> 0.061896552 | R16: =(F16*(1-Abg_1)*Neig_1+G16*(1-Abg_2)*Neig_2+H16*(1-Abg_3)*Neig_3+I16*(1-Abg_4)*Neig_4+J16*(1-Abg_5)*Neig_5)/MAX(0.0001,1-N16) -> 0.49660874 | S16: =(C16-D16)*((1-N16)*R16+N16*O16*Neig_Neu)*L16/C16 -> 0.45221983 | T16: =IF(Anlagen!W16<>"",Anlagen!W16,IF(Quote_Modus=2,Quote_fest,IF(Szenario=2,S16,M16))) -> 0.42913793 | U16: =IF(Anlagen!W16<>"","manuell",IF(Quote_Modus=2,"fest",IF(Szenario=2,"Alter, in 5 J.","Alter, heute"))) -> Alter, heute | V16: =C16*T16 -> 8.1536207
... A92: =Anlagen!A92 -> 88 | B92: =Anlagen!B92 -> Zur Insel | C92: =Anlagen!F92 -> 86 | D92: =Anlagen!G92 -> 0 | E92: =D92/C92 -> 0 | F92: =Anlagen!I92/MAX(0.0001,SUM(Anlagen!I92:M92)) -> 0 | G92: =Anlagen!J92/MAX(0.0001,SUM(Anlagen!I92:M92)) -> 0.20941402 | H92: =Anlagen!K92/MAX(0.0001,SUM(Anlagen!I92:M92)) -> 0.51488953 | I92: =Anlagen!L92/MAX(0.0001,SUM(Anlagen!I92:M92)) -> 0.27569645 | J92: =Anlagen!M92/MAX(0.0001,SUM(Anlagen!I92:M92)) -> 0 | K92: =F92*Neig_1+G92*Neig_2+H92*Neig_3+I92*Neig_4+J92*Neig_5 -> 0.56248799 | L92: =IF(LEFT(Anlagen!D92,1)="A",Stufe_A,IF(LEFT(Anlagen!D92,1)="B",Stufe_B,IF(LEFT(Anlagen!D92,1)="C",Stufe_C,Stufe_D))) -> 1 | M92: =K92*(1-E92)*L92 -> 0.56248799 | N92: =F92*Abg_1+G92*Abg_2+H92*Abg_3+I92*Abg_4+J92*Abg_5 -> 0.14466859 | O92: =MAX(0,MIN(1,Nachbes-E92*Nachbes_Leer)) -> 0.7 | P92: =D92+(C92-D92)*N92*(1-O92) -> 3.7324496 | Q92: =P92/C92 -> 0.043400576 | R92: =(F92*(1-Abg_1)*Neig_1+G92*(1-Abg_2)*Neig_2+H92*(1-Abg_3)*Neig_3+I92*(1-Abg_4)*Neig_4+J92*(1-Abg_5)*Neig_5)/MAX(0.0001,1-N92) -> 0.57848158 | S92: =(C92-D92)*((1-N92)*R92+N92*O92*Neig_Neu)*L92/C92 -> 0.57074448 | T92: =IF(Anlagen!W92<>"",Anlagen!W92,IF(Quote_Modus=2,Quote_fest,IF(Szenario=2,S92,M92))) -> 0.56248799 | U92: =IF(Anlagen!W92<>"","manuell",IF(Quote_Modus=2,"fest",IF(Szenario=2,"Alter, in 5 J.","Alter, heute"))) -> Alter, heute | V92: =C92*T92 -> 48.373967
B93: Summe / Ø | C93: =SUM(C5:C92) -> 5017 | D93: =SUM(D5:D92) -> 171 | E93: =D93/C93 -> 0.034084114 | M93: =SUMPRODUCT(C5:C92,M5:M92)/C93 -> 0.56105513 | P93: =SUM(P5:P92) -> 396.97271 | Q93: =P93/C93 -> 0.079125515 | S93: =SUMPRODUCT(C5:C92,S5:S92)/C93 -> 0.56106063 | T93: =V93/C93 -> 0.56105513 | V93: =SUM(V5:V92) -> 2814.8136

Sheet Netz
A1: Netz – Gateway-Standort, Glasfaser-Zuleitung und Gateway-Belegung je Sparte
A2: Gateways eines Standorts werden in der Reihenfolge gefüllt (je 55 Parzellen) · Zuleitung von Sparte zu Sparte per Glasfaser
A4: Nr. | B4: Kleingartenanlage | C4: Gateway-Standort (wirksam) | D4: Zuleitung von (wirksam) | E4: Rolle | F4: Entfernung km | G4: Glasfaser Zuleitung m | H4: Zuleitung € | I4: Unterverteiler € | J4: Sortierung | K4: Parzellen davor am Standort | L4: Gateway von | M4: Gateway bis | N4: versorgt durch | O4: Kunden | P4: Prüfung | Q4: Kürzel | R4: VLAN-Block | S4: VLAN Parzellen von | T4: VLAN Parzellen bis | U4: VLAN Vorstand | V4: VLAN Gäste | W4: VLAN Technik | X4: Subnetz Parzelle 1 | Y4: Prüfung VLAN
A5: =Anlagen!A5 -> 1 | B5: =Anlagen!B5 -> 1. März | C5: =IF(Anlagen!S5<>"",Anlagen!S5,IF(Vorschlag_nutzen=1,Anlagen!Q5,A5)) -> 33 | D5: =IF(C5=A5,"",IF(Anlagen!T5<>"",Anlagen!T5,IF(AND(Anlagen!S5="",Vorschlag_nutzen=1,Anlagen!R5<>""),Anlagen!R5,C5))) -> 6 | E5: =IF(C5=A5,IF(COUNTIF($C$5:$C$92,A5)>1,"Gateway-Standort","eigenständig"),"über "&IFERROR(INDEX(Anlagen!$B$5:$B$92,MATCH(D5,Anlagen!$A$5:$A$92,0)),"?")) -> über Altstadt Forst | F5: =IF(C5=A5,0,IF(Anlagen!V5<>"",Anlagen!V5/1000,IFERROR(SQRT((Anlagen!N5-INDEX(Anlagen!$N$5:$N$92,MATCH(D5,Anlagen!$A$5:$A$92,0)))^2+(Anlagen!O5-INDEX(Anlagen!$O$5:$O$92,MATCH(D5,Anlagen!$A$5:$A$92,0)))^2),0))) -> 0.89643739 | G5: =IF(C5=A5,0,IF(Anlagen!V5<>"",Anlagen!V5,F5*1000*Umweg)) -> 1165.3686 | H5: =IF(C5=A5,0,(G5*(P_Faser+P_Tiefbau)+2*P_SFP+P_MontZul)*EK) -> 2310.805 | I5: =IF(C5=A5,0,(P_Saeule+P_Flex+P_NT+P_Halter+P_Luefter+P_Spleiss+P_Ueber)*EK) -> 851.326 | J5: =IF(Anlagen!U5<>"",Anlagen!U5,IF(C5=A5,500,1000)+ROW()) -> 1005 | K5: =SUMIFS(Anlagen!$F$5:$F$92,$C$5:$C$92,C5,$J$5:$J$92,"<"&J5) -> 127 | L5: =INT(K5/PG)+1 -> 3 | M5: =MAX(L5,CEILING((K5+Anlagen!F5)/PG,1)) -> 3 | N5: =IFERROR(INDEX(Anlagen!$B$5:$B$92,MATCH(C5,Anlagen!$A$5:$A$92,0)),"?")&": GW "&L5&IF(M5>L5,"–"&M5,"") -> Fohrder Landstraße: GW 3 | O5: =Buchungsquote!V5 -> 18.709091 | P5: =IF(ISNA(MATCH(C5,Anlagen!$A$5:$A$92,0)),"Fehler: Standort unbekannt",IF(C5=A5,"OK",IF(INDEX($C$5:$C$92,MATCH(C5,Anlagen!$A$5:$A$92,0))<>C5,"Fehler: Standort hängt selbst an anderem Standort",IF(D5=A5,"Fehler: Zuleitung von sich selbst",IF(ISNA(MATCH(D5,Anlagen!$A$5:$A$92,0)),"Fehler: Zuleitung unbekannt",IF(INDEX($C$5:$C$92,MATCH(D5,Anlagen!$A$5:$A$92,0))<>C5,"Fehler: Zuleitung hängt an anderem Standort","OK")))))) -> OK | Q5: =Anlagen!AA5 -> MAERZ | R5: =IF(Anlagen!AB5<>"",Anlagen!AB5,COUNTIFS($C$5:$C$92,C5,$J$5:$J$92,"<"&J5)+1) -> 2 | S5: =1000+200*(R5-1)+1 -> 1201 | T5: =1000+200*(R5-1)+Anlagen!F5 -> 1230 | U5: =100+A5 -> 101 | V5: =200+A5 -> 201 | W5: =300+A5 -> 301 | X5: ="10."&A5&".1.0/24" -> 10.1.1.0/24 | Y5: =IF(R5>15,"Fehler: VLAN-Block über 15",IF(COUNTIFS($C$5:$C$92,C5,$R$5:$R$92,R5)>1,"Fehler: VLAN-Block am Standort doppelt",IF(COUNTIF($Q$5:$Q$92,Q5)>1,"Fehler: Kürzel doppelt",IF(Anlagen!F5>199,"Fehler: mehr als 199 Parzellen","OK")))) -> OK
A6: =Anlagen!A6 -> 2 | B6: =Anlagen!B6 -> Abendfrieden | C6: =IF(Anlagen!S6<>"",Anlagen!S6,IF(Vorschlag_nutzen=1,Anlagen!Q6,A6)) -> 41 | D6: =IF(C6=A6,"",IF(Anlagen!T6<>"",Anlagen!T6,IF(AND(Anlagen!S6="",Vorschlag_nutzen=1,Anlagen!R6<>""),Anlagen!R6,C6))) -> 20 | E6: =IF(C6=A6,IF(COUNTIF($C$5:$C$92,A6)>1,"Gateway-Standort","eigenständig"),"über "&IFERROR(INDEX(Anlagen!$B$5:$B$92,MATCH(D6,Anlagen!$A$5:$A$92,0)),"?")) -> über Buchenweg | F6: =IF(C6=A6,0,IF(Anlagen!V6<>"",Anlagen!V6/1000,IFERROR(SQRT((Anlagen!N6-INDEX(Anlagen!$N$5:$N$92,MATCH(D6,Anlagen!$A$5:$A$92,0)))^2+(Anlagen!O6-INDEX(Anlagen!$O$5:$O$92,MATCH(D6,Anlagen!$A$5:$A$92,0)))^2),0))) -> 0.47539457 | G6: =IF(C6=A6,0,IF(Anlagen!V6<>"",Anlagen!V6,F6*1000*Umweg)) -> 618.01294 | H6: =IF(C6=A6,0,(G6*(P_Faser+P_Tiefbau)+2*P_SFP+P_MontZul)*EK) -> 1333.7751 | I6: =IF(C6=A6,0,(P_Saeule+P_Flex+P_NT+P_Halter+P_Luefter+P_Spleiss+P_Ueber)*EK) -> 851.326 | J6: =IF(Anlagen!U6<>"",Anlagen!U6,IF(C6=A6,500,1000)+ROW()) -> 1006 | K6: =SUMIFS(Anlagen!$F$5:$F$92,$C$5:$C$92,C6,$J$5:$J$92,"<"&J6) -> 139 | L6: =INT(K6/PG)+1 -> 3 | M6: =MAX(L6,CEILING((K6+Anlagen!F6)/PG,1)) -> 4 | N6: =IFERROR(INDEX(Anlagen!$B$5:$B$92,MATCH(C6,Anlagen!$A$5:$A$92,0)),"?")&": GW "&L6&IF(M6>L6,"–"&M6,"") -> Glück im Winkel: GW 3–4 | O6: =Buchungsquote!V6 -> 40.149728 | P6: =IF(ISNA(MATCH(C6,Anlagen!$A$5:$A$92,0)),"Fehler: Standort unbekannt",IF(C6=A6,"OK",IF(INDEX($C$5:$C$92,MATCH(C6,Anlagen!$A$5:$A$92,0))<>C6,"Fehler: Standort hängt selbst an anderem Standort",IF(D6=A6,"Fehler: Zuleitung von sich selbst",IF(ISNA(MATCH(D6,Anlagen!$A$5:$A$92,0)),"Fehler: Zuleitung unbekannt",IF(INDEX($C$5:$C$92,MATCH(D6,Anlagen!$A$5:$A$92,0))<>C6,"Fehler: Zuleitung hängt an anderem Standort","OK")))))) -> OK | Q6: =Anlagen!AA6 -> ABFRI | R6: =IF(Anlagen!AB6<>"",Anlagen!AB6,COUNTIFS($C$5:$C$92,C6,$J$5:$J$92,"<"&J6)+1) -> 2 | S6: =1000+200*(R6-1)+1 -> 1201 | T6: =1000+200*(R6-1)+Anlagen!F6 -> 1275 | U6: =100+A6 -> 102 | V6: =200+A6 -> 202 | W6: =300+A6 -> 302 | X6: ="10."&A6&".1.0/24" -> 10.2.1.0/24 | Y6: =IF(R6>15,"Fehler: VLAN-Block über 15",IF(COUNTIFS($C$5:$C$92,C6,$R$5:$R$92,R6)>1,"Fehler: VLAN-Block am Standort doppelt",IF(COUNTIF($Q$5:$Q$92,Q6)>1,"Fehler: Kürzel doppelt",IF(Anlagen!F6>199,"Fehler: mehr als 199 Parzellen","OK")))) -> OK
A7: =Anlagen!A7 -> 3 | B7: =Anlagen!B7 -> Abendrot | C7: =IF(Anlagen!S7<>"",Anlagen!S7,IF(Vorschlag_nutzen=1,Anlagen!Q7,A7)) -> 30 | D7: =IF(C7=A7,"",IF(Anlagen!T7<>"",Anlagen!T7,IF(AND(Anlagen!S7="",Vorschlag_nutzen=1,Anlagen!R7<>""),Anlagen!R7,C7))) -> 30 | E7: =IF(C7=A7,IF(COUNTIF($C$5:$C$92,A7)>1,"Gateway-Standort","eigenständig"),"über "&IFERROR(INDEX(Anlagen!$B$5:$B$92,MATCH(D7,Anlagen!$A$5:$A$92,0)),"?")) -> über Feierabend | F7: =IF(C7=A7,0,IF(Anlagen!V7<>"",Anlagen!V7/1000,IFERROR(SQRT((Anlagen!N7-INDEX(Anlagen!$N$5:$N$92,MATCH(D7,Anlagen!$A$5:$A$92,0)))^2+(Anlagen!O7-INDEX(Anlagen!$O$5:$O$92,MATCH(D7,Anlagen!$A$5:$A$92,0)))^2),0))) -> 1.1872658 | G7: =IF(C7=A7,0,IF(Anlagen!V7<>"",Anlagen!V7,F7*1000*Umweg)) -> 1543.4455 | H7: =IF(C7=A7,0,(G7*(P_Faser+P_Tiefbau)+2*P_SFP+P_MontZul)*EK) -> 2985.6722 | I7: =IF(C7=A7,0,(P_Saeule+P_Flex+P_NT+P_Halter+P_Luefter+P_Spleiss+P_Ueber)*EK) -> 851.326 | J7: =IF(Anlagen!U7<>"",Anlagen!U7,IF(C7=A7,500,1000)+ROW()) -> 1007 | K7: =SUMIFS(Anlagen!$F$5:$F$92,$C$5:$C$92,C7,$J$5:$J$92,"<"&J7) -> 190 | L7: =INT(K7/PG)+1 -> 4 | M7: =MAX(L7,CEILING((K7+Anlagen!F7)/PG,1)) -> 6 | N7: =IFERROR(INDEX(Anlagen!$B$5:$B$92,MATCH(C7,Anlagen!$A$5:$A$92,0)),"?")&": GW "&L7&IF(M7>L7,"–"&M7,"") -> Feierabend: GW 4–6 | O7: =Buchungsquote!V7 -> 77.934457 | P7: =IF(ISNA(MATCH(C7,Anlagen!$A$5:$A$92,0)),"Fehler: Standort unbekannt",IF(C7=A7,"OK",IF(INDEX($C$5:$C$92,MATCH(C7,Anlagen!$A$5:$A$92,0))<>C7,"Fehler: Standort hängt selbst an anderem Standort",IF(D7=A7,"Fehler: Zuleitung von sich selbst",IF(ISNA(MATCH(D7,Anlagen!$A$5:$A$92,0)),"Fehler: Zuleitung unbekannt",IF(INDEX($C$5:$C$92,MATCH(D7,Anlagen!$A$5:$A$92,0))<>C7,"Fehler: Zuleitung hängt an anderem Standort","OK")))))) -> OK | Q7: =Anlagen!AA7 -> ABROT | R7: =IF(Anlagen!AB7<>"",Anlagen!AB7,COUNTIFS($C$5:$C$92,C7,$J$5:$J$92,"<"&J7)+1) -> 2 | S7: =1000+200*(R7-1)+1 -> 1201 | T7: =1000+200*(R7-1)+Anlagen!F7 -> 1337 | U7: =100+A7 -> 103 | V7: =200+A7 -> 203 | W7: =300+A7 -> 303 | X7: ="10."&A7&".1.0/24" -> 10.3.1.0/24 | Y7: =IF(R7>15,"Fehler: VLAN-Block über 15",IF(COUNTIFS($C$5:$C$92,C7,$R$5:$R$92,R7)>1,"Fehler: VLAN-Block am Standort doppelt",IF(COUNTIF($Q$5:$Q$92,Q7)>1,"Fehler: Kürzel doppelt",IF(Anlagen!F7>199,"Fehler: mehr als 199 Parzellen","OK")))) -> OK
A8: =Anlagen!A8 -> 4 | B8: =Anlagen!B8 -> Abendruh | C8: =IF(Anlagen!S8<>"",Anlagen!S8,IF(Vorschlag_nutzen=1,Anlagen!Q8,A8)) -> 30 | D8: =IF(C8=A8,"",IF(Anlagen!T8<>"",Anlagen!T8,IF(AND(Anlagen!S8="",Vorschlag_nutzen=1,Anlagen!R8<>""),Anlagen!R8,C8))) -> 30 | E8: =IF(C8=A8,IF(COUNTIF($C$5:$C$92,A8)>1,"Gateway-Standort","eigenständig"),"über "&IFERROR(INDEX(Anlagen!$B$5:$B$92,MATCH(D8,Anlagen!$A$5:$A$92,0)),"?")) -> über Feierabend | F8: =IF(C8=A8,0,IF(Anlagen!V8<>"",Anlagen!V8/1000,IFERROR(SQRT((Anlagen!N8-INDEX(Anlagen!$N$5:$N$92,MATCH(D8,Anlagen!$A$5:$A$92,0)))^2+(Anlagen!O8-INDEX(Anlagen!$O$5:$O$92,MATCH(D8,Anlagen!$A$5:$A$92,0)))^2),0))) -> 0.83630138 | G8: =IF(C8=A8,0,IF(Anlagen!V8<>"",Anlagen!V8,F8*1000*Umweg)) -> 1087.1918 | H8: =IF(C8=A8,0,(G8*(P_Faser+P_Tiefbau)+2*P_SFP+P_MontZul)*EK) -> 2171.2594 | I8: =IF(C8=A8,0,(P_Saeule+P_Flex+P_NT+P_Halter+P_Luefter+P_Spleiss+P_Ueber)*EK) -> 851.326 | J8: =IF(Anlagen!U8<>"",Anlagen!U8,IF(C8=A8,500,1000)+ROW()) -> 1008 | K8: =SUMIFS(Anlagen!$F$5:$F$92,$C$5:$C$92,C8,$J$5:$J$92,"<"&J8) -> 327 | L8: =INT(K8/PG)+1 -> 6 | M8: =MAX(L8,CEILING((K8+Anlagen!F8)/PG,1)) -> 9 | N8: =IFERROR(INDEX(Anlagen!$B$5:$B$92,MATCH(C8,Anlagen!$A$5:$A$92,0)),"?")&": GW "&L8&IF(M8>L8,"–"&M8,"") -> Feierabend: GW 6–9 | O8: =Buchungsquote!V8 -> 79.553733 | P8: =IF(ISNA(MATCH(C8,Anlagen!$A$5:$A$92,0)),"Fehler: Standort unbekannt",IF(C8=A8,"OK",IF(INDEX($C$5:$C$92,MATCH(C8,Anlagen!$A$5:$A$92,0))<>C8,"Fehler: Standort hängt selbst an anderem Standort",IF(D8=A8,"Fehler: Zuleitung von sich selbst",IF(ISNA(MATCH(D8,Anlagen!$A$5:$A$92,0)),"Fehler: Zuleitung unbekannt",IF(INDEX($C$5:$C$92,MATCH(D8,Anlagen!$A$5:$A$92,0))<>C8,"Fehler: Zuleitung hängt an anderem Standort","OK")))))) -> OK | Q8: =Anlagen!AA8 -> ABRUH | R8: =IF(Anlagen!AB8<>"",Anlagen!AB8,COUNTIFS($C$5:$C$92,C8,$J$5:$J$92,"<"&J8)+1) -> 3 | S8: =1000+200*(R8-1)+1 -> 1401 | T8: =1000+200*(R8-1)+Anlagen!F8 -> 1542 | U8: =100+A8 -> 104 | V8: =200+A8 -> 204 | W8: =300+A8 -> 304 | X8: ="10."&A8&".1.0/24" -> 10.4.1.0/24 | Y8: =IF(R8>15,"Fehler: VLAN-Block über 15",IF(COUNTIFS($C$5:$C$92,C8,$R$5:$R$92,R8)>1,"Fehler: VLAN-Block am Standort doppelt",IF(COUNTIF($Q$5:$Q$92,Q8)>1,"Fehler: Kürzel doppelt",IF(Anlagen!F8>199,"Fehler: mehr als 199 Parzellen","OK")))) -> OK
A9: =Anlagen!A9 -> 5 | B9: =Anlagen!B9 -> Abendsonne | C9: =IF(Anlagen!S9<>"",Anlagen!S9,IF(Vorschlag_nutzen=1,Anlagen!Q9,A9)) -> 23 | D9: =IF(C9=A9,"",IF(Anlagen!T9<>"",Anlagen!T9,IF(AND(Anlagen!S9="",Vorschlag_nutzen=1,Anlagen!R9<>""),Anlagen!R9,C9))) -> 24 | E9: =IF(C9=A9,IF(COUNTIF($C$5:$C$92,A9)>1,"Gateway-Standort","eigenständig"),"über "&IFERROR(INDEX(Anlagen!$B$5:$B$92,MATCH(D9,Anlagen!$A$5:$A$92,0)),"?")) -> über Einheit | F9: =IF(C9=A9,0,IF(Anlagen!V9<>"",Anlagen!V9/1000,IFERROR(SQRT((Anlagen!N9-INDEX(Anlagen!$N$5:$N$92,MATCH(D9,Anlagen!$A$5:$A$92,0)))^2+(Anlagen!O9-INDEX(Anlagen!$O$5:$O$92,MATCH(D9,Anlagen!$A$5:$A$92,0)))^2),0))) -> 0.41725292 | G9: =IF(C9=A9,0,IF(Anlagen!V9<>"",Anlagen!V9,F9*1000*Umweg)) -> 542.4288 | H9: =IF(C9=A9,0,(G9*(P_Faser+P_Tiefbau)+2*P_SFP+P_MontZul)*EK) -> 1198.8574 | I9: =IF(C9=A9,0,(P_Saeule+P_Flex+P_NT+P_Halter+P_Luefter+P_Spleiss+P_Ueber)*EK) -> 851.326 | J9: =IF(Anlagen!U9<>"",Anlagen!U9,IF(C9=A9,500,1000)+ROW()) -> 1009 | K9: =SUMIFS(Anlagen!$F$5:$F$92,$C$5:$C$92,C9,$J$5:$J$92,"<"&J9) -> 123 | L9: =INT(K9/PG)+1 -> 3 | M9: =MAX(L9,CEILING((K9+Anlagen!F9)/PG,1)) -> 4 | N9: =IFERROR(INDEX(Anlagen!$B$5:$B$92,MATCH(C9,Anlagen!$A$5:$A$92,0)),"?")&": GW "&L9&IF(M9>L9,"–"&M9,"") -> Eigener Fleiß: GW 3–4 | O9: =Buchungsquote!V9 -> 33.75 | P9: =IF(ISNA(MATCH(C9,Anlagen!$A$5:$A$92,0)),"Fehler: Standort unbekannt",IF(C9=A9,"OK",IF(INDEX($C$5:$C$92,MATCH(C9,Anlagen!$A$5:$A$92,0))<>C9,"Fehler: Standort hängt selbst an anderem Standort",IF(D9=A9,"Fehler: Zuleitung von sich selbst",IF(ISNA(MATCH(D9,Anlagen!$A$5:$A$92,0)),"Fehler: Zuleitung unbekannt",IF(INDEX($C$5:$C$92,MATCH(D9,Anlagen!$A$5:$A$92,0))<>C9,"Fehler: Zuleitung hängt an anderem Standort","OK")))))) -> OK | Q9: =Anlagen!AA9 -> ABSON | R9: =IF(Anlagen!AB9<>"",Anlagen!AB9,COUNTIFS($C$5:$C$92,C9,$J$5:$J$92,"<"&J9)+1) -> 2 | S9: =1000+200*(R9-1)+1 -> 1201 | T9: =1000+200*(R9-1)+Anlagen!F9 -> 1267 | U9: =100+A9 -> 105 | V9: =200+A9 -> 205 | W9: =300+A9 -> 305 | X9: ="10."&A9&".1.0/24" -> 10.5.1.0/24 | Y9: =IF(R9>15,"Fehler: VLAN-Block über 15",IF(COUNTIFS($C$5:$C$92,C9,$R$5:$R$92,R9)>1,"Fehler: VLAN-Block am Standort doppelt",IF(COUNTIF($Q$5:$Q$92,Q9)>1,"Fehler: Kürzel doppelt",IF(Anlagen!F9>199,"Fehler: mehr als 199 Parzellen","OK")))) -> OK
A10: =Anlagen!A10 -> 6 | B10: =Anlagen!B10 -> Altstadt Forst | C10: =IF(Anlagen!S10<>"",Anlagen!S10,IF(Vorschlag_nutzen=1,Anlagen!Q10,A10)) -> 33 | D10: =IF(C10=A10,"",IF(Anlagen!T10<>"",Anlagen!T10,IF(AND(Anlagen!S10="",Vorschlag_nutzen=1,Anlagen!R10<>""),Anlagen!R10,C10))) -> 33 | E10: =IF(C10=A10,IF(COUNTIF($C$5:$C$92,A10)>1,"Gateway-Standort","eigenständig"),"über "&IFERROR(INDEX(Anlagen!$B$5:$B$92,MATCH(D10,Anlagen!$A$5:$A$92,0)),"?")) -> über Fohrder Landstraße | F10: =IF(C10=A10,0,IF(Anlagen!V10<>"",Anlagen!V10/1000,IFERROR(SQRT((Anlagen!N10-INDEX(Anlagen!$N$5:$N$92,MATCH(D10,Anlagen!$A$5:$A$92,0)))^2+(Anlagen!O10-INDEX(Anlagen!$O$5:$O$92,MATCH(D10,Anlagen!$A$5:$A$92,0)))^2),0))) -> 0.45310043 | G10: =IF(C10=A10,0,IF(Anlagen!V10<>"",Anlagen!V10,F10*1000*Umweg)) -> 589.03056 | H10: =IF(C10=A10,0,(G10*(P_Faser+P_Tiefbau)+2*P_SFP+P_MontZul)*EK) -> 1282.0415 | I10: =IF(C10=A10,0,(P_Saeule+P_Flex+P_NT+P_Halter+P_Luefter+P_Spleiss+P_Ueber)*EK) -> 851.326 | J10: =IF(Anlagen!U10<>"",Anlagen!U10,IF(C10=A10,500,1000)+ROW()) -> 1010 | K10: =SUMIFS(Anlagen!$F$5:$F$92,$C$5:$C$92,C10,$J$5:$J$92,"<"&J10) -> 157 | L10: =INT(K10/PG)+1 -> 3 | M10: =MAX(L10,CEILING((K10+Anlagen!F10)/PG,1)) -> 5 | N10: =IFERROR(INDEX(Anlagen!$B$5:$B$92,MATCH(C10,Anlagen!$A$5:$A$92,0)),"?")&": GW "&L10&IF(M10>L10,"–"&M10,"") -> Fohrder Landstraße: GW 3–5 | O10: =Buchungsquote!V10 -> 49.300905 | P10: =IF(ISNA(MATCH(C10,Anlagen!$A$5:$A$92,0)),"Fehler: Standort unbekannt",IF(C10=A10,"OK",IF(INDEX($C$5:$C$92,MATCH(C10,Anlagen!$A$5:$A$92,0))<>C10,"Fehler: Standort hängt selbst an anderem Standort",IF(D10=A10,"Fehler: Zuleitung von sich selbst",IF(ISNA(MATCH(D10,Anlagen!$A$5:$A$92,0)),"Fehler: Zuleitung unbekannt",IF(INDEX($C$5:$C$92,MATCH(D10,Anlagen!$A$5:$A$92,0))<>C10,"Fehler: Zuleitung hängt an anderem Standort","OK")))))) -> OK | Q10: =Anlagen!AA10 -> ALTFO | R10: =IF(Anlagen!AB10<>"",Anlagen!AB10,COUNTIFS($C$5:$C$92,C10,$J$5:$J$92,"<"&J10)+1) -> 3 | S10: =1000+200*(R10-1)+1 -> 1401 | T10: =1000+200*(R10-1)+Anlagen!F10 -> 1488 | U10: =100+A10 -> 106 | V10: =200+A10 -> 206 | W10: =300+A10 -> 306 | X10: ="10."&A10&".1.0/24" -> 10.6.1.0/24 | Y10: =IF(R10>15,"Fehler: VLAN-Block über 15",IF(COUNTIFS($C$5:$C$92,C10,$R$5:$R$92,R10)>1,"Fehler: VLAN-Block am Standort doppelt",IF(COUNTIF($Q$5:$Q$92,Q10)>1,"Fehler: Kürzel doppelt",IF(Anlagen!F10>199,"Fehler: mehr als 199 Parzellen","OK")))) -> OK
A11: =Anlagen!A11 -> 7 | B11: =Anlagen!B11 -> Am Beetzseeufer | C11: =IF(Anlagen!S11<>"",Anlagen!S11,IF(Vorschlag_nutzen=1,Anlagen!Q11,A11)) -> 49 | D11: =IF(C11=A11,"",IF(Anlagen!T11<>"",Anlagen!T11,IF(AND(Anlagen!S11="",Vorschlag_nutzen=1,Anlagen!R11<>""),Anlagen!R11,C11))) -> 88 | E11: =IF(C11=A11,IF(COUNTIF($C$5:$C$92,A11)>1,"Gateway-Standort","eigenständig"),"über "&IFERROR(INDEX(Anlagen!$B$5:$B$92,MATCH(D11,Anlagen!$A$5:$A$92,0)),"?")) -> über Zur Insel | F11: =IF(C11=A11,0,IF(Anlagen!V11<>"",Anlagen!V11/1000,IFERROR(SQRT((Anlagen!N11-INDEX(Anlagen!$N$5:$N$92,MATCH(D11,Anlagen!$A$5:$A$92,0)))^2+(Anlagen!O11-INDEX(Anlagen!$O$5:$O$92,MATCH(D11,Anlagen!$A$5:$A$92,0)))^2),0))) -> 0.93300589 | G11: =IF(C11=A11,0,IF(Anlagen!V11<>"",Anlagen!V11,F11*1000*Umweg)) -> 1212.9077 | H11: =IF(C11=A11,0,(G11*(P_Faser+P_Tiefbau)+2*P_SFP+P_MontZul)*EK) -> 2395.6622 | I11: =IF(C11=A11,0,(P_Saeule+P_Flex+P_NT+P_Halter+P_Luefter+P_Spleiss+P_Ueber)*EK) -> 851.326 | J11: =IF(Anlagen!U11<>"",Anlagen!U11,IF(C11=A11,500,1000)+ROW()) -> 1011 | K11: =SUMIFS(Anlagen!$F$5:$F$92,$C$5:$C$92,C11,$J$5:$J$92,"<"&J11) -> 110 | L11: =INT(K11/PG)+1 -> 3 | M11: =MAX(L11,CEILING((K11+Anlagen!F11)/PG,1)) -> 4 | N11: =IFERROR(INDEX(Anlagen!$B$5:$B$92,MATCH(C11,Anlagen!$A$5:$A$92,0)),"?")&": GW "&L11&IF(M11>L11,"–"&M11,"") -> Helgoland: GW 3–4 | O11: =Buchungsquote!V11 -> 48.733591 | P11: =IF(ISNA(MATCH(C11,Anlagen!$A$5:$A$92,0)),"Fehler: Standort unbekannt",IF(C11=A11,"OK",IF(INDEX($C$5:$C$92,MATCH(C11,Anlagen!$A$5:$A$92,0))<>C11,"Fehler: Standort hängt selbst an anderem Standort",IF(D11=A11,"Fehler: Zuleitung von sich selbst",IF(ISNA(MATCH(D11,Anlagen!$A$5:$A$92,0)),"Fehler: Zuleitung unbekannt",IF(INDEX($C$5:$C$92,MATCH(D11,Anlagen!$A$5:$A$92,0))<>C11,"Fehler: Zuleitung hängt an anderem Standort","OK")))))) -> OK | Q11: =Anlagen!AA11 -> BEETZ | R11: =IF(Anlagen!AB11<>"",Anlagen!AB11,COUNTIFS($C$5:$C$92,C11,$J$5:$J$92,"<"&J11)+1) -> 2 | S11: =1000+200*(R11-1)+1 -> 1201 | T11: =1000+200*(R11-1)+Anlagen!F11 -> 1277 | U11: =100+A11 -> 107 | V11: =200+A11 -> 207 | W11: =300+A11 -> 307 | X11: ="10."&A11&".1.0/24" -> 10.7.1.0/24 | Y11: =IF(R11>15,"Fehler: VLAN-Block über 15",IF(COUNTIFS($C$5:$C$92,C11,$R$5:$R$92,R11)>1,"Fehler: VLAN-Block am Standort doppelt",IF(COUNTIF($Q$5:$Q$92,Q11)>1,"Fehler: Kürzel doppelt",IF(Anlagen!F11>199,"Fehler: mehr als 199 Parzellen","OK")))) -> OK
A12: =Anlagen!A12 -> 8 | B12: =Anlagen!B12 -> Am Büttelhandfassgraben | C12: =IF(Anlagen!S12<>"",Anlagen!S12,IF(Vorschlag_nutzen=1,Anlagen!Q12,A12)) -> 49 | D12: =IF(C12=A12,"",IF(Anlagen!T12<>"",Anlagen!T12,IF(AND(Anlagen!S12="",Vorschlag_nutzen=1,Anlagen!R12<>""),Anlagen!R12,C12))) -> 50 | E12: =IF(C12=A12,IF(COUNTIF($C$5:$C$92,A12)>1,"Gateway-Standort","eigenständig"),"über "&IFERROR(INDEX(Anlagen!$B$5:$B$92,MATCH(D12,Anlagen!$A$5:$A$92,0)),"?")) -> über Hoffnung | F12: =IF(C12=A12,0,IF(Anlagen!V12<>"",Anlagen!V12/1000,IFERROR(SQRT((Anlagen!N12-INDEX(Anlagen!$N$5:$N$92,MATCH(D12,Anlagen!$A$5:$A$92,0)))^2+(Anlagen!O12-INDEX(Anlagen!$O$5:$O$92,MATCH(D12,Anlagen!$A$5:$A$92,0)))^2),0))) -> 0.067082039 | G12: =IF(C12=A12,0,IF(Anlagen!V12<>"",Anlagen!V12,F12*1000*Umweg)) -> 87.206651 | H12: =IF(C12=A12,0,(G12*(P_Faser+P_Tiefbau)+2*P_SFP+P_MontZul)*EK) -> 386.28587 | I12: =IF(C12=A12,0,(P_Saeule+P_Flex+P_NT+P_Halter+P_Luefter+P_Spleiss+P_Ueber)*EK) -> 851.326 | J12: =IF(Anlagen!U12<>"",Anlagen!U12,IF(C12=A12,500,1000)+ROW()) -> 1012 | K12: =SUMIFS(Anlagen!$F$5:$F$92,$C$5:$C$92,C12,$J$5:$J$92,"<"&J12) -> 187 | L12: =INT(K12/PG)+1 -> 4 | M12: =MAX(L12,CEILING((K12+Anlagen!F12)/PG,1)) -> 4 | N12: =IFERROR(INDEX(Anlagen!$B$5:$B$92,MATCH(C12,Anlagen!$A$5:$A$92,0)),"?")&": GW "&L12&IF(M12>L12,"–"&M12,"") -> Helgoland: GW 4 | O12: =Buchungsquote!V12 -> 3.3928571 | P12: =IF(ISNA(MATCH(C12,Anlagen!$A$5:$A$92,0)),"Fehler: Standort unbekannt",IF(C12=A12,"OK",IF(INDEX($C$5:$C$92,MATCH(C12,Anlagen!$A$5:$A$92,0))<>C12,"Fehler: Standort hängt selbst an anderem Standort",IF(D12=A12,"Fehler: Zuleitung von sich selbst",IF(ISNA(MATCH(D12,Anlagen!$A$5:$A$92,0)),"Fehler: Zuleitung unbekannt",IF(INDEX($C$5:$C$92,MATCH(D12,Anlagen!$A$5:$A$92,0))<>C12,"Fehler: Zuleitung hängt an anderem Standort","OK")))))) -> OK | Q12: =Anlagen!AA12 -> BUETT | R12: =IF(Anlagen!AB12<>"",Anlagen!AB12,COUNTIFS($C$5:$C$92,C12,$J$5:$J$92,"<"&J12)+1) -> 3 | S12: =1000+200*(R12-1)+1 -> 1401 | T12: =1000+200*(R12-1)+Anlagen!F12 -> 1405 | U12: =100+A12 -> 108 | V12: =200+A12 -> 208 | W12: =300+A12 -> 308 | X12: ="10."&A12&".1.0/24" -> 10.8.1.0/24 | Y12: =IF(R12>15,"Fehler: VLAN-Block über 15",IF(COUNTIFS($C$5:$C$92,C12,$R$5:$R$92,R12)>1,"Fehler: VLAN-Block am Standort doppelt",IF(COUNTIF($Q$5:$Q$92,Q12)>1,"Fehler: Kürzel doppelt",IF(Anlagen!F12>199,"Fehler: mehr als 199 Parzellen","OK")))) -> OK
A13: =Anlagen!A13 -> 9 | B13: =Anlagen!B13 -> Am Eichenweg | C13: =IF(Anlagen!S13<>"",Anlagen!S13,IF(Vorschlag_nutzen=1,Anlagen!Q13,A13)) -> 17 | D13: =IF(C13=A13,"",IF(Anlagen!T13<>"",Anlagen!T13,IF(AND(Anlagen!S13="",Vorschlag_nutzen=1,Anlagen!R13<>""),Anlagen!R13,C13))) -> 17 | E13: =IF(C13=A13,IF(COUNTIF($C$5:$C$92,A13)>1,"Gateway-Standort","eigenständig"),"über "&IFERROR(INDEX(Anlagen!$B$5:$B$92,MATCH(D13,Anlagen!$A$5:$A$92,0)),"?")) -> über Birkenwäldchen | F13: =IF(C13=A13,0,IF(Anlagen!V13<>"",Anlagen!V13/1000,IFERROR(SQRT((Anlagen!N13-INDEX(Anlagen!$N$5:$N$92,MATCH(D13,Anlagen!$A$5:$A$92,0)))^2+(Anlagen!O13-INDEX(Anlagen!$O$5:$O$92,MATCH(D13,Anlagen!$A$5:$A$92,0)))^2),0))) -> 1.3792752 | G13: =IF(C13=A13,0,IF(Anlagen!V13<>"",Anlagen!V13,F13*1000*Umweg)) -> 1793.0577 | H13: =IF(C13=A13,0,(G13*(P_Faser+P_Tiefbau)+2*P_SFP+P_MontZul)*EK) -> 3431.23 | I13: =IF(C13=A13,0,(P_Saeule+P_Flex+P_NT+P_Halter+P_Luefter+P_Spleiss+P_Ueber)*EK) -> 851.326 | J13: =IF(Anlagen!U13<>"",Anlagen!U13,IF(C13=A13,500,1000)+ROW()) -> 1013 | K13: =SUMIFS(Anlagen!$F$5:$F$92,$C$5:$C$92,C13,$J$5:$J$92,"<"&J13) -> 56 | L13: =INT(K13/PG)+1 -> 2 | M13: =MAX(L13,CEILING((K13+Anlagen!F13)/PG,1)) -> 2 | N13: =IFERROR(INDEX(Anlagen!$B$5:$B$92,MATCH(C13,Anlagen!$A$5:$A$92,0)),"?")&": GW "&L13&IF(M13>L13,"–"&M13,"") -> Birkenwäldchen: GW 2 | O13: =Buchungsquote!V13 -> 30.1716 | P13: =IF(ISNA(MATCH(C13,Anlagen!$A$5:$A$92,0)),"Fehler: Standort unbekannt",IF(C13=A13,"OK",IF(INDEX($C$5:$C$92,MATCH(C13,Anlagen!$A$5:$A$92,0))<>C13,"Fehler: Standort hängt selbst an anderem Standort",IF(D13=A13,"Fehler: Zuleitung von sich selbst",IF(ISNA(MATCH(D13,Anlagen!$A$5:$A$92,0)),"Fehler: Zuleitung unbekannt",IF(INDEX($C$5:$C$92,MATCH(D13,Anlagen!$A$5:$A$92,0))<>C13,"Fehler: Zuleitung hängt an anderem Standort","OK")))))) -> OK | Q13: =Anlagen!AA13 -> EICHW | R13: =IF(Anlagen!AB13<>"",Anlagen!AB13,COUNTIFS($C$5:$C$92,C13,$J$5:$J$92,"<"&J13)+1) -> 2 | S13: =1000+200*(R13-1)+1 -> 1201 | T13: =1000+200*(R13-1)+Anlagen!F13 -> 1254 | U13: =100+A13 -> 109 | V13: =200+A13 -> 209 | W13: =300+A13 -> 309 | X13: ="10."&A13&".1.0/24" -> 10.9.1.0/24 | Y13: =IF(R13>15,"Fehler: VLAN-Block über 15",IF(COUNTIFS($C$5:$C$92,C13,$R$5:$R$92,R13)>1,"Fehler: VLAN-Block am Standort doppelt",IF(COUNTIF($Q$5:$Q$92,Q13)>1,"Fehler: Kürzel doppelt",IF(Anlagen!F13>199,"Fehler: mehr als 199 Parzellen","OK")))) -> OK
A14: =Anlagen!A14 -> 10 | B14: =Anlagen!B14 -> Am Jakobsgraben | C14: =IF(Anlagen!S14<>"",Anlagen!S14,IF(Vorschlag_nutzen=1,Anlagen!Q14,A14)) -> 17 | D14: =IF(C14=A14,"",IF(Anlagen!T14<>"",Anlagen!T14,IF(AND(Anlagen!S14="",Vorschlag_nutzen=1,Anlagen!R14<>""),Anlagen!R14,C14))) -> 27 | E14: =IF(C14=A14,IF(COUNTIF($C$5:$C$92,A14)>1,"Gateway-Standort","eigenständig"),"über "&IFERROR(INDEX(Anlagen!$B$5:$B$92,MATCH(D14,Anlagen!$A$5:$A$92,0)),"?")) -> über Eintracht II | F14: =IF(C14=A14,0,IF(Anlagen!V14<>"",Anlagen!V14/1000,IFERROR(SQRT((Anlagen!N14-INDEX(Anlagen!$N$5:$N$92,MATCH(D14,Anlagen!$A$5:$A$92,0)))^2+(Anlagen!O14-INDEX(Anlagen!$O$5:$O$92,MATCH(D14,Anlagen!$A$5:$A$92,0)))^2),0))) -> 1.121606 | G14: =IF(C14=A14,0,IF(Anlagen!V14<>"",Anlagen!V14,F14*1000*Umweg)) -> 1458.0878 | H14: =IF(C14=A14,0,(G14*(P_Faser+P_Tiefbau)+2*P_SFP+P_MontZul)*EK) -> 2833.3087 | I14: =IF(C14=A14,0,(P_Saeule+P_Flex+P_NT+P_Halter+P_Luefter+P_Spleiss+P_Ueber)*EK) -> 851.326 | J14: =IF(Anlagen!U14<>"",Anlagen!U14,IF(C14=A14,500,1000)+ROW()) -> 1014 | K14: =SUMIFS(Anlagen!$F$5:$F$92,$C$5:$C$92,C14,$J$5:$J$92,"<"&J14) -> 110 | L14: =INT(K14/PG)+1 -> 3 | M14: =MAX(L14,CEILING((K14+Anlagen!F14)/PG,1)) -> 3 | N14: =IFERROR(INDEX(Anlagen!$B$5:$B$92,MATCH(C14,Anlagen!$A$5:$A$92,0)),"?")&": GW "&L14&IF(M14>L14,"–"&M14,"") -> Birkenwäldchen: GW 3 | O14: =Buchungsquote!V14 -> 18.637201 | P14: =IF(ISNA(MATCH(C14,Anlagen!$A$5:$A$92,0)),"Fehler: Standort unbekannt",IF(C14=A14,"OK",IF(INDEX($C$5:$C$92,MATCH(C14,Anlagen!$A$5:$A$92,0))<>C14,"Fehler: Standort hängt selbst an anderem Standort",IF(D14=A14,"Fehler: Zuleitung von sich selbst",IF(ISNA(MATCH(D14,Anlagen!$A$5:$A$92,0)),"Fehler: Zuleitung unbekannt",IF(INDEX($C$5:$C$92,MATCH(D14,Anlagen!$A$5:$A$92,0))<>C14,"Fehler: Zuleitung hängt an anderem Standort","OK")))))) -> OK | Q14: =Anlagen!AA14 -> JAKGR | R14: =IF(Anlagen!AB14<>"",Anlagen!AB14,COUNTIFS($C$5:$C$92,C14,$J$5:$J$92,"<"&J14)+1) -> 3 | S14: =1000+200*(R14-1)+1 -> 1401 | T14: =1000+200*(R14-1)+Anlagen!F14 -> 1441 | U14: =100+A14 -> 110 | V14: =200+A14 -> 210 | W14: =300+A14 -> 310 | X14: ="10."&A14&".1.0/24" -> 10.10.1.0/24 | Y14: =IF(R14>15,"Fehler: VLAN-Block über 15",IF(COUNTIFS($C$5:$C$92,C14,$R$5:$R$92,R14)>1,"Fehler: VLAN-Block am Standort doppelt",IF(COUNTIF($Q$5:$Q$92,Q14)>1,"Fehler: Kürzel doppelt",IF(Anlagen!F14>199,"Fehler: mehr als 199 Parzellen","OK")))) -> OK
