Workbook

Sheet Eingabe
A1: SparteNet – VLAN-Planer: bis zu 10 Sparten an einem Gateway
A2: Gelbe Felder ausfüllen. Für den nächsten Gateway die Datei kopieren und die Werte ändern. Alles andere rechnet automatisch.
A4: Gateway-Nummer (1–254) | B4: 1 | C4: nur für das Technik-Netz des Gateways selbst: 10.0.<Gateway>.0/24
A5: Gateway-Bezeichnung | B5: KGS Buchenweg e.V.
A6: WLAN-Präfix | B6: SparteNet.de | C6: WLANs: Präfix-Kürzel-Pächter, -Gäste, -Vorstand
A8: Steckplatz | B8: Sparte (Name) | C8: Kürzel (ohne Umlaute) | D8: Sparten-ID (1–254, firmenweit einmalig) | E8: Parzellen (1–199) | F8: Slots belegt | G8: Start-Slot | H8: VLAN Parzellen | I8: VLAN Vorstand / Gäste / Technik | J8: IP-Bereich | K8: Pächter-WLAN | L8: Gast-WLAN | M8: Netze | N8: Prüfung | O8: Beispiel Parzelle 1 | P8: Hilfe: Start | Q8: Hilfe: Zeilen
A9: 1 | B9: KGS Buchenweg e.V. | C9: BW | D9: 1 | E9: 85 | F9: =IF(OR(B9="",E9=""),0,IF(E9>99,2,1)) -> 1 | G9: =IF(F9=0,"",1) -> 1 | H9: =IF(F9=0,"",IF(E9<=99,(IF((G9)<=9,1000+(G9)*100,3000)+1)&" – "&(IF((G9)<=9,1000+(G9)*100,3000)+E9),(IF((G9)<=9,1000+(G9)*100,3000)+1)&" – "&(IF((G9)<=9,1000+(G9)*100,3000)+99)&" und "&(IF((G9+1)<=9,1000+(G9+1)*100,3000))&" – "&(IF((G9+1)<=9,1000+(G9+1)*100,3000)+E9-100))) -> 1101 – 1185 | I9: =IF(F9=0,"",(2000+G9*10+1)&" / "&(2000+G9*10+2)&" / "&(2000+G9*10+9)) -> 2011 / 2012 / 2019 | J9: =IF(F9=0,"","10."&D9&".0.0/16") -> 10.1.0.0/16 | K9: =IF(F9=0,"",$B$6&"-"&C9&"-Pächter") -> SparteNet.de-BW-Pächter | L9: =IF(F9=0,"",$B$6&"-"&C9&"-Gäste") -> SparteNet.de-BW-Gäste | M9: =IF(F9=0,"",E9+3) -> 88 | N9: =IF(F9=0,"",IF(E9>199,"Fehler: max. 199 Parzellen",IF(COUNTIF($D$9:$D$18,D9)>1,"Fehler: Sparten-ID doppelt",IF(OR(D9<1,D9>254),"Fehler: ID 1–254",IF(G9+F9-1>10,"Fehler: mehr als 10 Slots","OK"))))) -> OK | O9: =IF(F9=0,"","Parzelle 1 → VLAN "&(IF((G9)<=9,1000+(G9)*100,3000)+1)&" → Handy 10."&D9&".1.10") -> Parzelle 1 → VLAN 1101 → Handy 10.1.1.10 | P9: =1 -> 1 | Q9: =IF(F9=0,0,E9+5) -> 90
A10: 2 | B10: Mittelweg | C10: MW | D10: 2 | E10: 53 | F10: =IF(OR(B10="",E10=""),0,IF(E10>99,2,1)) -> 1 | G10: =IF(F10=0,"",1+SUM($F$9:F9)) -> 2 | H10: =IF(F10=0,"",IF(E10<=99,(IF((G10)<=9,1000+(G10)*100,3000)+1)&" – "&(IF((G10)<=9,1000+(G10)*100,3000)+E10),(IF((G10)<=9,1000+(G10)*100,3000)+1)&" – "&(IF((G10)<=9,1000+(G10)*100,3000)+99)&" und "&(IF((G10+1)<=9,1000+(G10+1)*100,3000))&" – "&(IF((G10+1)<=9,1000+(G10+1)*100,3000)+E10-100))) -> 1201 – 1253 | I10: =IF(F10=0,"",(2000+G10*10+1)&" / "&(2000+G10*10+2)&" / "&(2000+G10*10+9)) -> 2021 / 2022 / 2029 | J10: =IF(F10=0,"","10."&D10&".0.0/16") -> 10.2.0.0/16 | K10: =IF(F10=0,"",$B$6&"-"&C10&"-Pächter") -> SparteNet.de-MW-Pächter | L10: =IF(F10=0,"",$B$6&"-"&C10&"-Gäste") -> SparteNet.de-MW-Gäste | M10: =IF(F10=0,"",E10+3) -> 56 | N10: =IF(F10=0,"",IF(E10>199,"Fehler: max. 199 Parzellen",IF(COUNTIF($D$9:$D$18,D10)>1,"Fehler: Sparten-ID doppelt",IF(OR(D10<1,D10>254),"Fehler: ID 1–254",IF(G10+F10-1>10,"Fehler: mehr als 10 Slots","OK"))))) -> OK | O10: =IF(F10=0,"","Parzelle 1 → VLAN "&(IF((G10)<=9,1000+(G10)*100,3000)+1)&" → Handy 10."&D10&".1.10") -> Parzelle 1 → VLAN 1201 → Handy 10.2.1.10 | P10: =P9+Q9 -> 91 | Q10: =IF(F10=0,0,E10+5) -> 58
A11: 3 | B11: Sonnenwinkel | C11: SW | D11: 3 | E11: 53 | F11: =IF(OR(B11="",E11=""),0,IF(E11>99,2,1)) -> 1 | G11: =IF(F11=0,"",1+SUM($F$9:F10)) -> 3 | H11: =IF(F11=0,"",IF(E11<=99,(IF((G11)<=9,1000+(G11)*100,3000)+1)&" – "&(IF((G11)<=9,1000+(G11)*100,3000)+E11),(IF((G11)<=9,1000+(G11)*100,3000)+1)&" – "&(IF((G11)<=9,1000+(G11)*100,3000)+99)&" und "&(IF((G11+1)<=9,1000+(G11+1)*100,3000))&" – "&(IF((G11+1)<=9,1000+(G11+1)*100,3000)+E11-100))) -> 1301 – 1353 | I11: =IF(F11=0,"",(2000+G11*10+1)&" / "&(2000+G11*10+2)&" / "&(2000+G11*10+9)) -> 2031 / 2032 / 2039 | J11: =IF(F11=0,"","10."&D11&".0.0/16") -> 10.3.0.0/16 | K11: =IF(F11=0,"",$B$6&"-"&C11&"-Pächter") -> SparteNet.de-SW-Pächter | L11: =IF(F11=0,"",$B$6&"-"&C11&"-Gäste") -> SparteNet.de-SW-Gäste | M11: =IF(F11=0,"",E11+3) -> 56 | N11: =IF(F11=0,"",IF(E11>199,"Fehler: max. 199 Parzellen",IF(COUNTIF($D$9:$D$18,D11)>1,"Fehler: Sparten-ID doppelt",IF(OR(D11<1,D11>254),"Fehler: ID 1–254",IF(G11+F11-1>10,"Fehler: mehr als 10 Slots","OK"))))) -> OK | O11: =IF(F11=0,"","Parzelle 1 → VLAN "&(IF((G11)<=9,1000+(G11)*100,3000)+1)&" → Handy 10."&D11&".1.10") -> Parzelle 1 → VLAN 1301 → Handy 10.3.1.10 | P11: =P10+Q10 -> 149 | Q11: =IF(F11=0,0,E11+5) -> 58
A12: 4 | B12: Sorgenfrei II | C12: SF2 | D12: 4 | E12: 53 | F12: =IF(OR(B12="",E12=""),0,IF(E12>99,2,1)) -> 1 | G12: =IF(F12=0,"",1+SUM($F$9:F11)) -> 4 | H12: =IF(F12=0,"",IF(E12<=99,(IF((G12)<=9,1000+(G12)*100,3000)+1)&" – "&(IF((G12)<=9,1000+(G12)*100,3000)+E12),(IF((G12)<=9,1000+(G12)*100,3000)+1)&" – "&(IF((G12)<=9,1000+(G12)*100,3000)+99)&" und "&(IF((G12+1)<=9,1000+(G12+1)*100,3000))&" – "&(IF((G12+1)<=9,1000+(G12+1)*100,3000)+E12-100))) -> 1401 – 1453 | I12: =IF(F12=0,"",(2000+G12*10+1)&" / "&(2000+G12*10+2)&" / "&(2000+G12*10+9)) -> 2041 / 2042 / 2049 | J12: =IF(F12=0,"","10."&D12&".0.0/16") -> 10.4.0.0/16 | K12: =IF(F12=0,"",$B$6&"-"&C12&"-Pächter") -> SparteNet.de-SF2-Pächter | L12: =IF(F12=0,"",$B$6&"-"&C12&"-Gäste") -> SparteNet.de-SF2-Gäste | M12: =IF(F12=0,"",E12+3) -> 56 | N12: =IF(F12=0,"",IF(E12>199,"Fehler: max. 199 Parzellen",IF(COUNTIF($D$9:$D$18,D12)>1,"Fehler: Sparten-ID doppelt",IF(OR(D12<1,D12>254),"Fehler: ID 1–254",IF(G12+F12-1>10,"Fehler: mehr als 10 Slots","OK"))))) -> OK | O12: =IF(F12=0,"","Parzelle 1 → VLAN "&(IF((G12)<=9,1000+(G12)*100,3000)+1)&" → Handy 10."&D12&".1.10") -> Parzelle 1 → VLAN 1401 → Handy 10.4.1.10 | P12: =P11+Q11 -> 207 | Q12: =IF(F12=0,0,E12+5) -> 58
A13: 5 | F13: =IF(OR(B13="",E13=""),0,IF(E13>99,2,1)) -> 0 | G13: =IF(F13=0,"",1+SUM($F$9:F12)) | H13: =IF(F13=0,"",IF(E13<=99,(IF((G13)<=9,1000+(G13)*100,3000)+1)&" – "&(IF((G13)<=9,1000+(G13)*100,3000)+E13),(IF((G13)<=9,1000+(G13)*100,3000)+1)&" – "&(IF((G13)<=9,1000+(G13)*100,3000)+99)&" und "&(IF((G13+1)<=9,1000+(G13+1)*100,3000))&" – "&(IF((G13+1)<=9,1000+(G13+1)*100,3000)+E13-100))) | I13: =IF(F13=0,"",(2000+G13*10+1)&" / "&(2000+G13*10+2)&" / "&(2000+G13*10+9)) | J13: =IF(F13=0,"","10."&D13&".0.0/16") | K13: =IF(F13=0,"",$B$6&"-"&C13&"-Pächter") | L13: =IF(F13=0,"",$B$6&"-"&C13&"-Gäste") | M13: =IF(F13=0,"",E13+3) | N13: =IF(F13=0,"",IF(E13>199,"Fehler: max. 199 Parzellen",IF(COUNTIF($D$9:$D$18,D13)>1,"Fehler: Sparten-ID doppelt",IF(OR(D13<1,D13>254),"Fehler: ID 1–254",IF(G13+F13-1>10,"Fehler: mehr als 10 Slots","OK"))))) | O13: =IF(F13=0,"","Parzelle 1 → VLAN "&(IF((G13)<=9,1000+(G13)*100,3000)+1)&" → Handy 10."&D13&".1.10") | P13: =P12+Q12 -> 265 | Q13: =IF(F13=0,0,E13+5) -> 0
A14: 6 | F14: =IF(OR(B14="",E14=""),0,IF(E14>99,2,1)) -> 0 | G14: =IF(F14=0,"",1+SUM($F$9:F13)) | H14: =IF(F14=0,"",IF(E14<=99,(IF((G14)<=9,1000+(G14)*100,3000)+1)&" – "&(IF((G14)<=9,1000+(G14)*100,3000)+E14),(IF((G14)<=9,1000+(G14)*100,3000)+1)&" – "&(IF((G14)<=9,1000+(G14)*100,3000)+99)&" und "&(IF((G14+1)<=9,1000+(G14+1)*100,3000))&" – "&(IF((G14+1)<=9,1000+(G14+1)*100,3000)+E14-100))) | I14: =IF(F14=0,"",(2000+G14*10+1)&" / "&(2000+G14*10+2)&" / "&(2000+G14*10+9)) | J14: =IF(F14=0,"","10."&D14&".0.0/16") | K14: =IF(F14=0,"",$B$6&"-"&C14&"-Pächter") | L14: =IF(F14=0,"",$B$6&"-"&C14&"-Gäste") | M14: =IF(F14=0,"",E14+3) | N14: =IF(F14=0,"",IF(E14>199,"Fehler: max. 199 Parzellen",IF(COUNTIF($D$9:$D$18,D14)>1,"Fehler: Sparten-ID doppelt",IF(OR(D14<1,D14>254),"Fehler: ID 1–254",IF(G14+F14-1>10,"Fehler: mehr als 10 Slots","OK"))))) | O14: =IF(F14=0,"","Parzelle 1 → VLAN "&(IF((G14)<=9,1000+(G14)*100,3000)+1)&" → Handy 10."&D14&".1.10") | P14: =P13+Q13 -> 265 | Q14: =IF(F14=0,0,E14+5) -> 0
A15: 7 | F15: =IF(OR(B15="",E15=""),0,IF(E15>99,2,1)) -> 0 | G15: =IF(F15=0,"",1+SUM($F$9:F14)) | H15: =IF(F15=0,"",IF(E15<=99,(IF((G15)<=9,1000+(G15)*100,3000)+1)&" – "&(IF((G15)<=9,1000+(G15)*100,3000)+E15),(IF((G15)<=9,1000+(G15)*100,3000)+1)&" – "&(IF((G15)<=9,1000+(G15)*100,3000)+99)&" und "&(IF((G15+1)<=9,1000+(G15+1)*100,3000))&" – "&(IF((G15+1)<=9,1000+(G15+1)*100,3000)+E15-100))) | I15: =IF(F15=0,"",(2000+G15*10+1)&" / "&(2000+G15*10+2)&" / "&(2000+G15*10+9)) | J15: =IF(F15=0,"","10."&D15&".0.0/16") | K15: =IF(F15=0,"",$B$6&"-"&C15&"-Pächter") | L15: =IF(F15=0,"",$B$6&"-"&C15&"-Gäste") | M15: =IF(F15=0,"",E15+3) | N15: =IF(F15=0,"",IF(E15>199,"Fehler: max. 199 Parzellen",IF(COUNTIF($D$9:$D$18,D15)>1,"Fehler: Sparten-ID doppelt",IF(OR(D15<1,D15>254),"Fehler: ID 1–254",IF(G15+F15-1>10,"Fehler: mehr als 10 Slots","OK"))))) | O15: =IF(F15=0,"","Parzelle 1 → VLAN "&(IF((G15)<=9,1000+(G15)*100,3000)+1)&" → Handy 10."&D15&".1.10") | P15: =P14+Q14 -> 265 | Q15: =IF(F15=0,0,E15+5) -> 0
A16: 8 | F16: =IF(OR(B16="",E16=""),0,IF(E16>99,2,1)) -> 0 | G16: =IF(F16=0,"",1+SUM($F$9:F15)) | H16: =IF(F16=0,"",IF(E16<=99,(IF((G16)<=9,1000+(G16)*100,3000)+1)&" – "&(IF((G16)<=9,1000+(G16)*100,3000)+E16),(IF((G16)<=9,1000+(G16)*100,3000)+1)&" – "&(IF((G16)<=9,1000+(G16)*100,3000)+99)&" und "&(IF((G16+1)<=9,1000+(G16+1)*100,3000))&" – "&(IF((G16+1)<=9,1000+(G16+1)*100,3000)+E16-100))) | I16: =IF(F16=0,"",(2000+G16*10+1)&" / "&(2000+G16*10+2)&" / "&(2000+G16*10+9)) | J16: =IF(F16=0,"","10."&D16&".0.0/16") | K16: =IF(F16=0,"",$B$6&"-"&C16&"-Pächter") | L16: =IF(F16=0,"",$B$6&"-"&C16&"-Gäste") | M16: =IF(F16=0,"",E16+3) | N16: =IF(F16=0,"",IF(E16>199,"Fehler: max. 199 Parzellen",IF(COUNTIF($D$9:$D$18,D16)>1,"Fehler: Sparten-ID doppelt",IF(OR(D16<1,D16>254),"Fehler: ID 1–254",IF(G16+F16-1>10,"Fehler: mehr als 10 Slots","OK"))))) | O16: =IF(F16=0,"","Parzelle 1 → VLAN "&(IF((G16)<=9,1000+(G16)*100,3000)+1)&" → Handy 10."&D16&".1.10") | P16: =P15+Q15 -> 265 | Q16: =IF(F16=0,0,E16+5) -> 0
A17: 9 | F17: =IF(OR(B17="",E17=""),0,IF(E17>99,2,1)) -> 0 | G17: =IF(F17=0,"",1+SUM($F$9:F16)) | H17: =IF(F17=0,"",IF(E17<=99,(IF((G17)<=9,1000+(G17)*100,3000)+1)&" – "&(IF((G17)<=9,1000+(G17)*100,3000)+E17),(IF((G17)<=9,1000+(G17)*100,3000)+1)&" – "&(IF((G17)<=9,1000+(G17)*100,3000)+99)&" und "&(IF((G17+1)<=9,1000+(G17+1)*100,3000))&" – "&(IF((G17+1)<=9,1000+(G17+1)*100,3000)+E17-100))) | I17: =IF(F17=0,"",(2000+G17*10+1)&" / "&(2000+G17*10+2)&" / "&(2000+G17*10+9)) | J17: =IF(F17=0,"","10."&D17&".0.0/16") | K17: =IF(F17=0,"",$B$6&"-"&C17&"-Pächter") | L17: =IF(F17=0,"",$B$6&"-"&C17&"-Gäste") | M17: =IF(F17=0,"",E17+3) | N17: =IF(F17=0,"",IF(E17>199,"Fehler: max. 199 Parzellen",IF(COUNTIF($D$9:$D$18,D17)>1,"Fehler: Sparten-ID doppelt",IF(OR(D17<1,D17>254),"Fehler: ID 1–254",IF(G17+F17-1>10,"Fehler: mehr als 10 Slots","OK"))))) | O17: =IF(F17=0,"","Parzelle 1 → VLAN "&(IF((G17)<=9,1000+(G17)*100,3000)+1)&" → Handy 10."&D17&".1.10") | P17: =P16+Q16 -> 265 | Q17: =IF(F17=0,0,E17+5) -> 0
A18: 10 | F18: =IF(OR(B18="",E18=""),0,IF(E18>99,2,1)) -> 0 | G18: =IF(F18=0,"",1+SUM($F$9:F17)) | H18: =IF(F18=0,"",IF(E18<=99,(IF((G18)<=9,1000+(G18)*100,3000)+1)&" – "&(IF((G18)<=9,1000+(G18)*100,3000)+E18),(IF((G18)<=9,1000+(G18)*100,3000)+1)&" – "&(IF((G18)<=9,1000+(G18)*100,3000)+99)&" und "&(IF((G18+1)<=9,1000+(G18+1)*100,3000))&" – "&(IF((G18+1)<=9,1000+(G18+1)*100,3000)+E18-100))) | I18: =IF(F18=0,"",(2000+G18*10+1)&" / "&(2000+G18*10+2)&" / "&(2000+G18*10+9)) | J18: =IF(F18=0,"","10."&D18&".0.0/16") | K18: =IF(F18=0,"",$B$6&"-"&C18&"-Pächter") | L18: =IF(F18=0,"",$B$6&"-"&C18&"-Gäste") | M18: =IF(F18=0,"",E18+3) | N18: =IF(F18=0,"",IF(E18>199,"Fehler: max. 199 Parzellen",IF(COUNTIF($D$9:$D$18,D18)>1,"Fehler: Sparten-ID doppelt",IF(OR(D18<1,D18>254),"Fehler: ID 1–254",IF(G18+F18-1>10,"Fehler: mehr als 10 Slots","OK"))))) | O18: =IF(F18=0,"","Parzelle 1 → VLAN "&(IF((G18)<=9,1000+(G18)*100,3000)+1)&" → Handy 10."&D18&".1.10") | P18: =P17+Q17 -> 265 | Q18: =IF(F18=0,0,E18+5) -> 0
A20: Slots belegt (max. 10) | B20: =SUM(F9:F18) -> 4
A21: Netze gesamt am Gateway | B21: =SUM(M9:M18)+1 -> 257
A22: Parzellen gesamt | B22: =SUM(E9:E18) -> 244
A23: Gesamtprüfung | B23: =IF(B20>10,"Fehler: mehr als 10 Slots",IF(COUNTIF(N9:N18,"Fehler*")>0,"Fehler in Tabelle","OK")) -> OK
A24: Hinweis | B24: =IF(B21>300,"Mehr als 300 Netze: Gateway-Leistung vorher testen, ggf. größeres Gateway","")
A26: Beispiel: die vier Vereine an der Straße Buchenweg (Buchenweg 62–77). Parzellenzahlen außer Buchenweg sind Schätzungen.

Sheet Übersicht
A1: ="IP-Plan "&Eingabe!$B$5 -> IP-Plan KGS Buchenweg e.V.
A3: Gateway (Hauptverteiler) | B3: 1 | C3: ="10.0."&Eingabe!$B$4&".0/24" -> 10.0.1.0/24 | D3: 255.255.255.0 | E3: ="10.0."&Eingabe!$B$4&".1" -> 10.0.1.1 | F3: ="10.0."&Eingabe!$B$4&".2 – .50" -> 10.0.1.2 – .50 | G3: Technik des Gateways (untagged)
A5: Netz | B5: VLAN | C5: Netz (Subnetz) | D5: Subnetzmaske | E5: Router-IP | F5: Geräte-IPs (automatisch) | G5: WLAN und Zugang
A6: =IF(I6="","",IF(J6=0,"Sparte "&I6&": "&INDEX(Eingabe!$B$9:$B$18,I6)&" (Sparten-ID "&INDEX(Eingabe!$D$9:$D$18,I6)&", "&K6&" Parzellen)",IF(J6<=K6," Parzelle "&J6,IF(J6=K6+1," Vorstand",IF(J6=K6+2," Gäste",IF(J6=K6+3," Technik (Switches, Access Points)","")))))) -> Sparte 1: KGS Buchenweg e.V. (Sparten-ID 1, 85 Parzellen) | B6: =IF(I6="","",IF(AND(J6>=1,J6<=K6+3),IF(J6<=K6,IF(J6<=99,IF((INDEX(Eingabe!$G$9:$G$18,I6))<=9,1000+(INDEX(Eingabe!$G$9:$G$18,I6))*100,3000)+J6,IF((INDEX(Eingabe!$G$9:$G$18,I6)+1)<=9,1000+(INDEX(Eingabe!$G$9:$G$18,I6)+1)*100,3000)+J6-100),IF(J6=K6+1,2000+INDEX(Eingabe!$G$9:$G$18,I6)*10+1,IF(J6=K6+2,2000+INDEX(Eingabe!$G$9:$G$18,I6)*10+2,2000+INDEX(Eingabe!$G$9:$G$18,I6)*10+9))),"")) | C6: =IF(I6="","",IF(AND(J6>=1,J6<=K6+3),"10."&INDEX(Eingabe!$D$9:$D$18,I6)&"."&IF(J6<=K6,J6,IF(J6=K6+1,200,IF(J6=K6+2,201,250)))&".0/24","")) | D6: =IF(I6="","",IF(AND(J6>=1,J6<=K6+3),"255.255.255.0","")) | E6: =IF(I6="","",IF(AND(J6>=1,J6<=K6+3),"10."&INDEX(Eingabe!$D$9:$D$18,I6)&"."&IF(J6<=K6,J6,IF(J6=K6+1,200,IF(J6=K6+2,201,250)))&".1","")) | F6: =IF(I6="","",IF(AND(J6>=1,J6<=K6+3),"10."&INDEX(Eingabe!$D$9:$D$18,I6)&"."&IF(J6<=K6,J6,IF(J6=K6+1,200,IF(J6=K6+2,201,250)))&".10 – 10."&INDEX(Eingabe!$D$9:$D$18,I6)&"."&IF(J6<=K6,J6,IF(J6=K6+1,200,IF(J6=K6+2,201,250)))&".250","")) | G6: =IF(I6="","",IF(AND(J6>=1,J6<=K6),Eingabe!$B$6&"-"&INDEX(Eingabe!$C$9:$C$18,I6)&"-Pächter · Passwort Parzelle "&J6,IF(J6=K6+1,Eingabe!$B$6&"-"&INDEX(Eingabe!$C$9:$C$18,I6)&"-Vorstand · eigenes WLAN",IF(J6=K6+2,Eingabe!$B$6&"-"&INDEX(Eingabe!$C$9:$C$18,I6)&"-Gäste · Voucher",IF(J6=K6+3,"Kabel · Access Point y = .(50+y), Mast-Switch x = .(10+x)",""))))) | I6: =IF(1<=(Eingabe!$P$18+Eingabe!$Q$18-1),MATCH(1,Eingabe!$P$9:$P$18,1),"") -> 1 | J6: =IF(I6="","",1-INDEX(Eingabe!$P$9:$P$18,I6)) -> 0 | K6: =IF(I6="","",INDEX(Eingabe!$E$9:$E$18,I6)) -> 85
A7: =IF(I7="","",IF(J7=0,"Sparte "&I7&": "&INDEX(Eingabe!$B$9:$B$18,I7)&" (Sparten-ID "&INDEX(Eingabe!$D$9:$D$18,I7)&", "&K7&" Parzellen)",IF(J7<=K7," Parzelle "&J7,IF(J7=K7+1," Vorstand",IF(J7=K7+2," Gäste",IF(J7=K7+3," Technik (Switches, Access Points)","")))))) -> Parzelle 1 | B7: =IF(I7="","",IF(AND(J7>=1,J7<=K7+3),IF(J7<=K7,IF(J7<=99,IF((INDEX(Eingabe!$G$9:$G$18,I7))<=9,1000+(INDEX(Eingabe!$G$9:$G$18,I7))*100,3000)+J7,IF((INDEX(Eingabe!$G$9:$G$18,I7)+1)<=9,1000+(INDEX(Eingabe!$G$9:$G$18,I7)+1)*100,3000)+J7-100),IF(J7=K7+1,2000+INDEX(Eingabe!$G$9:$G$18,I7)*10+1,IF(J7=K7+2,2000+INDEX(Eingabe!$G$9:$G$18,I7)*10+2,2000+INDEX(Eingabe!$G$9:$G$18,I7)*10+9))),"")) -> 1101 | C7: =IF(I7="","",IF(AND(J7>=1,J7<=K7+3),"10."&INDEX(Eingabe!$D$9:$D$18,I7)&"."&IF(J7<=K7,J7,IF(J7=K7+1,200,IF(J7=K7+2,201,250)))&".0/24","")) -> 10.1.1.0/24 | D7: =IF(I7="","",IF(AND(J7>=1,J7<=K7+3),"255.255.255.0","")) -> 255.255.255.0 | E7: =IF(I7="","",IF(AND(J7>=1,J7<=K7+3),"10."&INDEX(Eingabe!$D$9:$D$18,I7)&"."&IF(J7<=K7,J7,IF(J7=K7+1,200,IF(J7=K7+2,201,250)))&".1","")) -> 10.1.1.1 | F7: =IF(I7="","",IF(AND(J7>=1,J7<=K7+3),"10."&INDEX(Eingabe!$D$9:$D$18,I7)&"."&IF(J7<=K7,J7,IF(J7=K7+1,200,IF(J7=K7+2,201,250)))&".10 – 10."&INDEX(Eingabe!$D$9:$D$18,I7)&"."&IF(J7<=K7,J7,IF(J7=K7+1,200,IF(J7=K7+2,201,250)))&".250","")) -> 10.1.1.10 – 10.1.1.250 | G7: =IF(I7="","",IF(AND(J7>=1,J7<=K7),Eingabe!$B$6&"-"&INDEX(Eingabe!$C$9:$C$18,I7)&"-Pächter · Passwort Parzelle "&J7,IF(J7=K7+1,Eingabe!$B$6&"-"&INDEX(Eingabe!$C$9:$C$18,I7)&"-Vorstand · eigenes WLAN",IF(J7=K7+2,Eingabe!$B$6&"-"&INDEX(Eingabe!$C$9:$C$18,I7)&"-Gäste · Voucher",IF(J7=K7+3,"Kabel · Access Point y = .(50+y), Mast-Switch x = .(10+x)",""))))) -> SparteNet.de-BW-Pächter · Passwort Parzelle 1 | I7: =IF(2<=(Eingabe!$P$18+Eingabe!$Q$18-1),MATCH(2,Eingabe!$P$9:$P$18,1),"") -> 1 | J7: =IF(I7="","",2-INDEX(Eingabe!$P$9:$P$18,I7)) -> 1 | K7: =IF(I7="","",INDEX(Eingabe!$E$9:$E$18,I7)) -> 85
A8: =IF(I8="","",IF(J8=0,"Sparte "&I8&": "&INDEX(Eingabe!$B$9:$B$18,I8)&" (Sparten-ID "&INDEX(Eingabe!$D$9:$D$18,I8)&", "&K8&" Parzellen)",IF(J8<=K8," Parzelle "&J8,IF(J8=K8+1," Vorstand",IF(J8=K8+2," Gäste",IF(J8=K8+3," Technik (Switches, Access Points)","")))))) -> Parzelle 2 | B8: =IF(I8="","",IF(AND(J8>=1,J8<=K8+3),IF(J8<=K8,IF(J8<=99,IF((INDEX(Eingabe!$G$9:$G$18,I8))<=9,1000+(INDEX(Eingabe!$G$9:$G$18,I8))*100,3000)+J8,IF((INDEX(Eingabe!$G$9:$G$18,I8)+1)<=9,1000+(INDEX(Eingabe!$G$9:$G$18,I8)+1)*100,3000)+J8-100),IF(J8=K8+1,2000+INDEX(Eingabe!$G$9:$G$18,I8)*10+1,IF(J8=K8+2,2000+INDEX(Eingabe!$G$9:$G$18,I8)*10+2,2000+INDEX(Eingabe!$G$9:$G$18,I8)*10+9))),"")) -> 1102 | C8: =IF(I8="","",IF(AND(J8>=1,J8<=K8+3),"10."&INDEX(Eingabe!$D$9:$D$18,I8)&"."&IF(J8<=K8,J8,IF(J8=K8+1,200,IF(J8=K8+2,201,250)))&".0/24","")) -> 10.1.2.0/24 | D8: =IF(I8="","",IF(AND(J8>=1,J8<=K8+3),"255.255.255.0","")) -> 255.255.255.0 | E8: =IF(I8="","",IF(AND(J8>=1,J8<=K8+3),"10."&INDEX(Eingabe!$D$9:$D$18,I8)&"."&IF(J8<=K8,J8,IF(J8=K8+1,200,IF(J8=K8+2,201,250)))&".1","")) -> 10.1.2.1 | F8: =IF(I8="","",IF(AND(J8>=1,J8<=K8+3),"10."&INDEX(Eingabe!$D$9:$D$18,I8)&"."&IF(J8<=K8,J8,IF(J8=K8+1,200,IF(J8=K8+2,201,250)))&".10 – 10."&INDEX(Eingabe!$D$9:$D$18,I8)&"."&IF(J8<=K8,J8,IF(J8=K8+1,200,IF(J8=K8+2,201,250)))&".250","")) -> 10.1.2.10 – 10.1.2.250 | G8: =IF(I8="","",IF(AND(J8>=1,J8<=K8),Eingabe!$B$6&"-"&INDEX(Eingabe!$C$9:$C$18,I8)&"-Pächter · Passwort Parzelle "&J8,IF(J8=K8+1,Eingabe!$B$6&"-"&INDEX(Eingabe!$C$9:$C$18,I8)&"-Vorstand · eigenes WLAN",IF(J8=K8+2,Eingabe!$B$6&"-"&INDEX(Eingabe!$C$9:$C$18,I8)&"-Gäste · Voucher",IF(J8=K8+3,"Kabel · Access Point y = .(50+y), Mast-Switch x = .(10+x)",""))))) -> SparteNet.de-BW-Pächter · Passwort Parzelle 2 | I8: =IF(3<=(Eingabe!$P$18+Eingabe!$Q$18-1),MATCH(3,Eingabe!$P$9:$P$18,1),"") -> 1 | J8: =IF(I8="","",3-INDEX(Eingabe!$P$9:$P$18,I8)) -> 2 | K8: =IF(I8="","",INDEX(Eingabe!$E$9:$E$18,I8)) -> 85
A9: =IF(I9="","",IF(J9=0,"Sparte "&I9&": "&INDEX(Eingabe!$B$9:$B$18,I9)&" (Sparten-ID "&INDEX(Eingabe!$D$9:$D$18,I9)&", "&K9&" Parzellen)",IF(J9<=K9," Parzelle "&J9,IF(J9=K9+1," Vorstand",IF(J9=K9+2," Gäste",IF(J9=K9+3," Technik (Switches, Access Points)","")))))) -> Parzelle 3 | B9: =IF(I9="","",IF(AND(J9>=1,J9<=K9+3),IF(J9<=K9,IF(J9<=99,IF((INDEX(Eingabe!$G$9:$G$18,I9))<=9,1000+(INDEX(Eingabe!$G$9:$G$18,I9))*100,3000)+J9,IF((INDEX(Eingabe!$G$9:$G$18,I9)+1)<=9,1000+(INDEX(Eingabe!$G$9:$G$18,I9)+1)*100,3000)+J9-100),IF(J9=K9+1,2000+INDEX(Eingabe!$G$9:$G$18,I9)*10+1,IF(J9=K9+2,2000+INDEX(Eingabe!$G$9:$G$18,I9)*10+2,2000+INDEX(Eingabe!$G$9:$G$18,I9)*10+9))),"")) -> 1103 | C9: =IF(I9="","",IF(AND(J9>=1,J9<=K9+3),"10."&INDEX(Eingabe!$D$9:$D$18,I9)&"."&IF(J9<=K9,J9,IF(J9=K9+1,200,IF(J9=K9+2,201,250)))&".0/24","")) -> 10.1.3.0/24 | D9: =IF(I9="","",IF(AND(J9>=1,J9<=K9+3),"255.255.255.0","")) -> 255.255.255.0 | E9: =IF(I9="","",IF(AND(J9>=1,J9<=K9+3),"10."&INDEX(Eingabe!$D$9:$D$18,I9)&"."&IF(J9<=K9,J9,IF(J9=K9+1,200,IF(J9=K9+2,201,250)))&".1","")) -> 10.1.3.1 | F9: =IF(I9="","",IF(AND(J9>=1,J9<=K9+3),"10."&INDEX(Eingabe!$D$9:$D$18,I9)&"."&IF(J9<=K9,J9,IF(J9=K9+1,200,IF(J9=K9+2,201,250)))&".10 – 10."&INDEX(Eingabe!$D$9:$D$18,I9)&"."&IF(J9<=K9,J9,IF(J9=K9+1,200,IF(J9=K9+2,201,250)))&".250","")) -> 10.1.3.10 – 10.1.3.250 | G9: =IF(I9="","",IF(AND(J9>=1,J9<=K9),Eingabe!$B$6&"-"&INDEX(Eingabe!$C$9:$C$18,I9)&"-Pächter · Passwort Parzelle "&J9,IF(J9=K9+1,Eingabe!$B$6&"-"&INDEX(Eingabe!$C$9:$C$18,I9)&"-Vorstand · eigenes WLAN",IF(J9=K9+2,Eingabe!$B$6&"-"&INDEX(Eingabe!$C$9:$C$18,I9)&"-Gäste · Voucher",IF(J9=K9+3,"Kabel · Access Point y = .(50+y), Mast-Switch x = .(10+x)",""))))) -> SparteNet.de-BW-Pächter · Passwort Parzelle 3 | I9: =IF(4<=(Eingabe!$P$18+Eingabe!$Q$18-1),MATCH(4,Eingabe!$P$9:$P$18,1),"") -> 1 | J9: =IF(I9="","",4-INDEX(Eingabe!$P$9:$P$18,I9)) -> 3 | K9: =IF(I9="","",INDEX(Eingabe!$E$9:$E$18,I9)) -> 85
A10: =IF(I10="","",IF(J10=0,"Sparte "&I10&": "&INDEX(Eingabe!$B$9:$B$18,I10)&" (Sparten-ID "&INDEX(Eingabe!$D$9:$D$18,I10)&", "&K10&" Parzellen)",IF(J10<=K10," Parzelle "&J10,IF(J10=K10+1," Vorstand",IF(J10=K10+2," Gäste",IF(J10=K10+3," Technik (Switches, Access Points)","")))))) -> Parzelle 4 | B10: =IF(I10="","",IF(AND(J10>=1,J10<=K10+3),IF(J10<=K10,IF(J10<=99,IF((INDEX(Eingabe!$G$9:$G$18,I10))<=9,1000+(INDEX(Eingabe!$G$9:$G$18,I10))*100,3000)+J10,IF((INDEX(Eingabe!$G$9:$G$18,I10)+1)<=9,1000+(INDEX(Eingabe!$G$9:$G$18,I10)+1)*100,3000)+J10-100),IF(J10=K10+1,2000+INDEX(Eingabe!$G$9:$G$18,I10)*10+1,IF(J10=K10+2,2000+INDEX(Eingabe!$G$9:$G$18,I10)*10+2,2000+INDEX(Eingabe!$G$9:$G$18,I10)*10+9))),"")) -> 1104 | C10: =IF(I10="","",IF(AND(J10>=1,J10<=K10+3),"10."&INDEX(Eingabe!$D$9:$D$18,I10)&"."&IF(J10<=K10,J10,IF(J10=K10+1,200,IF(J10=K10+2,201,250)))&".0/24","")) -> 10.1.4.0/24 | D10: =IF(I10="","",IF(AND(J10>=1,J10<=K10+3),"255.255.255.0","")) -> 255.255.255.0 | E10: =IF(I10="","",IF(AND(J10>=1,J10<=K10+3),"10."&INDEX(Eingabe!$D$9:$D$18,I10)&"."&IF(J10<=K10,J10,IF(J10=K10+1,200,IF(J10=K10+2,201,250)))&".1","")) -> 10.1.4.1 | F10: =IF(I10="","",IF(AND(J10>=1,J10<=K10+3),"10."&INDEX(Eingabe!$D$9:$D$18,I10)&"."&IF(J10<=K10,J10,IF(J10=K10+1,200,IF(J10=K10+2,201,250)))&".10 – 10."&INDEX(Eingabe!$D$9:$D$18,I10)&"."&IF(J10<=K10,J10,IF(J10=K10+1,200,IF(J10=K10+2,201,250)))&".250","")) -> 10.1.4.10 – 10.1.4.250 | G10: =IF(I10="","",IF(AND(J10>=1,J10<=K10),Eingabe!$B$6&"-"&INDEX(Eingabe!$C$9:$C$18,I10)&"-Pächter · Passwort Parzelle "&J10,IF(J10=K10+1,Eingabe!$B$6&"-"&INDEX(Eingabe!$C$9:$C$18,I10)&"-Vorstand · eigenes WLAN",IF(J10=K10+2,Eingabe!$B$6&"-"&INDEX(Eingabe!$C$9:$C$18,I10)&"-Gäste · Voucher",IF(J10=K10+3,"Kabel · Access Point y = .(50+y), Mast-Switch x = .(10+x)",""))))) -> SparteNet.de-BW-Pächter · Passwort Parzelle 4 | I10: =IF(5<=(Eingabe!$P$18+Eingabe!$Q$18-1),MATCH(5,Eingabe!$P$9:$P$18,1),"") -> 1 | J10: =IF(I10="","",5-INDEX(Eingabe!$P$9:$P$18,I10)) -> 4 | K10: =IF(I10="","",INDEX(Eingabe!$E$9:$E$18,I10)) -> 85
A11: =IF(I11="","",IF(J11=0,"Sparte "&I11&": "&INDEX(Eingabe!$B$9:$B$18,I11)&" (Sparten-ID "&INDEX(Eingabe!$D$9:$D$18,I11)&", "&K11&" Parzellen)",IF(J11<=K11," Parzelle "&J11,IF(J11=K11+1," Vorstand",IF(J11=K11+2," Gäste",IF(J11=K11+3," Technik (Switches, Access Points)","")))))) -> Parzelle 5 | B11: =IF(I11="","",IF(AND(J11>=1,J11<=K11+3),IF(J11<=K11,IF(J11<=99,IF((INDEX(Eingabe!$G$9:$G$18,I11))<=9,1000+(INDEX(Eingabe!$G$9:$G$18,I11))*100,3000)+J11,IF((INDEX(Eingabe!$G$9:$G$18,I11)+1)<=9,1000+(INDEX(Eingabe!$G$9:$G$18,I11)+1)*100,3000)+J11-100),IF(J11=K11+1,2000+INDEX(Eingabe!$G$9:$G$18,I11)*10+1,IF(J11=K11+2,2000+INDEX(Eingabe!$G$9:$G$18,I11)*10+2,2000+INDEX(Eingabe!$G$9:$G$18,I11)*10+9))),"")) -> 1105 | C11: =IF(I11="","",IF(AND(J11>=1,J11<=K11+3),"10."&INDEX(Eingabe!$D$9:$D$18,I11)&"."&IF(J11<=K11,J11,IF(J11=K11+1,200,IF(J11=K11+2,201,250)))&".0/24","")) -> 10.1.5.0/24 | D11: =IF(I11="","",IF(AND(J11>=1,J11<=K11+3),"255.255.255.0","")) -> 255.255.255.0 | E11: =IF(I11="","",IF(AND(J11>=1,J11<=K11+3),"10."&INDEX(Eingabe!$D$9:$D$18,I11)&"."&IF(J11<=K11,J11,IF(J11=K11+1,200,IF(J11=K11+2,201,250)))&".1","")) -> 10.1.5.1 | F11: =IF(I11="","",IF(AND(J11>=1,J11<=K11+3),"10."&INDEX(Eingabe!$D$9:$D$18,I11)&"."&IF(J11<=K11,J11,IF(J11=K11+1,200,IF(J11=K11+2,201,250)))&".10 – 10."&INDEX(Eingabe!$D$9:$D$18,I11)&"."&IF(J11<=K11,J11,IF(J11=K11+1,200,IF(J11=K11+2,201,250)))&".250","")) -> 10.1.5.10 – 10.1.5.250 | G11: =IF(I11="","",IF(AND(J11>=1,J11<=K11),Eingabe!$B$6&"-"&INDEX(Eingabe!$C$9:$C$18,I11)&"-Pächter · Passwort Parzelle "&J11,IF(J11=K11+1,Eingabe!$B$6&"-"&INDEX(Eingabe!$C$9:$C$18,I11)&"-Vorstand · eigenes WLAN",IF(J11=K11+2,Eingabe!$B$6&"-"&INDEX(Eingabe!$C$9:$C$18,I11)&"-Gäste · Voucher",IF(J11=K11+3,"Kabel · Access Point y = .(50+y), Mast-Switch x = .(10+x)",""))))) -> SparteNet.de-BW-Pächter · Passwort Parzelle 5 | I11: =IF(6<=(Eingabe!$P$18+Eingabe!$Q$18-1),MATCH(6,Eingabe!$P$9:$P$18,1),"") -> 1 | J11: =IF(I11="","",6-INDEX(Eingabe!$P$9:$P$18,I11)) -> 5 | K11: =IF(I11="","",INDEX(Eingabe!$E$9:$E$18,I11)) -> 85
A12: =IF(I12="","",IF(J12=0,"Sparte "&I12&": "&INDEX(Eingabe!$B$9:$B$18,I12)&" (Sparten-ID "&INDEX(Eingabe!$D$9:$D$18,I12)&", "&K12&" Parzellen)",IF(J12<=K12," Parzelle "&J12,IF(J12=K12+1," Vorstand",IF(J12=K12+2," Gäste",IF(J12=K12+3," Technik (Switches, Access Points)","")))))) -> Parzelle 6 | B12: =IF(I12="","",IF(AND(J12>=1,J12<=K12+3),IF(J12<=K12,IF(J12<=99,IF((INDEX(Eingabe!$G$9:$G$18,I12))<=9,1000+(INDEX(Eingabe!$G$9:$G$18,I12))*100,3000)+J12,IF((INDEX(Eingabe!$G$9:$G$18,I12)+1)<=9,1000+(INDEX(Eingabe!$G$9:$G$18,I12)+1)*100,3000)+J12-100),IF(J12=K12+1,2000+INDEX(Eingabe!$G$9:$G$18,I12)*10+1,IF(J12=K12+2,2000+INDEX(Eingabe!$G$9:$G$18,I12)*10+2,2000+INDEX(Eingabe!$G$9:$G$18,I12)*10+9))),"")) -> 1106 | C12: =IF(I12="","",IF(AND(J12>=1,J12<=K12+3),"10."&INDEX(Eingabe!$D$9:$D$18,I12)&"."&IF(J12<=K12,J12,IF(J12=K12+1,200,IF(J12=K12+2,201,250)))&".0/24","")) -> 10.1.6.0/24 | D12: =IF(I12="","",IF(AND(J12>=1,J12<=K12+3),"255.255.255.0","")) -> 255.255.255.0 | E12: =IF(I12="","",IF(AND(J12>=1,J12<=K12+3),"10."&INDEX(Eingabe!$D$9:$D$18,I12)&"."&IF(J12<=K12,J12,IF(J12=K12+1,200,IF(J12=K12+2,201,250)))&".1","")) -> 10.1.6.1 | F12: =IF(I12="","",IF(AND(J12>=1,J12<=K12+3),"10."&INDEX(Eingabe!$D$9:$D$18,I12)&"."&IF(J12<=K12,J12,IF(J12=K12+1,200,IF(J12=K12+2,201,250)))&".10 – 10."&INDEX(Eingabe!$D$9:$D$18,I12)&"."&IF(J12<=K12,J12,IF(J12=K12+1,200,IF(J12=K12+2,201,250)))&".250","")) -> 10.1.6.10 – 10.1.6.250 | G12: =IF(I12="","",IF(AND(J12>=1,J12<=K12),Eingabe!$B$6&"-"&INDEX(Eingabe!$C$9:$C$18,I12)&"-Pächter · Passwort Parzelle "&J12,IF(J12=K12+1,Eingabe!$B$6&"-"&INDEX(Eingabe!$C$9:$C$18,I12)&"-Vorstand · eigenes WLAN",IF(J12=K12+2,Eingabe!$B$6&"-"&INDEX(Eingabe!$C$9:$C$18,I12)&"-Gäste · Voucher",IF(J12=K12+3,"Kabel · Access Point y = .(50+y), Mast-Switch x = .(10+x)",""))))) -> SparteNet.de-BW-Pächter · Passwort Parzelle 6 | I12: =IF(7<=(Eingabe!$P$18+Eingabe!$Q$18-1),MATCH(7,Eingabe!$P$9:$P$18,1),"") -> 1 | J12: =IF(I12="","",7-INDEX(Eingabe!$P$9:$P$18,I12)) -> 6 | K12: =IF(I12="","",INDEX(Eingabe!$E$9:$E$18,I12)) -> 85
A13: =IF(I13="","",IF(J13=0,"Sparte "&I13&": "&INDEX(Eingabe!$B$9:$B$18,I13)&" (Sparten-ID "&INDEX(Eingabe!$D$9:$D$18,I13)&", "&K13&" Parzellen)",IF(J13<=K13," Parzelle "&J13,IF(J13=K13+1," Vorstand",IF(J13=K13+2," Gäste",IF(J13=K13+3," Technik (Switches, Access Points)","")))))) -> Parzelle 7 | B13: =IF(I13="","",IF(AND(J13>=1,J13<=K13+3),IF(J13<=K13,IF(J13<=99,IF((INDEX(Eingabe!$G$9:$G$18,I13))<=9,1000+(INDEX(Eingabe!$G$9:$G$18,I13))*100,3000)+J13,IF((INDEX(Eingabe!$G$9:$G$18,I13)+1)<=9,1000+(INDEX(Eingabe!$G$9:$G$18,I13)+1)*100,3000)+J13-100),IF(J13=K13+1,2000+INDEX(Eingabe!$G$9:$G$18,I13)*10+1,IF(J13=K13+2,2000+INDEX(Eingabe!$G$9:$G$18,I13)*10+2,2000+INDEX(Eingabe!$G$9:$G$18,I13)*10+9))),"")) -> 1107 | C13: =IF(I13="","",IF(AND(J13>=1,J13<=K13+3),"10."&INDEX(Eingabe!$D$9:$D$18,I13)&"."&IF(J13<=K13,J13,IF(J13=K13+1,200,IF(J13=K13+2,201,250)))&".0/24","")) -> 10.1.7.0/24 | D13: =IF(I13="","",IF(AND(J13>=1,J13<=K13+3),"255.255.255.0","")) -> 255.255.255.0 | E13: =IF(I13="","",IF(AND(J13>=1,J13<=K13+3),"10."&INDEX(Eingabe!$D$9:$D$18,I13)&"."&IF(J13<=K13,J13,IF(J13=K13+1,200,IF(J13=K13+2,201,250)))&".1","")) -> 10.1.7.1 | F13: =IF(I13="","",IF(AND(J13>=1,J13<=K13+3),"10."&INDEX(Eingabe!$D$9:$D$18,I13)&"."&IF(J13<=K13,J13,IF(J13=K13+1,200,IF(J13=K13+2,201,250)))&".10 – 10."&INDEX(Eingabe!$D$9:$D$18,I13)&"."&IF(J13<=K13,J13,IF(J13=K13+1,200,IF(J13=K13+2,201,250)))&".250","")) -> 10.1.7.10 – 10.1.7.250 | G13: =IF(I13="","",IF(AND(J13>=1,J13<=K13),Eingabe!$B$6&"-"&INDEX(Eingabe!$C$9:$C$18,I13)&"-Pächter · Passwort Parzelle "&J13,IF(J13=K13+1,Eingabe!$B$6&"-"&INDEX(Eingabe!$C$9:$C$18,I13)&"-Vorstand · eigenes WLAN",IF(J13=K13+2,Eingabe!$B$6&"-"&INDEX(Eingabe!$C$9:$C$18,I13)&"-Gäste · Voucher",IF(J13=K13+3,"Kabel · Access Point y = .(50+y), Mast-Switch x = .(10+x)",""))))) -> SparteNet.de-BW-Pächter · Passwort Parzelle 7 | I13: =IF(8<=(Eingabe!$P$18+Eingabe!$Q$18-1),MATCH(8,Eingabe!$P$9:$P$18,1),"") -> 1 | J13: =IF(I13="","",8-INDEX(Eingabe!$P$9:$P$18,I13)) -> 7 | K13: =IF(I13="","",INDEX(Eingabe!$E$9:$E$18,I13)) -> 85
A14: =IF(I14="","",IF(J14=0,"Sparte "&I14&": "&INDEX(Eingabe!$B$9:$B$18,I14)&" (Sparten-ID "&INDEX(Eingabe!$D$9:$D$18,I14)&", "&K14&" Parzellen)",IF(J14<=K14," Parzelle "&J14,IF(J14=K14+1," Vorstand",IF(J14=K14+2," Gäste",IF(J14=K14+3," Technik (Switches, Access Points)","")))))) -> Parzelle 8 | B14: =IF(I14="","",IF(AND(J14>=1,J14<=K14+3),IF(J14<=K14,IF(J14<=99,IF((INDEX(Eingabe!$G$9:$G$18,I14))<=9,1000+(INDEX(Eingabe!$G$9:$G$18,I14))*100,3000)+J14,IF((INDEX(Eingabe!$G$9:$G$18,I14)+1)<=9,1000+(INDEX(Eingabe!$G$9:$G$18,I14)+1)*100,3000)+J14-100),IF(J14=K14+1,2000+INDEX(Eingabe!$G$9:$G$18,I14)*10+1,IF(J14=K14+2,2000+INDEX(Eingabe!$G$9:$G$18,I14)*10+2,2000+INDEX(Eingabe!$G$9:$G$18,I14)*10+9))),"")) -> 1108 | C14: =IF(I14="","",IF(AND(J14>=1,J14<=K14+3),"10."&INDEX(Eingabe!$D$9:$D$18,I14)&"."&IF(J14<=K14,J14,IF(J14=K14+1,200,IF(J14=K14+2,201,250)))&".0/24","")) -> 10.1.8.0/24 | D14: =IF(I14="","",IF(AND(J14>=1,J14<=K14+3),"255.255.255.0","")) -> 255.255.255.0 | E14: =IF(I14="","",IF(AND(J14>=1,J14<=K14+3),"10."&INDEX(Eingabe!$D$9:$D$18,I14)&"."&IF(J14<=K14,J14,IF(J14=K14+1,200,IF(J14=K14+2,201,250)))&".1","")) -> 10.1.8.1 | F14: =IF(I14="","",IF(AND(J14>=1,J14<=K14+3),"10."&INDEX(Eingabe!$D$9:$D$18,I14)&"."&IF(J14<=K14,J14,IF(J14=K14+1,200,IF(J14=K14+2,201,250)))&".10 – 10."&INDEX(Eingabe!$D$9:$D$18,I14)&"."&IF(J14<=K14,J14,IF(J14=K14+1,200,IF(J14=K14+2,201,250)))&".250","")) -> 10.1.8.10 – 10.1.8.250 | G14: =IF(I14="","",IF(AND(J14>=1,J14<=K14),Eingabe!$B$6&"-"&INDEX(Eingabe!$C$9:$C$18,I14)&"-Pächter · Passwort Parzelle "&J14,IF(J14=K14+1,Eingabe!$B$6&"-"&INDEX(Eingabe!$C$9:$C$18,I14)&"-Vorstand · eigenes WLAN",IF(J14=K14+2,Eingabe!$B$6&"-"&INDEX(Eingabe!$C$9:$C$18,I14)&"-Gäste · Voucher",IF(J14=K14+3,"Kabel · Access Point y = .(50+y), Mast-Switch x = .(10+x)",""))))) -> SparteNet.de-BW-Pächter · Passwort Parzelle 8 | I14: =IF(9<=(Eingabe!$P$18+Eingabe!$Q$18-1),MATCH(9,Eingabe!$P$9:$P$18,1),"") -> 1 | J14: =IF(I14="","",9-INDEX(Eingabe!$P$9:$P$18,I14)) -> 8 | K14: =IF(I14="","",INDEX(Eingabe!$E$9:$E$18,I14)) -> 85
A15: =IF(I15="","",IF(J15=0,"Sparte "&I15&": "&INDEX(Eingabe!$B$9:$B$18,I15)&" (Sparten-ID "&INDEX(Eingabe!$D$9:$D$18,I15)&", "&K15&" Parzellen)",IF(J15<=K15," Parzelle "&J15,IF(J15=K15+1," Vorstand",IF(J15=K15+2," Gäste",IF(J15=K15+3," Technik (Switches, Access Points)","")))))) -> Parzelle 9 | B15: =IF(I15="","",IF(AND(J15>=1,J15<=K15+3),IF(J15<=K15,IF(J15<=99,IF((INDEX(Eingabe!$G$9:$G$18,I15))<=9,1000+(INDEX(Eingabe!$G$9:$G$18,I15))*100,3000)+J15,IF((INDEX(Eingabe!$G$9:$G$18,I15)+1)<=9,1000+(INDEX(Eingabe!$G$9:$G$18,I15)+1)*100,3000)+J15-100),IF(J15=K15+1,2000+INDEX(Eingabe!$G$9:$G$18,I15)*10+1,IF(J15=K15+2,2000+INDEX(Eingabe!$G$9:$G$18,I15)*10+2,2000+INDEX(Eingabe!$G$9:$G$18,I15)*10+9))),"")) -> 1109 | C15: =IF(I15="","",IF(AND(J15>=1,J15<=K15+3),"10."&INDEX(Eingabe!$D$9:$D$18,I15)&"."&IF(J15<=K15,J15,IF(J15=K15+1,200,IF(J15=K15+2,201,250)))&".0/24","")) -> 10.1.9.0/24 | D15: =IF(I15="","",IF(AND(J15>=1,J15<=K15+3),"255.255.255.0","")) -> 255.255.255.0 | E15: =IF(I15="","",IF(AND(J15>=1,J15<=K15+3),"10."&INDEX(Eingabe!$D$9:$D$18,I15)&"."&IF(J15<=K15,J15,IF(J15=K15+1,200,IF(J15=K15+2,201,250)))&".1","")) -> 10.1.9.1 | F15: =IF(I15="","",IF(AND(J15>=1,J15<=K15+3),"10."&INDEX(Eingabe!$D$9:$D$18,I15)&"."&IF(J15<=K15,J15,IF(J15=K15+1,200,IF(J15=K15+2,201,250)))&".10 – 10."&INDEX(Eingabe!$D$9:$D$18,I15)&"."&IF(J15<=K15,J15,IF(J15=K15+1,200,IF(J15=K15+2,201,250)))&".250","")) -> 10.1.9.10 – 10.1.9.250 | G15: =IF(I15="","",IF(AND(J15>=1,J15<=K15),Eingabe!$B$6&"-"&INDEX(Eingabe!$C$9:$C$18,I15)&"-Pächter · Passwort Parzelle "&J15,IF(J15=K15+1,Eingabe!$B$6&"-"&INDEX(Eingabe!$C$9:$C$18,I15)&"-Vorstand · eigenes WLAN",IF(J15=K15+2,Eingabe!$B$6&"-"&INDEX(Eingabe!$C$9:$C$18,I15)&"-Gäste · Voucher",IF(J15=K15+3,"Kabel · Access Point y = .(50+y), Mast-Switch x = .(10+x)",""))))) -> SparteNet.de-BW-Pächter · Passwort Parzelle 9 | I15: =IF(10<=(Eingabe!$P$18+Eingabe!$Q$18-1),MATCH(10,Eingabe!$P$9:$P$18,1),"") -> 1 | J15: =IF(I15="","",10-INDEX(Eingabe!$P$9:$P$18,I15)) -> 9 | K15: =IF(I15="","",INDEX(Eingabe!$E$9:$E$18,I15)) -> 85
A16: =IF(I16="","",IF(J16=0,"Sparte "&I16&": "&INDEX(Eingabe!$B$9:$B$18,I16)&" (Sparten-ID "&INDEX(Eingabe!$D$9:$D$18,I16)&", "&K16&" Parzellen)",IF(J16<=K16," Parzelle "&J16,IF(J16=K16+1," Vorstand",IF(J16=K16+2," Gäste",IF(J16=K16+3," Technik (Switches, Access Points)","")))))) -> Parzelle 10 | B16: =IF(I16="","",IF(AND(J16>=1,J16<=K16+3),IF(J16<=K16,IF(J16<=99,IF((INDEX(Eingabe!$G$9:$G$18,I16))<=9,1000+(INDEX(Eingabe!$G$9:$G$18,I16))*100,3000)+J16,IF((INDEX(Eingabe!$G$9:$G$18,I16)+1)<=9,1000+(INDEX(Eingabe!$G$9:$G$18,I16)+1)*100,3000)+J16-100),IF(J16=K16+1,2000+INDEX(Eingabe!$G$9:$G$18,I16)*10+1,IF(J16=K16+2,2000+INDEX(Eingabe!$G$9:$G$18,I16)*10+2,2000+INDEX(Eingabe!$G$9:$G$18,I16)*10+9))),"")) -> 1110 | C16: =IF(I16="","",IF(AND(J16>=1,J16<=K16+3),"10."&INDEX(Eingabe!$D$9:$D$18,I16)&"."&IF(J16<=K16,J16,IF(J16=K16+1,200,IF(J16=K16+2,201,250)))&".0/24","")) -> 10.1.10.0/24 | D16: =IF(I16="","",IF(AND(J16>=1,J16<=K16+3),"255.255.255.0","")) -> 255.255.255.0 | E16: =IF(I16="","",IF(AND(J16>=1,J16<=K16+3),"10."&INDEX(Eingabe!$D$9:$D$18,I16)&"."&IF(J16<=K16,J16,IF(J16=K16+1,200,IF(J16=K16+2,201,250)))&".1","")) -> 10.1.10.1 | F16: =IF(I16="","",IF(AND(J16>=1,J16<=K16+3),"10."&INDEX(Eingabe!$D$9:$D$18,I16)&"."&IF(J16<=K16,J16,IF(J16=K16+1,200,IF(J16=K16+2,201,250)))&".10 – 10."&INDEX(Eingabe!$D$9:$D$18,I16)&"."&IF(J16<=K16,J16,IF(J16=K16+1,200,IF(J16=K16+2,201,250)))&".250","")) -> 10.1.10.10 – 10.1.10.250 | G16: =IF(I16="","",IF(AND(J16>=1,J16<=K16),Eingabe!$B$6&"-"&INDEX(Eingabe!$C$9:$C$18,I16)&"-Pächter · Passwort Parzelle "&J16,IF(J16=K16+1,Eingabe!$B$6&"-"&INDEX(Eingabe!$C$9:$C$18,I16)&"-Vorstand · eigenes WLAN",IF(J16=K16+2,Eingabe!$B$6&"-"&INDEX(Eingabe!$C$9:$C$18,I16)&"-Gäste · Voucher",IF(J16=K16+3,"Kabel · Access Point y = .(50+y), Mast-Switch x = .(10+x)",""))))) -> SparteNet.de-BW-Pächter · Passwort Parzelle 10 | I16: =IF(11<=(Eingabe!$P$18+Eingabe!$Q$18-1),MATCH(11,Eingabe!$P$9:$P$18,1),"") -> 1 | J16: =IF(I16="","",11-INDEX(Eingabe!$P$9:$P$18,I16)) -> 10 | K16: =IF(I16="","",INDEX(Eingabe!$E$9:$E$18,I16)) -> 85
A17: =IF(I17="","",IF(J17=0,"Sparte "&I17&": "&INDEX(Eingabe!$B$9:$B$18,I17)&" (Sparten-ID "&INDEX(Eingabe!$D$9:$D$18,I17)&", "&K17&" Parzellen)",IF(J17<=K17," Parzelle "&J17,IF(J17=K17+1," Vorstand",IF(J17=K17+2," Gäste",IF(J17=K17+3," Technik (Switches, Access Points)","")))))) -> Parzelle 11 | B17: =IF(I17="","",IF(AND(J17>=1,J17<=K17+3),IF(J17<=K17,IF(J17<=99,IF((INDEX(Eingabe!$G$9:$G$18,I17))<=9,1000+(INDEX(Eingabe!$G$9:$G$18,I17))*100,3000)+J17,IF((INDEX(Eingabe!$G$9:$G$18,I17)+1)<=9,1000+(INDEX(Eingabe!$G$9:$G$18,I17)+1)*100,3000)+J17-100),IF(J17=K17+1,2000+INDEX(Eingabe!$G$9:$G$18,I17)*10+1,IF(J17=K17+2,2000+INDEX(Eingabe!$G$9:$G$18,I17)*10+2,2000+INDEX(Eingabe!$G$9:$G$18,I17)*10+9))),"")) -> 1111 | C17: =IF(I17="","",IF(AND(J17>=1,J17<=K17+3),"10."&INDEX(Eingabe!$D$9:$D$18,I17)&"."&IF(J17<=K17,J17,IF(J17=K17+1,200,IF(J17=K17+2,201,250)))&".0/24","")) -> 10.1.11.0/24 | D17: =IF(I17="","",IF(AND(J17>=1,J17<=K17+3),"255.255.255.0","")) -> 255.255.255.0 | E17: =IF(I17="","",IF(AND(J17>=1,J17<=K17+3),"10."&INDEX(Eingabe!$D$9:$D$18,I17)&"."&IF(J17<=K17,J17,IF(J17=K17+1,200,IF(J17=K17+2,201,250)))&".1","")) -> 10.1.11.1 | F17: =IF(I17="","",IF(AND(J17>=1,J17<=K17+3),"10."&INDEX(Eingabe!$D$9:$D$18,I17)&"."&IF(J17<=K17,J17,IF(J17=K17+1,200,IF(J17=K17+2,201,250)))&".10 – 10."&INDEX(Eingabe!$D$9:$D$18,I17)&"."&IF(J17<=K17,J17,IF(J17=K17+1,200,IF(J17=K17+2,201,250)))&".250","")) -> 10.1.11.10 – 10.1.11.250 | G17: =IF(I17="","",IF(AND(J17>=1,J17<=K17),Eingabe!$B$6&"-"&INDEX(Eingabe!$C$9:$C$18,I17)&"-Pächter · Passwort Parzelle "&J17,IF(J17=K17+1,Eingabe!$B$6&"-"&INDEX(Eingabe!$C$9:$C$18,I17)&"-Vorstand · eigenes WLAN",IF(J17=K17+2,Eingabe!$B$6&"-"&INDEX(Eingabe!$C$9:$C$18,I17)&"-Gäste · Voucher",IF(J17=K17+3,"Kabel · Access Point y = .(50+y), Mast-Switch x = .(10+x)",""))))) -> SparteNet.de-BW-Pächter · Passwort Parzelle 11 | I17: =IF(12<=(Eingabe!$P$18+Eingabe!$Q$18-1),MATCH(12,Eingabe!$P$9:$P$18,1),"") -> 1 | J17: =IF(I17="","",12-INDEX(Eingabe!$P$9:$P$18,I17)) -> 11 | K17: =IF(I17="","",INDEX(Eingabe!$E$9:$E$18,I17)) -> 85
A18: =IF(I18="","",IF(J18=0,"Sparte "&I18&": "&INDEX(Eingabe!$B$9:$B$18,I18)&" (Sparten-ID "&INDEX(Eingabe!$D$9:$D$18,I18)&", "&K18&" Parzellen)",IF(J18<=K18," Parzelle "&J18,IF(J18=K18+1," Vorstand",IF(J18=K18+2," Gäste",IF(J18=K18+3," Technik (Switches, Access Points)","")))))) -> Parzelle 12 | B18: =IF(I18="","",IF(AND(J18>=1,J18<=K18+3),IF(J18<=K18,IF(J18<=99,IF((INDEX(Eingabe!$G$9:$G$18,I18))<=9,1000+(INDEX(Eingabe!$G$9:$G$18,I18))*100,3000)+J18,IF((INDEX(Eingabe!$G$9:$G$18,I18)+1)<=9,1000+(INDEX(Eingabe!$G$9:$G$18,I18)+1)*100,3000)+J18-100),IF(J18=K18+1,2000+INDEX(Eingabe!$G$9:$G$18,I18)*10+1,IF(J18=K18+2,2000+INDEX(Eingabe!$G$9:$G$18,I18)*10+2,2000+INDEX(Eingabe!$G$9:$G$18,I18)*10+9))),"")) -> 1112 | C18: =IF(I18="","",IF(AND(J18>=1,J18<=K18+3),"10."&INDEX(Eingabe!$D$9:$D$18,I18)&"."&IF(J18<=K18,J18,IF(J18=K18+1,200,IF(J18=K18+2,201,250)))&".0/24","")) -> 10.1.12.0/24 | D18: =IF(I18="","",IF(AND(J18>=1,J18<=K18+3),"255.255.255.0","")) -> 255.255.255.0 | E18: =IF(I18="","",IF(AND(J18>=1,J18<=K18+3),"10."&INDEX(Eingabe!$D$9:$D$18,I18)&"."&IF(J18<=K18,J18,IF(J18=K18+1,200,IF(J18=K18+2,201,250)))&".1","")) -> 10.1.12.1 | F18: =IF(I18="","",IF(AND(J18>=1,J18<=K18+3),"10."&INDEX(Eingabe!$D$9:$D$18,I18)&"."&IF(J18<=K18,J18,IF(J18=K18+1,200,IF(J18=K18+2,201,250)))&".10 – 10."&INDEX(Eingabe!$D$9:$D$18,I18)&"."&IF(J18<=K18,J18,IF(J18=K18+1,200,IF(J18=K18+2,201,250)))&".250","")) -> 10.1.12.10 – 10.1.12.250 | G18: =IF(I18="","",IF(AND(J18>=1,J18<=K18),Eingabe!$B$6&"-"&INDEX(Eingabe!$C$9:$C$18,I18)&"-Pächter · Passwort Parzelle "&J18,IF(J18=K18+1,Eingabe!$B$6&"-"&INDEX(Eingabe!$C$9:$C$18,I18)&"-Vorstand · eigenes WLAN",IF(J18=K18+2,Eingabe!$B$6&"-"&INDEX(Eingabe!$C$9:$C$18,I18)&"-Gäste · Voucher",IF(J18=K18+3,"Kabel · Access Point y = .(50+y), Mast-Switch x = .(10+x)",""))))) -> SparteNet.de-BW-Pächter · Passwort Parzelle 12 | I18: =IF(13<=(Eingabe!$P$18+Eingabe!$Q$18-1),MATCH(13,Eingabe!$P$9:$P$18,1),"") -> 1 | J18: =IF(I18="","",13-INDEX(Eingabe!$P$9:$P$18,I18)) -> 12 | K18: =IF(I18="","",INDEX(Eingabe!$E$9:$E$18,I18)) -> 85
A19: =IF(I19="","",IF(J19=0,"Sparte "&I19&": "&INDEX(Eingabe!$B$9:$B$18,I19)&" (Sparten-ID "&INDEX(Eingabe!$D$9:$D$18,I19)&", "&K19&" Parzellen)",IF(J19<=K19," Parzelle "&J19,IF(J19=K19+1," Vorstand",IF(J19=K19+2," Gäste",IF(J19=K19+3," Technik (Switches, Access Points)","")))))) -> Parzelle 13 | B19: =IF(I19="","",IF(AND(J19>=1,J19<=K19+3),IF(J19<=K19,IF(J19<=99,IF((INDEX(Eingabe!$G$9:$G$18,I19))<=9,1000+(INDEX(Eingabe!$G$9:$G$18,I19))*100,3000)+J19,IF((INDEX(Eingabe!$G$9:$G$18,I19)+1)<=9,1000+(INDEX(Eingabe!$G$9:$G$18,I19)+1)*100,3000)+J19-100),IF(J19=K19+1,2000+INDEX(Eingabe!$G$9:$G$18,I19)*10+1,IF(J19=K19+2,2000+INDEX(Eingabe!$G$9:$G$18,I19)*10+2,2000+INDEX(Eingabe!$G$9:$G$18,I19)*10+9))),"")) -> 1113 | C19: =IF(I19="","",IF(AND(J19>=1,J19<=K19+3),"10."&INDEX(Eingabe!$D$9:$D$18,I19)&"."&IF(J19<=K19,J19,IF(J19=K19+1,200,IF(J19=K19+2,201,250)))&".0/24","")) -> 10.1.13.0/24 | D19: =IF(I19="","",IF(AND(J19>=1,J19<=K19+3),"255.255.255.0","")) -> 255.255.255.0 | E19: =IF(I19="","",IF(AND(J19>=1,J19<=K19+3),"10."&INDEX(Eingabe!$D$9:$D$18,I19)&"."&IF(J19<=K19,J19,IF(J19=K19+1,200,IF(J19=K19+2,201,250)))&".1","")) -> 10.1.13.1 | F19: =IF(I19="","",IF(AND(J19>=1,J19<=K19+3),"10."&INDEX(Eingabe!$D$9:$D$18,I19)&"."&IF(J19<=K19,J19,IF(J19=K19+1,200,IF(J19=K19+2,201,250)))&".10 – 10."&INDEX(Eingabe!$D$9:$D$18,I19)&"."&IF(J19<=K19,J19,IF(J19=K19+1,200,IF(J19=K19+2,201,250)))&".250","")) -> 10.1.13.10 – 10.1.13.250 | G19: =IF(I19="","",IF(AND(J19>=1,J19<=K19),Eingabe!$B$6&"-"&INDEX(Eingabe!$C$9:$C$18,I19)&"-Pächter · Passwort Parzelle "&J19,IF(J19=K19+1,Eingabe!$B$6&"-"&INDEX(Eingabe!$C$9:$C$18,I19)&"-Vorstand · eigenes WLAN",IF(J19=K19+2,Eingabe!$B$6&"-"&INDEX(Eingabe!$C$9:$C$18,I19)&"-Gäste · Voucher",IF(J19=K19+3,"Kabel · Access Point y = .(50+y), Mast-Switch x = .(10+x)",""))))) -> SparteNet.de-BW-Pächter · Passwort Parzelle 13 | I19: =IF(14<=(Eingabe!$P$18+Eingabe!$Q$18-1),MATCH(14,Eingabe!$P$9:$P$18,1),"") -> 1 | J19: =IF(I19="","",14-INDEX(Eingabe!$P$9:$P$18,I19)) -> 13 | K19: =IF(I19="","",INDEX(Eingabe!$E$9:$E$18,I19)) -> 85
A20: =IF(I20="","",IF(J20=0,"Sparte "&I20&": "&INDEX(Eingabe!$B$9:$B$18,I20)&" (Sparten-ID "&INDEX(Eingabe!$D$9:$D$18,I20)&", "&K20&" Parzellen)",IF(J20<=K20," Parzelle "&J20,IF(J20=K20+1," Vorstand",IF(J20=K20+2," Gäste",IF(J20=K20+3," Technik (Switches, Access Points)","")))))) -> Parzelle 14 | B20: =IF(I20="","",IF(AND(J20>=1,J20<=K20+3),IF(J20<=K20,IF(J20<=99,IF((INDEX(Eingabe!$G$9:$G$18,I20))<=9,1000+(INDEX(Eingabe!$G$9:$G$18,I20))*100,3000)+J20,IF((INDEX(Eingabe!$G$9:$G$18,I20)+1)<=9,1000+(INDEX(Eingabe!$G$9:$G$18,I20)+1)*100,3000)+J20-100),IF(J20=K20+1,2000+INDEX(Eingabe!$G$9:$G$18,I20)*10+1,IF(J20=K20+2,2000+INDEX(Eingabe!$G$9:$G$18,I20)*10+2,2000+INDEX(Eingabe!$G$9:$G$18,I20)*10+9))),"")) -> 1114 | C20: =IF(I20="","",IF(AND(J20>=1,J20<=K20+3),"10."&INDEX(Eingabe!$D$9:$D$18,I20)&"."&IF(J20<=K20,J20,IF(J20=K20+1,200,IF(J20=K20+2,201,250)))&".0/24","")) -> 10.1.14.0/24 | D20: =IF(I20="","",IF(AND(J20>=1,J20<=K20+3),"255.255.255.0","")) -> 255.255.255.0 | E20: =IF(I20="","",IF(AND(J20>=1,J20<=K20+3),"10."&INDEX(Eingabe!$D$9:$D$18,I20)&"."&IF(J20<=K20,J20,IF(J20=K20+1,200,IF(J20=K20+2,201,250)))&".1","")) -> 10.1.14.1 | F20: =IF(I20="","",IF(AND(J20>=1,J20<=K20+3),"10."&INDEX(Eingabe!$D$9:$D$18,I20)&"."&IF(J20<=K20,J20,IF(J20=K20+1,200,IF(J20=K20+2,201,250)))&".10 – 10."&INDEX(Eingabe!$D$9:$D$18,I20)&"."&IF(J20<=K20,J20,IF(J20=K20+1,200,IF(J20=K20+2,201,250)))&".250","")) -> 10.1.14.10 – 10.1.14.250 | G20: =IF(I20="","",IF(AND(J20>=1,J20<=K20),Eingabe!$B$6&"-"&INDEX(Eingabe!$C$9:$C$18,I20)&"-Pächter · Passwort Parzelle "&J20,IF(J20=K20+1,Eingabe!$B$6&"-"&INDEX(Eingabe!$C$9:$C$18,I20)&"-Vorstand · eigenes WLAN",IF(J20=K20+2,Eingabe!$B$6&"-"&INDEX(Eingabe!$C$9:$C$18,I20)&"-Gäste · Voucher",IF(J20=K20+3,"Kabel · Access Point y = .(50+y), Mast-Switch x = .(10+x)",""))))) -> SparteNet.de-BW-Pächter · Passwort Parzelle 14 | I20: =IF(15<=(Eingabe!$P$18+Eingabe!$Q$18-1),MATCH(15,Eingabe!$P$9:$P$18,1),"") -> 1 | J20: =IF(I20="","",15-INDEX(Eingabe!$P$9:$P$18,I20)) -> 14 | K20: =IF(I20="","",INDEX(Eingabe!$E$9:$E$18,I20)) -> 85
A21: =IF(I21="","",IF(J21=0,"Sparte "&I21&": "&INDEX(Eingabe!$B$9:$B$18,I21)&" (Sparten-ID "&INDEX(Eingabe!$D$9:$D$18,I21)&", "&K21&" Parzellen)",IF(J21<=K21," Parzelle "&J21,IF(J21=K21+1," Vorstand",IF(J21=K21+2," Gäste",IF(J21=K21+3," Technik (Switches, Access Points)","")))))) -> Parzelle 15 | B21: =IF(I21="","",IF(AND(J21>=1,J21<=K21+3),IF(J21<=K21,IF(J21<=99,IF((INDEX(Eingabe!$G$9:$G$18,I21))<=9,1000+(INDEX(Eingabe!$G$9:$G$18,I21))*100,3000)+J21,IF((INDEX(Eingabe!$G$9:$G$18,I21)+1)<=9,1000+(INDEX(Eingabe!$G$9:$G$18,I21)+1)*100,3000)+J21-100),IF(J21=K21+1,2000+INDEX(Eingabe!$G$9:$G$18,I21)*10+1,IF(J21=K21+2,2000+INDEX(Eingabe!$G$9:$G$18,I21)*10+2,2000+INDEX(Eingabe!$G$9:$G$18,I21)*10+9))),"")) -> 1115 | C21: =IF(I21="","",IF(AND(J21>=1,J21<=K21+3),"10."&INDEX(Eingabe!$D$9:$D$18,I21)&"."&IF(J21<=K21,J21,IF(J21=K21+1,200,IF(J21=K21+2,201,250)))&".0/24","")) -> 10.1.15.0/24 | D21: =IF(I21="","",IF(AND(J21>=1,J21<=K21+3),"255.255.255.0","")) -> 255.255.255.0 | E21: =IF(I21="","",IF(AND(J21>=1,J21<=K21+3),"10."&INDEX(Eingabe!$D$9:$D$18,I21)&"."&IF(J21<=K21,J21,IF(J21=K21+1,200,IF(J21=K21+2,201,250)))&".1","")) -> 10.1.15.1 | F21: =IF(I21="","",IF(AND(J21>=1,J21<=K21+3),"10."&INDEX(Eingabe!$D$9:$D$18,I21)&"."&IF(J21<=K21,J21,IF(J21=K21+1,200,IF(J21=K21+2,201,250)))&".10 – 10."&INDEX(Eingabe!$D$9:$D$18,I21)&"."&IF(J21<=K21,J21,IF(J21=K21+1,200,IF(J21=K21+2,201,250)))&".250","")) -> 10.1.15.10 – 10.1.15.250 | G21: =IF(I21="","",IF(AND(J21>=1,J21<=K21),Eingabe!$B$6&"-"&INDEX(Eingabe!$C$9:$C$18,I21)&"-Pächter · Passwort Parzelle "&J21,IF(J21=K21+1,Eingabe!$B$6&"-"&INDEX(Eingabe!$C$9:$C$18,I21)&"-Vorstand · eigenes WLAN",IF(J21=K21+2,Eingabe!$B$6&"-"&INDEX(Eingabe!$C$9:$C$18,I21)&"-Gäste · Voucher",IF(J21=K21+3,"Kabel · Access Point y = .(50+y), Mast-Switch x = .(10+x)",""))))) -> SparteNet.de-BW-Pächter · Passwort Parzelle 15 | I21: =IF(16<=(Eingabe!$P$18+Eingabe!$Q$18-1),MATCH(16,Eingabe!$P$9:$P$18,1),"") -> 1 | J21: =IF(I21="","",16-INDEX(Eingabe!$P$9:$P$18,I21)) -> 15 | K21: =IF(I21="","",INDEX(Eingabe!$E$9:$E$18,I21)) -> 85
A22: =IF(I22="","",IF(J22=0,"Sparte "&I22&": "&INDEX(Eingabe!$B$9:$B$18,I22)&" (Sparten-ID "&INDEX(Eingabe!$D$9:$D$18,I22)&", "&K22&" Parzellen)",IF(J22<=K22," Parzelle "&J22,IF(J22=K22+1," Vorstand",IF(J22=K22+2," Gäste",IF(J22=K22+3," Technik (Switches, Access Points)","")))))) -> Parzelle 16 | B22: =IF(I22="","",IF(AND(J22>=1,J22<=K22+3),IF(J22<=K22,IF(J22<=99,IF((INDEX(Eingabe!$G$9:$G$18,I22))<=9,1000+(INDEX(Eingabe!$G$9:$G$18,I22))*100,3000)+J22,IF((INDEX(Eingabe!$G$9:$G$18,I22)+1)<=9,1000+(INDEX(Eingabe!$G$9:$G$18,I22)+1)*100,3000)+J22-100),IF(J22=K22+1,2000+INDEX(Eingabe!$G$9:$G$18,I22)*10+1,IF(J22=K22+2,2000+INDEX(Eingabe!$G$9:$G$18,I22)*10+2,2000+INDEX(Eingabe!$G$9:$G$18,I22)*10+9))),"")) -> 1116 | C22: =IF(I22="","",IF(AND(J22>=1,J22<=K22+3),"10."&INDEX(Eingabe!$D$9:$D$18,I22)&"."&IF(J22<=K22,J22,IF(J22=K22+1,200,IF(J22=K22+2,201,250)))&".0/24","")) -> 10.1.16.0/24 | D22: =IF(I22="","",IF(AND(J22>=1,J22<=K22+3),"255.255.255.0","")) -> 255.255.255.0 | E22: =IF(I22="","",IF(AND(J22>=1,J22<=K22+3),"10."&INDEX(Eingabe!$D$9:$D$18,I22)&"."&IF(J22<=K22,J22,IF(J22=K22+1,200,IF(J22=K22+2,201,250)))&".1","")) -> 10.1.16.1 | F22: =IF(I22="","",IF(AND(J22>=1,J22<=K22+3),"10."&INDEX(Eingabe!$D$9:$D$18,I22)&"."&IF(J22<=K22,J22,IF(J22=K22+1,200,IF(J22=K22+2,201,250)))&".10 – 10."&INDEX(Eingabe!$D$9:$D$18,I22)&"."&IF(J22<=K22,J22,IF(J22=K22+1,200,IF(J22=K22+2,201,250)))&".250","")) -> 10.1.16.10 – 10.1.16.250 | G22: =IF(I22="","",IF(AND(J22>=1,J22<=K22),Eingabe!$B$6&"-"&INDEX(Eingabe!$C$9:$C$18,I22)&"-Pächter · Passwort Parzelle "&J22,IF(J22=K22+1,Eingabe!$B$6&"-"&INDEX(Eingabe!$C$9:$C$18,I22)&"-Vorstand · eigenes WLAN",IF(J22=K22+2,Eingabe!$B$6&"-"&INDEX(Eingabe!$C$9:$C$18,I22)&"-Gäste · Voucher",IF(J22=K22+3,"Kabel · Access Point y = .(50+y), Mast-Switch x = .(10+x)",""))))) -> SparteNet.de-BW-Pächter · Passwort Parzelle 16 | I22: =IF(17<=(Eingabe!$P$18+Eingabe!$Q$18-1),MATCH(17,Eingabe!$P$9:$P$18,1),"") -> 1 | J22: =IF(I22="","",17-INDEX(Eingabe!$P$9:$P$18,I22)) -> 16 | K22: =IF(I22="","",INDEX(Eingabe!$E$9:$E$18,I22)) -> 85
A23: =IF(I23="","",IF(J23=0,"Sparte "&I23&": "&INDEX(Eingabe!$B$9:$B$18,I23)&" (Sparten-ID "&INDEX(Eingabe!$D$9:$D$18,I23)&", "&K23&" Parzellen)",IF(J23<=K23," Parzelle "&J23,IF(J23=K23+1," Vorstand",IF(J23=K23+2," Gäste",IF(J23=K23+3," Technik (Switches, Access Points)","")))))) -> Parzelle 17 | B23: =IF(I23="","",IF(AND(J23>=1,J23<=K23+3),IF(J23<=K23,IF(J23<=99,IF((INDEX(Eingabe!$G$9:$G$18,I23))<=9,1000+(INDEX(Eingabe!$G$9:$G$18,I23))*100,3000)+J23,IF((INDEX(Eingabe!$G$9:$G$18,I23)+1)<=9,1000+(INDEX(Eingabe!$G$9:$G$18,I23)+1)*100,3000)+J23-100),IF(J23=K23+1,2000+INDEX(Eingabe!$G$9:$G$18,I23)*10+1,IF(J23=K23+2,2000+INDEX(Eingabe!$G$9:$G$18,I23)*10+2,2000+INDEX(Eingabe!$G$9:$G$18,I23)*10+9))),"")) -> 1117 | C23: =IF(I23="","",IF(AND(J23>=1,J23<=K23+3),"10."&INDEX(Eingabe!$D$9:$D$18,I23)&"."&IF(J23<=K23,J23,IF(J23=K23+1,200,IF(J23=K23+2,201,250)))&".0/24","")) -> 10.1.17.0/24 | D23: =IF(I23="","",IF(AND(J23>=1,J23<=K23+3),"255.255.255.0","")) -> 255.255.255.0 | E23: =IF(I23="","",IF(AND(J23>=1,J23<=K23+3),"10."&INDEX(Eingabe!$D$9:$D$18,I23)&"."&IF(J23<=K23,J23,IF(J23=K23+1,200,IF(J23=K23+2,201,250)))&".1","")) -> 10.1.17.1 | F23: =IF(I23="","",IF(AND(J23>=1,J23<=K23+3),"10."&INDEX(Eingabe!$D$9:$D$18,I23)&"."&IF(J23<=K23,J23,IF(J23=K23+1,200,IF(J23=K23+2,201,250)))&".10 – 10."&INDEX(Eingabe!$D$9:$D$18,I23)&"."&IF(J23<=K23,J23,IF(J23=K23+1,200,IF(J23=K23+2,201,250)))&".250","")) -> 10.1.17.10 – 10.1.17.250 | G23: =IF(I23="","",IF(AND(J23>=1,J23<=K23),Eingabe!$B$6&"-"&INDEX(Eingabe!$C$9:$C$18,I23)&"-Pächter · Passwort Parzelle "&J23,IF(J23=K23+1,Eingabe!$B$6&"-"&INDEX(Eingabe!$C$9:$C$18,I23)&"-Vorstand · eigenes WLAN",IF(J23=K23+2,Eingabe!$B$6&"-"&INDEX(Eingabe!$C$9:$C$18,I23)&"-Gäste · Voucher",IF(J23=K23+3,"Kabel · Access Point y = .(50+y), Mast-Switch x = .(10+x)",""))))) -> SparteNet.de-BW-Pächter · Passwort Parzelle 17 | I23: =IF(18<=(Eingabe!$P$18+Eingabe!$Q$18-1),MATCH(18,Eingabe!$P$9:$P$18,1),"") -> 1 | J23: =IF(I23="","",18-INDEX(Eingabe!$P$9:$P$18,I23)) -> 17 | K23: =IF(I23="","",INDEX(Eingabe!$E$9:$E$18,I23)) -> 85
A24: =IF(I24="","",IF(J24=0,"Sparte "&I24&": "&INDEX(Eingabe!$B$9:$B$18,I24)&" (Sparten-ID "&INDEX(Eingabe!$D$9:$D$18,I24)&", "&K24&" Parzellen)",IF(J24<=K24," Parzelle "&J24,IF(J24=K24+1," Vorstand",IF(J24=K24+2," Gäste",IF(J24=K24+3," Technik (Switches, Access Points)","")))))) -> Parzelle 18 | B24: =IF(I24="","",IF(AND(J24>=1,J24<=K24+3),IF(J24<=K24,IF(J24<=99,IF((INDEX(Eingabe!$G$9:$G$18,I24))<=9,1000+(INDEX(Eingabe!$G$9:$G$18,I24))*100,3000)+J24,IF((INDEX(Eingabe!$G$9:$G$18,I24)+1)<=9,1000+(INDEX(Eingabe!$G$9:$G$18,I24)+1)*100,3000)+J24-100),IF(J24=K24+1,2000+INDEX(Eingabe!$G$9:$G$18,I24)*10+1,IF(J24=K24+2,2000+INDEX(Eingabe!$G$9:$G$18,I24)*10+2,2000+INDEX(Eingabe!$G$9:$G$18,I24)*10+9))),"")) -> 1118 | C24: =IF(I24="","",IF(AND(J24>=1,J24<=K24+3),"10."&INDEX(Eingabe!$D$9:$D$18,I24)&"."&IF(J24<=K24,J24,IF(J24=K24+1,200,IF(J24=K24+2,201,250)))&".0/24","")) -> 10.1.18.0/24 | D24: =IF(I24="","",IF(AND(J24>=1,J24<=K24+3),"255.255.255.0","")) -> 255.255.255.0 | E24: =IF(I24="","",IF(AND(J24>=1,J24<=K24+3),"10."&INDEX(Eingabe!$D$9:$D$18,I24)&"."&IF(J24<=K24,J24,IF(J24=K24+1,200,IF(J24=K24+2,201,250)))&".1","")) -> 10.1.18.1 | F24: =IF(I24="","",IF(AND(J24>=1,J24<=K24+3),"10."&INDEX(Eingabe!$D$9:$D$18,I24)&"."&IF(J24<=K24,J24,IF(J24=K24+1,200,IF(J24=K24+2,201,250)))&".10 – 10."&INDEX(Eingabe!$D$9:$D$18,I24)&"."&IF(J24<=K24,J24,IF(J24=K24+1,200,IF(J24=K24+2,201,250)))&".250","")) -> 10.1.18.10 – 10.1.18.250 | G24: =IF(I24="","",IF(AND(J24>=1,J24<=K24),Eingabe!$B$6&"-"&INDEX(Eingabe!$C$9:$C$18,I24)&"-Pächter · Passwort Parzelle "&J24,IF(J24=K24+1,Eingabe!$B$6&"-"&INDEX(Eingabe!$C$9:$C$18,I24)&"-Vorstand · eigenes WLAN",IF(J24=K24+2,Eingabe!$B$6&"-"&INDEX(Eingabe!$C$9:$C$18,I24)&"-Gäste · Voucher",IF(J24=K24+3,"Kabel · Access Point y = .(50+y), Mast-Switch x = .(10+x)",""))))) -> SparteNet.de-BW-Pächter · Passwort Parzelle 18 | I24: =IF(19<=(Eingabe!$P$18+Eingabe!$Q$18-1),MATCH(19,Eingabe!$P$9:$P$18,1),"") -> 1 | J24: =IF(I24="","",19-INDEX(Eingabe!$P$9:$P$18,I24)) -> 18 | K24: =IF(I24="","",INDEX(Eingabe!$E$9:$E$18,I24)) -> 85
A25: =IF(I25="","",IF(J25=0,"Sparte "&I25&": "&INDEX(Eingabe!$B$9:$B$18,I25)&" (Sparten-ID "&INDEX(Eingabe!$D$9:$D$18,I25)&", "&K25&" Parzellen)",IF(J25<=K25," Parzelle "&J25,IF(J25=K25+1," Vorstand",IF(J25=K25+2," Gäste",IF(J25=K25+3," Technik (Switches, Access Points)","")))))) -> Parzelle 19 | B25: =IF(I25="","",IF(AND(J25>=1,J25<=K25+3),IF(J25<=K25,IF(J25<=99,IF((INDEX(Eingabe!$G$9:$G$18,I25))<=9,1000+(INDEX(Eingabe!$G$9:$G$18,I25))*100,3000)+J25,IF((INDEX(Eingabe!$G$9:$G$18,I25)+1)<=9,1000+(INDEX(Eingabe!$G$9:$G$18,I25)+1)*100,3000)+J25-100),IF(J25=K25+1,2000+INDEX(Eingabe!$G$9:$G$18,I25)*10+1,IF(J25=K25+2,2000+INDEX(Eingabe!$G$9:$G$18,I25)*10+2,2000+INDEX(Eingabe!$G$9:$G$18,I25)*10+9))),"")) -> 1119 | C25: =IF(I25="","",IF(AND(J25>=1,J25<=K25+3),"10."&INDEX(Eingabe!$D$9:$D$18,I25)&"."&IF(J25<=K25,J25,IF(J25=K25+1,200,IF(J25=K25+2,201,250)))&".0/24","")) -> 10.1.19.0/24 | D25: =IF(I25="","",IF(AND(J25>=1,J25<=K25+3),"255.255.255.0","")) -> 255.255.255.0 | E25: =IF(I25="","",IF(AND(J25>=1,J25<=K25+3),"10."&INDEX(Eingabe!$D$9:$D$18,I25)&"."&IF(J25<=K25,J25,IF(J25=K25+1,200,IF(J25=K25+2,201,250)))&".1","")) -> 10.1.19.1 | F25: =IF(I25="","",IF(AND(J25>=1,J25<=K25+3),"10."&INDEX(Eingabe!$D$9:$D$18,I25)&"."&IF(J25<=K25,J25,IF(J25=K25+1,200,IF(J25=K25+2,201,250)))&".10 – 10."&INDEX(Eingabe!$D$9:$D$18,I25)&"."&IF(J25<=K25,J25,IF(J25=K25+1,200,IF(J25=K25+2,201,250)))&".250","")) -> 10.1.19.10 – 10.1.19.250 | G25: =IF(I25="","",IF(AND(J25>=1,J25<=K25),Eingabe!$B$6&"-"&INDEX(Eingabe!$C$9:$C$18,I25)&"-Pächter · Passwort Parzelle "&J25,IF(J25=K25+1,Eingabe!$B$6&"-"&INDEX(Eingabe!$C$9:$C$18,I25)&"-Vorstand · eigenes WLAN",IF(J25=K25+2,Eingabe!$B$6&"-"&INDEX(Eingabe!$C$9:$C$18,I25)&"-Gäste · Voucher",IF(J25=K25+3,"Kabel · Access Point y = .(50+y), Mast-Switch x = .(10+x)",""))))) -> SparteNet.de-BW-Pächter · Passwort Parzelle 19 | I25: =IF(20<=(Eingabe!$P$18+Eingabe!$Q$18-1),MATCH(20,Eingabe!$P$9:$P$18,1),"") -> 1 | J25: =IF(I25="","",20-INDEX(Eingabe!$P$9:$P$18,I25)) -> 19 | K25: =IF(I25="","",INDEX(Eingabe!$E$9:$E$18,I25)) -> 85
A26: =IF(I26="","",IF(J26=0,"Sparte "&I26&": "&INDEX(Eingabe!$B$9:$B$18,I26)&" (Sparten-ID "&INDEX(Eingabe!$D$9:$D$18,I26)&", "&K26&" Parzellen)",IF(J26<=K26," Parzelle "&J26,IF(J26=K26+1," Vorstand",IF(J26=K26+2," Gäste",IF(J26=K26+3," Technik (Switches, Access Points)","")))))) -> Parzelle 20 | B26: =IF(I26="","",IF(AND(J26>=1,J26<=K26+3),IF(J26<=K26,IF(J26<=99,IF((INDEX(Eingabe!$G$9:$G$18,I26))<=9,1000+(INDEX(Eingabe!$G$9:$G$18,I26))*100,3000)+J26,IF((INDEX(Eingabe!$G$9:$G$18,I26)+1)<=9,1000+(INDEX(Eingabe!$G$9:$G$18,I26)+1)*100,3000)+J26-100),IF(J26=K26+1,2000+INDEX(Eingabe!$G$9:$G$18,I26)*10+1,IF(J26=K26+2,2000+INDEX(Eingabe!$G$9:$G$18,I26)*10+2,2000+INDEX(Eingabe!$G$9:$G$18,I26)*10+9))),"")) -> 1120 | C26: =IF(I26="","",IF(AND(J26>=1,J26<=K26+3),"10."&INDEX(Eingabe!$D$9:$D$18,I26)&"."&IF(J26<=K26,J26,IF(J26=K26+1,200,IF(J26=K26+2,201,250)))&".0/24","")) -> 10.1.20.0/24 | D26: =IF(I26="","",IF(AND(J26>=1,J26<=K26+3),"255.255.255.0","")) -> 255.255.255.0 | E26: =IF(I26="","",IF(AND(J26>=1,J26<=K26+3),"10."&INDEX(Eingabe!$D$9:$D$18,I26)&"."&IF(J26<=K26,J26,IF(J26=K26+1,200,IF(J26=K26+2,201,250)))&".1","")) -> 10.1.20.1 | F26: =IF(I26="","",IF(AND(J26>=1,J26<=K26+3),"10."&INDEX(Eingabe!$D$9:$D$18,I26)&"."&IF(J26<=K26,J26,IF(J26=K26+1,200,IF(J26=K26+2,201,250)))&".10 – 10."&INDEX(Eingabe!$D$9:$D$18,I26)&"."&IF(J26<=K26,J26,IF(J26=K26+1,200,IF(J26=K26+2,201,250)))&".250","")) -> 10.1.20.10 – 10.1.20.250 | G26: =IF(I26="","",IF(AND(J26>=1,J26<=K26),Eingabe!$B$6&"-"&INDEX(Eingabe!$C$9:$C$18,I26)&"-Pächter · Passwort Parzelle "&J26,IF(J26=K26+1,Eingabe!$B$6&"-"&INDEX(Eingabe!$C$9:$C$18,I26)&"-Vorstand · eigenes WLAN",IF(J26=K26+2,Eingabe!$B$6&"-"&INDEX(Eingabe!$C$9:$C$18,I26)&"-Gäste · Voucher",IF(J26=K26+3,"Kabel · Access Point y = .(50+y), Mast-Switch x = .(10+x)",""))))) -> SparteNet.de-BW-Pächter · Passwort Parzelle 20 | I26: =IF(21<=(Eingabe!$P$18+Eingabe!$Q$18-1),MATCH(21,Eingabe!$P$9:$P$18,1),"") -> 1 | J26: =IF(I26="","",21-INDEX(Eingabe!$P$9:$P$18,I26)) -> 20 | K26: =IF(I26="","",INDEX(Eingabe!$E$9:$E$18,I26)) -> 85
A27: =IF(I27="","",IF(J27=0,"Sparte "&I27&": "&INDEX(Eingabe!$B$9:$B$18,I27)&" (Sparten-ID "&INDEX(Eingabe!$D$9:$D$18,I27)&", "&K27&" Parzellen)",IF(J27<=K27," Parzelle "&J27,IF(J27=K27+1," Vorstand",IF(J27=K27+2," Gäste",IF(J27=K27+3," Technik (Switches, Access Points)","")))))) -> Parzelle 21 | B27: =IF(I27="","",IF(AND(J27>=1,J27<=K27+3),IF(J27<=K27,IF(J27<=99,IF((INDEX(Eingabe!$G$9:$G$18,I27))<=9,1000+(INDEX(Eingabe!$G$9:$G$18,I27))*100,3000)+J27,IF((INDEX(Eingabe!$G$9:$G$18,I27)+1)<=9,1000+(INDEX(Eingabe!$G$9:$G$18,I27)+1)*100,3000)+J27-100),IF(J27=K27+1,2000+INDEX(Eingabe!$G$9:$G$18,I27)*10+1,IF(J27=K27+2,2000+INDEX(Eingabe!$G$9:$G$18,I27)*10+2,2000+INDEX(Eingabe!$G$9:$G$18,I27)*10+9))),"")) -> 1121 | C27: =IF(I27="","",IF(AND(J27>=1,J27<=K27+3),"10."&INDEX(Eingabe!$D$9:$D$18,I27)&"."&IF(J27<=K27,J27,IF(J27=K27+1,200,IF(J27=K27+2,201,250)))&".0/24","")) -> 10.1.21.0/24 | D27: =IF(I27="","",IF(AND(J27>=1,J27<=K27+3),"255.255.255.0","")) -> 255.255.255.0 | E27: =IF(I27="","",IF(AND(J27>=1,J27<=K27+3),"10."&INDEX(Eingabe!$D$9:$D$18,I27)&"."&IF(J27<=K27,J27,IF(J27=K27+1,200,IF(J27=K27+2,201,250)))&".1","")) -> 10.1.21.1 | F27: =IF(I27="","",IF(AND(J27>=1,J27<=K27+3),"10."&INDEX(Eingabe!$D$9:$D$18,I27)&"."&IF(J27<=K27,J27,IF(J27=K27+1,200,IF(J27=K27+2,201,250)))&".10 – 10."&INDEX(Eingabe!$D$9:$D$18,I27)&"."&IF(J27<=K27,J27,IF(J27=K27+1,200,IF(J27=K27+2,201,250)))&".250","")) -> 10.1.21.10 – 10.1.21.250 | G27: =IF(I27="","",IF(AND(J27>=1,J27<=K27),Eingabe!$B$6&"-"&INDEX(Eingabe!$C$9:$C$18,I27)&"-Pächter · Passwort Parzelle "&J27,IF(J27=K27+1,Eingabe!$B$6&"-"&INDEX(Eingabe!$C$9:$C$18,I27)&"-Vorstand · eigenes WLAN",IF(J27=K27+2,Eingabe!$B$6&"-"&INDEX(Eingabe!$C$9:$C$18,I27)&"-Gäste · Voucher",IF(J27=K27+3,"Kabel · Access Point y = .(50+y), Mast-Switch x = .(10+x)",""))))) -> SparteNet.de-BW-Pächter · Passwort Parzelle 21 | I27: =IF(22<=(Eingabe!$P$18+Eingabe!$Q$18-1),MATCH(22,Eingabe!$P$9:$P$18,1),"") -> 1 | J27: =IF(I27="","",22-INDEX(Eingabe!$P$9:$P$18,I27)) -> 21 | K27: =IF(I27="","",INDEX(Eingabe!$E$9:$E$18,I27)) -> 85
A28: =IF(I28="","",IF(J28=0,"Sparte "&I28&": "&INDEX(Eingabe!$B$9:$B$18,I28)&" (Sparten-ID "&INDEX(Eingabe!$D$9:$D$18,I28)&", "&K28&" Parzellen)",IF(J28<=K28," Parzelle "&J28,IF(J28=K28+1," Vorstand",IF(J28=K28+2," Gäste",IF(J28=K28+3," Technik (Switches, Access Points)","")))))) -> Parzelle 22 | B28: =IF(I28="","",IF(AND(J28>=1,J28<=K28+3),IF(J28<=K28,IF(J28<=99,IF((INDEX(Eingabe!$G$9:$G$18,I28))<=9,1000+(INDEX(Eingabe!$G$9:$G$18,I28))*100,3000)+J28,IF((INDEX(Eingabe!$G$9:$G$18,I28)+1)<=9,1000+(INDEX(Eingabe!$G$9:$G$18,I28)+1)*100,3000)+J28-100),IF(J28=K28+1,2000+INDEX(Eingabe!$G$9:$G$18,I28)*10+1,IF(J28=K28+2,2000+INDEX(Eingabe!$G$9:$G$18,I28)*10+2,2000+INDEX(Eingabe!$G$9:$G$18,I28)*10+9))),"")) -> 1122 | C28: =IF(I28="","",IF(AND(J28>=1,J28<=K28+3),"10."&INDEX(Eingabe!$D$9:$D$18,I28)&"."&IF(J28<=K28,J28,IF(J28=K28+1,200,IF(J28=K28+2,201,250)))&".0/24","")) -> 10.1.22.0/24 | D28: =IF(I28="","",IF(AND(J28>=1,J28<=K28+3),"255.255.255.0","")) -> 255.255.255.0 | E28: =IF(I28="","",IF(AND(J28>=1,J28<=K28+3),"10."&INDEX(Eingabe!$D$9:$D$18,I28)&"."&IF(J28<=K28,J28,IF(J28=K28+1,200,IF(J28=K28+2,201,250)))&".1","")) -> 10.1.22.1 | F28: =IF(I28="","",IF(AND(J28>=1,J28<=K28+3),"10."&INDEX(Eingabe!$D$9:$D$18,I28)&"."&IF(J28<=K28,J28,IF(J28=K28+1,200,IF(J28=K28+2,201,250)))&".10 – 10."&INDEX(Eingabe!$D$9:$D$18,I28)&"."&IF(J28<=K28,J28,IF(J28=K28+1,200,IF(J28=K28+2,201,250)))&".250","")) -> 10.1.22.10 – 10.1.22.250 | G28: =IF(I28="","",IF(AND(J28>=1,J28<=K28),Eingabe!$B$6&"-"&INDEX(Eingabe!$C$9:$C$18,I28)&"-Pächter · Passwort Parzelle "&J28,IF(J28=K28+1,Eingabe!$B$6&"-"&INDEX(Eingabe!$C$9:$C$18,I28)&"-Vorstand · eigenes WLAN",IF(J28=K28+2,Eingabe!$B$6&"-"&INDEX(Eingabe!$C$9:$C$18,I28)&"-Gäste · Voucher",IF(J28=K28+3,"Kabel · Access Point y = .(50+y), Mast-Switch x = .(10+x)",""))))) -> SparteNet.de-BW-Pächter · Passwort Parzelle 22 | I28: =IF(23<=(Eingabe!$P$18+Eingabe!$Q$18-1),MATCH(23,Eingabe!$P$9:$P$18,1),"") -> 1 | J28: =IF(I28="","",23-INDEX(Eingabe!$P$9:$P$18,I28)) -> 22 | K28: =IF(I28="","",INDEX(Eingabe!$E$9:$E$18,I28)) -> 85
